Workbook
Name company: [1]Data!$B$2
Name emirates: [1]Data!$B$5
Name pobox: [1]Data!$B$4

Sheet BS
A3: Unaudited Statement of Financial Position
A4: As at 31 August 2022
C6: AED | E6: AED
C7: =+TB!C4 -> 44804 | E7: =+TB!D4 -> 44439 | G7: Change | H7: Percentage | J7: Remarks
B8: ASSETS | G8: AED | H8: Change
B9: Non Current Assets
B10: Property and Equipment | C10: =+Schedules!E11 -> 14143627 | E10: =+SUM(Schedules!F11) -> 13986508 | G10: =+C10-E10 -> 157118.9 | H10: =+G10/E10 -> 0.011233605
B11: Accumulated Depreciation | C11: =+Schedules!E18 -> -8510463.6 | E11: =+Schedules!F18 -> -7670308.5 | G11: =+C11-E11 -> -840155.05 | H11: =+G11/E11 -> 0.10953341
C13: =+C10+C11 -> 5633163.2 | E13: =+E10+E11 -> 6316199.3 | G13: =+G10+G11 -> -683036.15 | H13: =+G13/E13 -> -0.10814037
B15: Current Assets
B16: Accounts Receivables and Prepayments | C16: =+Schedules!E30 -> 589449.14 | E16: =+Schedules!F30 -> 616840.37 | G16: =+C16-E16 -> -27391.23 | H16: =+G16/E16 -> -0.044405703
B17: Due from Related Party | G17: =+C17-E17 -> 0 | H17: =+G17/E17 -> #DIV/0!
B18: Cash and Bank Balances | C18: =+Schedules!E36 -> 1101737.3 | E18: =+Schedules!F36 -> 2224755.9 | G18: =+C18-E18 -> -1123018.6 | H18: =+G18/E18 -> -0.50478286
C20: =SUM(C16:C19) -> 1691186.4 | E20: =SUM(E16:E19) -> 2841596.3 | G20: =SUM(G16:G19) -> -1150409.9 | H20: =+G20/E20 -> -0.40484635
B22: TOTAL ASSETS | C22: =+C20+C13 -> 7324349.6 | E22: =+E20+E13 -> 9157795.6 | G22: =+G20+G13 -> -1833446 | H22: =+G22/E22 -> -0.20020604
B24: LIABILITIES
B25: Non Current Liabilities
B26: Deferred Grant - Capital | C26: =C13 -> 5633163.2 | E26: =E13 -> 6316199.3 | G26: =+C26-E26 -> -683036.15 | H26: =+G26/E26 -> -0.10814037
B27: Deferred Grant - Operating | C27: =-(TB!C49+TB!C50+TB!C53+IS!D9-IS!D16)-C26 -> 566356.68 | E27: =-(TB!D49+TB!D50+TB!D53+IS!F9-IS!F16)-E26 -> 1807862.8 | G27: =+C27-E27 -> -1241506.1 | H27: =+G27/E27 -> -0.68672584
B28: Employees' end of service benefits | C28: =-TB!C48 -> 140321.17 | E28: =-TB!D48 -> 151863.37 | G28: =+C28-E28 -> -11542.2
C30: =SUM(C26:C28) -> 6339841 | E30: =SUM(E26:E28) -> 8275925.4 | G30: =SUM(G26:G28) -> -1936084.4 | H30: =+G30/E30 -> -0.23394174
B31: Current Liabilities
B32: Accounts Payable and Accruals | C32: =+Schedules!E48 -> 984508.56 | E32: =+Schedules!F48 -> 881870.15 | G32: =+C32-E32 -> 102638.41 | H32: =+G32/E32 -> 0.11638721
C34: =SUM(C32:C33) -> 984508.56 | E34: =SUM(E32:E33) -> 881870.15 | G34: =SUM(G32:G33) -> 102638.41 | H34: =+G34/E34 -> 0.11638721
B36: TOTAL LIABILITIES | C36: =+C30+C34 -> 7324349.6 | E36: =+E30+E34 -> 9157795.6 | G36: =+G30+G34 -> -1833446 | H36: =+G36/E36 -> -0.20020604
C39: =+C36-C22 -> 0 | E39: =+E36-E22 -> 0

Sheet IS
B3: Unaudited Statement of Comprehensive Income
B4: Period from 1 January 2022 to 31 August 2022
D6: AED | F6: AED
D7: =+TB!C4 -> 44804 | F7: =+TB!D4 -> 44439 | H7: Change | I7: Percentage
C8: Revenue | H8: AED | I8: Change
C9: Operating Contributions recognized as revenue | D9: =+D18-D10 -> 1331857.4 | F9: =+F18-F10 -> 1468514.3 | H9: =+D9-F9 -> -136656.9 | I9: =+H9/F9 -> -0.093057927
C10: Other Income | D10: =-TB!C54 -> 0 | F10: =-TB!D54 -> 0 | H10: =+D10-F10 -> 0 | I10: =+H10/F10 -> #DIV/0!
D11: =D9+D10 -> 1331857.4 | F11: =F9+F10 -> 1468514.3 | H11: =+D11-F11 -> -136656.9 | I11: =+H11/F11 -> -0.093057927
C13: Expenses
C14: Personnel | D14: =+'Expense Comparison'!D22 -> 1155310.8 | F14: =+'Expense Comparison'!E22 -> 1145494.9 | H14: =+D14-F14 -> 9815.85 | I14: =+H14/F14 -> 0.0085690907
C15: Depreciation | D15: ='Expense Comparison'!D71 -> 518751.61 | F15: ='Expense Comparison'!E71 -> 924580.74 | H15: =+D15-F15 -> -405829.13 | I15: =+H15/F15 -> -0.43893314
C16: Amortisation of deferred capital grant | D16: =-D15 -> -518751.61 | F16: =-F15 -> -924580.74 | H16: =+D16-F16 -> 405829.13 | I16: =+H16/F16 -> -0.43893314
C17: Administrative and other costs | D17: =+'Expense Comparison'!D58+'Expense Comparison'!D65 -> 176546.66 | F17: =+'Expense Comparison'!E58 -> 323019.41 | H17: =+D17-F17 -> -146472.75 | I17: =+H17/F17 -> -0.45344876
D18: =SUM(D14:D17) -> 1331857.4 | F18: =SUM(F14:F17) -> 1468514.3 | H18: =+D18-F18 -> -136656.9 | I18: =+H18/F18 -> -0.093057927
D19: =D11-D18 -> 0 | F19: =F11-F18 -> 0
C21: Note

Sheet Schedules
A1: ARIC FINANCIAL REPORTING
A3: Schedules
D4: Particulars | E4: =+BS!C7 -> 44804 | F4: =+BS!E7 -> 44439
D5: SCHEDULE 1
D6: Building | E6: =+'Fixed Assets'!G10 -> 7277144.4 | F6: =TB!D26 -> 7277144.4
D7: Furniture & Fixtures | E7: =+'Fixed Assets'!G11 -> 112725 | F7: =TB!D33 -> 112725
D8: Plant, Machinery & Equipment | E8: =+'Fixed Assets'!G12 -> 6203419.3 | F8: =TB!D30 -> 6119400.7
D9: Intangible Assets | E9: =+'Fixed Assets'!G13 -> 436988.01 | F9: =TB!D36 -> 436988.01
D10: Asset In Progress | E10: =+'Fixed Assets'!G14+'Fixed Assets'!G15+'Fixed Assets'!G16 -> 113350 | F10: =TB!D25+TB!D31 -> 40249.72
D11: Property, Plant & Eqpt. | E11: =SUM(E6:E10) -> 14143627 | F11: =SUM(F6:F10) -> 13986508
D12: SCHEDULE 2
D13: Accum Depreciation - Building | E13: =+'Fixed Assets'!L10 -> -2057709 | F13: =TB!D29 -> -1693446.7
D14: Accum Depreiation - Furniture & Fixtures | E14: =+'Fixed Assets'!L11 -> -112634.6 | F14: =TB!D35 -> -106355.5
D15: Accum Depreiation -Plant, Machinery & Equipment | E15: =+'Fixed Assets'!L12 -> -5903132 | F15: =TB!D32 -> -5445480.6
D16: Accum Depreiation -Intangible Assets | E16: =+'Fixed Assets'!L13 -> -436988.01 | F16: =TB!D38 -> -425025.77
D17: Asset In Progress
D18: Property, Plant & Eqpt. | E18: =SUM(E13:E17) -> -8510463.6 | F18: =SUM(F13:F17) -> -7670308.5
D19: SCHEDULE 3
B20: 120140 | D20: =VLOOKUP(B20,TB!$A$4:$B$109,2,0) -> Goods and services sales receivable | E20: =+VLOOKUP(B20,TB!$A$5:$D$109,3,0) -> 14514 | F20: =+VLOOKUP(B20,TB!$A$5:$D$109,4,0) -> -47619.05
B21: 120123 | D21: Goods and services Tax Receivable | E21: =+VLOOKUP(B21,TB!$A$5:$D$109,3,0) -> 0 | F21: =+VLOOKUP(B21,TB!$A$5:$D$109,4,0) -> 47619.05
B22: 120214 | D22: =VLOOKUP(B22,TB!$A$4:$B$109,2,0) -> Rent support loans to employees | E22: =+VLOOKUP(B22,TB!$A$5:$D$109,3,0) -> 0 | F22: =+VLOOKUP(B22,TB!$A$5:$D$109,4,0) -> 0
B23: 120180 | D23: =VLOOKUP(B23,TB!$A$4:$B$109,2,0) -> Accounts Receivable - General | E23: =+VLOOKUP(B23,TB!$A$5:$D$109,3,0) -> 0 | F23: =+VLOOKUP(B23,TB!$A$5:$D$109,4,0) -> 0
B24: 120330 | D24: =VLOOKUP(B24,TB!$A$4:$B$109,2,0) -> Other advances to vendors | E24: =+VLOOKUP(B24,TB!$A$5:$D$109,3,0) -> 556958.06 | F24: =+VLOOKUP(B24,TB!$A$5:$D$109,4,0) -> 513398.54
B25: 132020 | D25: =VLOOKUP(B25,TB!$A$4:$B$109,2,0) -> Prepayments-Asset Cost (for setup) | E25: =+VLOOKUP(B25,TB!$A$5:$D$109,3,0) -> 0 | F25: =+VLOOKUP(B25,TB!$A$5:$D$109,4,0) -> 0
B26: 132021 | D26: =VLOOKUP(B26,TB!$A$4:$B$109,2,0) -> Prepayments-Asset Clearing (for setup) | E26: =+VLOOKUP(B26,TB!$A$5:$D$109,3,0) -> 0 | F26: =+VLOOKUP(B26,TB!$A$5:$D$109,4,0) -> 0
B27: 126510 | D27: VAT Receivable Account | E27: =+VLOOKUP(B27,TB!$A$5:$D$109,3,0) -> 17977.08 | F27: =+VLOOKUP(B27,TB!$A$5:$D$109,4,0) -> 103441.83
B28: 130112 | D28: =VLOOKUP(B28,TB!$A$4:$B$109,2,0) -> Material cost:Receipt (pre-inspection) | E28: =+VLOOKUP(B28,TB!$A$5:$D$109,3,0) -> 0 | F28: =+VLOOKUP(B28,TB!$A$5:$D$109,4,0) -> 0
B29: 133090 | D29: =VLOOKUP(B29,TB!$A$4:$B$109,2,0) -> Other deposits | E29: =+VLOOKUP(B29,TB!$A$5:$D$109,3,0) -> 0 | F29: =+VLOOKUP(B29,TB!$A$5:$D$109,4,0) -> 0
D30: Accounts receivable and prepayments | E30: =SUM(E20:E29) -> 589449.14 | F30: =SUM(F20:F29) -> 616840.37
D31: SCHEDULE 4
B32: 101400 | D32: =VLOOKUP(B32,TB!$A$4:$B$109,2,0) -> Cash holdings - imprest floats for general purpose (replenishable) | E32: =+VLOOKUP(B32,TB!$A$5:$D$109,3,0) -> 5000 | F32: =+VLOOKUP(B32,TB!$A$5:$D$109,4,0) -> 5000
B33: 102601 | D33: FAB | E33: =+VLOOKUP(B33,TB!$A$5:$D$109,3,0) -> 1096737.3 | F33: =+VLOOKUP(B33,TB!$A$5:$D$109,4,0) -> 2219755.9
B34: 102101 | D34: =VLOOKUP(B34,TB!$A$4:$B$109,2,0) -> AED Current/Call Bank Acct | E34: =+VLOOKUP(B34,TB!$A$5:$D$109,3,0) -> 0 | F34: =+VLOOKUP(B34,TB!$A$5:$D$109,4,0) -> 0
B35: 105901 | D35: =VLOOKUP(B35,TB!$A$4:$B$109,2,0) -> AED AP Pyt - Clearing Acct | E35: =+VLOOKUP(B35,TB!$A$5:$D$109,3,0) -> 0 | F35: =+VLOOKUP(B35,TB!$A$5:$D$109,4,0) -> 0
D36: Cash & Bank Balances | E36: =SUM(E32:E35) -> 1101737.3 | F36: =SUM(F32:F35) -> 2224755.9
D37: SCHEDULE 5
B38: 200110 | D38: =VLOOKUP(B38,TB!$A$4:$B$109,2,0) -> Approved invoices - for payment | E38: =-VLOOKUP(B38,TB!$A$5:$D$109,3,0) -> 23276.12 | F38: =-VLOOKUP(B38,TB!$A$5:$D$109,4,0) -> 0
B39: 200130 | D39: =VLOOKUP(B39,TB!$A$4:$B$109,2,0) -> Accrued purchases - Invoice received pending approval | E39: =-VLOOKUP(B39,TB!$A$5:$D$109,3,0) -> 771221.17 | F39: =-VLOOKUP(B39,TB!$A$5:$D$109,4,0) -> 683588.08
B40: 215100 | D40: =VLOOKUP(B40,TB!$A$4:$B$109,2,0) -> Expense payroll accrual - pending payment | E40: =-VLOOKUP(B40,TB!$A$5:$D$109,3,0) -> 0 | F40: =-VLOOKUP(B40,TB!$A$5:$D$109,4,0) -> 0
B41: 211111 | D41: =VLOOKUP(B41,TB!$A$4:$B$109,2,0) -> Expense AP Accrual - Inventories in receiving area (pre-inspection) | E41: =-VLOOKUP(B41,TB!$A$5:$D$109,3,0) -> 14893.1 | F41: =-VLOOKUP(B41,TB!$A$5:$D$109,4,0) -> 48333.99
...

Sheet Expense Comparison
A1: ARIC FINANCIAL REPORTING
A3: Expense Comparison
C4: Particulars | D4: =+BS!C7 -> 44804 | E4: =+BS!E7 -> 44439 | F4: Change | G4: Percentage Change
C5: Personnel
A6: 511111 | B6: 412121 | C6: =VLOOKUP(B6,TB!$A$4:$B$109,2,0) -> Basic salary | D6: =+VLOOKUP(B6,TB!$A$55:$D$109,3,0) -> 691592.5 | E6: =+VLOOKUP(B6,TB!$A$55:$D$109,4,0) -> 644246.37 | F6: =D6-E6 -> 47346.13 | G6: =IFERROR(F6/E6,0) -> 0.073490721
A7: 511122 | B7: 412542 | C7: =VLOOKUP(B7,TB!$A$4:$B$109,2,0) -> Other allowances (miscellaneous) | D7: =+VLOOKUP(B7,TB!$A$55:$D$109,3,0) -> 0 | E7: =+VLOOKUP(B7,TB!$A$55:$D$109,4,0) -> 0 | F7: =D7-E7 -> 0 | G7: =IFERROR(F7/E7,0) -> 0
B8: 412110 | C8: =VLOOKUP(B8,TB!$A$4:$B$109,2,0) -> Consolidated pay (combined salaries and allowances) | D8: =+VLOOKUP(B8,TB!$A$55:$D$109,3,0) -> 0 | E8: =+VLOOKUP(B8,TB!$A$55:$D$109,4,0) -> 0 | F8: =D8-E8 -> 0 | G8: =IFERROR(F8/E8,0) -> 0
A9: 511129 | B9: 412521 | C9: =VLOOKUP(B9,TB!$A$4:$B$109,2,0) -> Administration allowance (including Mansab) | D9: =+VLOOKUP(B9,TB!$A$55:$D$109,3,0) -> 12000 | E9: =+VLOOKUP(B9,TB!$A$55:$D$109,4,0) -> 16000 | F9: =D9-E9 -> -4000 | G9: =IFERROR(F9/E9,0) -> -0.25
A10: 511133 | B10: 412125 | C10: =VLOOKUP(B10,TB!$A$4:$B$109,2,0) -> Cost of living adjustment pay (COLA) | D10: =+VLOOKUP(B10,TB!$A$55:$D$109,3,0) -> 355270.42 | E10: =+VLOOKUP(B10,TB!$A$55:$D$109,4,0) -> 323597.06 | F10: =D10-E10 -> 31673.36 | G10: =IFERROR(F10/E10,0) -> 0.09787901
A11: 511214 | B11: 412534 | C11: =VLOOKUP(B11,TB!$A$4:$B$109,2,0) -> School fee reimbursements | D11: =+VLOOKUP(B11,TB!$A$55:$D$109,3,0) -> 21395.5 | E11: =+VLOOKUP(B11,TB!$A$55:$D$109,4,0) -> 18889.13 | F11: =D11-E11 -> 2506.37 | G11: =IFERROR(F11/E11,0) -> 0.13268848
A12: 511216 | B12: 412184 | C12: =VLOOKUP(B12,TB!$A$4:$B$109,2,0) -> Vacation pay (including cash in lieu payment) | D12: =+VLOOKUP(B12,TB!$A$55:$D$109,3,0) -> 0 | E12: =+VLOOKUP(B12,TB!$A$55:$D$109,4,0) -> -16387.57 | F12: =D12-E12 -> 16387.57 | G12: =IFERROR(F12/E12,0) -> -1
A13: 511217 | B13: 416310 | C13: =VLOOKUP(B13,TB!$A$4:$B$109,2,0) -> Medical insurance premium | D13: =+VLOOKUP(B13,TB!$A$55:$D$109,3,0) -> 38285 | E13: =+VLOOKUP(B13,TB!$A$55:$D$109,4,0) -> 33528.35 | F13: =D13-E13 -> 4756.65 | G13: =IFERROR(F13/E13,0) -> 0.14186949
A14: 511218 | B14: 415220 | C14: =VLOOKUP(B14,TB!$A$4:$B$109,2,0) -> UAE visa requirement costs | D14: =+VLOOKUP(B14,TB!$A$55:$D$109,3,0) -> 0 | E14: =+VLOOKUP(B14,TB!$A$55:$D$109,4,0) -> 0 | F14: =D14-E14 -> 0 | G14: =IFERROR(F14/E14,0) -> 0
A15: 511221 | B15: 414120 | C15: =VLOOKUP(B15,TB!$A$4:$B$109,2,0) -> Gratuity - Non-pensionable employees | D15: =+VLOOKUP(B15,TB!$A$55:$D$109,3,0) -> 34474 | E15: =+VLOOKUP(B15,TB!$A$55:$D$109,4,0) -> 112548.68 | F15: =D15-E15 -> -78074.68 | G15: =IFERROR(F15/E15,0) -> -0.69369699
A16: 511222 | B16: 416110 | C16: =VLOOKUP(B16,TB!$A$4:$B$109,2,0) -> Employee travel costs - Fares | D16: =+VLOOKUP(B16,TB!$A$55:$D$109,3,0) -> 2293.28 | E16: =+VLOOKUP(B16,TB!$A$55:$D$109,4,0) -> 13072.15 | F16: =D16-E16 -> -10778.87 | G16: =IFERROR(F16/E16,0) -> -0.8245675
B17: 412590 | C17: =VLOOKUP(B17,TB!$A$4:$B$109,2,0) -> Rounding up cost of net pay | D17: =+VLOOKUP(B17,TB!$A$55:$D$109,3,0) -> 0.08 | E17: =+VLOOKUP(B17,TB!$A$55:$D$109,4,0) -> 0.76 | F17: =D17-E17 -> -0.68 | G17: =IFERROR(F17/E17,0) -> -0.89473684
A18: 511224 | B18: 415230 | C18: =VLOOKUP(B18,TB!$A$4:$B$109,2,0) -> Relocation expenses | D18: =+VLOOKUP(B18,TB!$A$55:$D$109,3,0) -> 0 | E18: =+VLOOKUP(B18,TB!$A$55:$D$109,4,0) -> 0 | F18: =+E18-D18 -> 0 | G18: =IFERROR(F18/E18,0) -> 0
A19: 511313 | B19: 415210 | C19: =VLOOKUP(B19,TB!$A$4:$B$109,2,0) -> Recruitment expenses | D19: =+VLOOKUP(B19,TB!$A$55:$D$109,3,0) -> 0 | E19: =+VLOOKUP(B19,TB!$A$55:$D$109,4,0) -> 0 | F19: =+E19-D19 -> 0 | G19: =IFERROR(F19/E19,0) -> 0
A20: 511412 | B20: 415320 | C20: =VLOOKUP(B20,TB!$A$4:$B$109,2,0) -> Employee Training costs - Travel and Accommodation | D20: =+VLOOKUP(B20,TB!$A$55:$D$109,3,0) -> 0 | E20: =+VLOOKUP(B20,TB!$A$55:$D$109,4,0) -> 0 | F20: =+E20-D20 -> 0 | G20: =IFERROR(F20/E20,0) -> 0
A21: 511228 | B21: 413121 | C21: =VLOOKUP(B21,TB!$A$4:$B$109,2,0) -> Temporary Staff Salary | D21: =+VLOOKUP(B21,TB!$A$55:$D$109,3,0) -> 0 | E21: =+VLOOKUP(B21,TB!$A$55:$D$109,4,0) -> 0 | F21: =+E21-D21 -> 0 | G21: =IFERROR(F21/E21,0) -> 0
C22: Personnel | D22: =SUM(D6:D21) -> 1155310.8 | E22: =SUM(E6:E21) -> 1145494.9 | F22: =SUM(F6:F21) -> 9815.85 | G22: =IFERROR(F22/E22,0) -> 0.0085690907
C23: Operating
A24: 511418 | B24: 428090 | C24: =VLOOKUP(B24,TB!$A$4:$B$109,2,0) -> Business Travel - Combined expenses | D24: =+VLOOKUP(B24,TB!$A$55:$D$109,3,0) -> 0 | E24: =+VLOOKUP(B24,TB!$A$55:$D$109,4,0) -> 0 | F24: =D24-E24 -> 0 | G24: =IFERROR(F24/E24,0) -> 0
A25: 511420 | B25: 425770 | C25: =VLOOKUP(B25,TB!$A$4:$B$109,2,0) -> Academic Missions - Combined expenses | D25: =+VLOOKUP(B25,TB!$A$55:$D$109,3,0) -> 0 | E25: =+VLOOKUP(B25,TB!$A$55:$D$109,4,0) -> 0 | F25: =D25-E25 -> 0 | G25: =IFERROR(F25/E25,0) -> 0
A26: 512113 | B26: 436110 | C26: =VLOOKUP(B26,TB!$A$4:$B$109,2,0) -> Printing supplies | D26: =+VLOOKUP(B26,TB!$A$55:$D$109,3,0) -> 0 | E26: =+VLOOKUP(B26,TB!$A$55:$D$109,4,0) -> 0 | F26: =D26-E26 -> 0 | G26: =IFERROR(F26/E26,0) -> 0
A27: 512114 | B27: 436120 | C27: =VLOOKUP(B27,TB!$A$4:$B$109,2,0) -> Stationery | D27: =+VLOOKUP(B27,TB!$A$55:$D$109,3,0) -> 0 | E27: =+VLOOKUP(B27,TB!$A$55:$D$109,4,0) -> 0 | F27: =D27-E27 -> 0 | G27: =IFERROR(F27/E27,0) -> 0
B28: 435350 | C28: Academic Publications | D28: =+VLOOKUP(B28,TB!$A$55:$D$109,3,0) -> 0 | E28: =+VLOOKUP(B28,TB!$A$55:$D$109,4,0) -> 0 | F28: =D28-E28 -> 0 | G28: =IFERROR(F28/E28,0) -> 0
A29: 512118 | B29: 435508 | C29: =VLOOKUP(B29,TB!$A$4:$B$109,2,0) -> Laboratory - Scientific | D29: =+VLOOKUP(B29,TB!$A$55:$D$109,3,0) -> 169384.76 | E29: =+VLOOKUP(B29,TB!$A$55:$D$109,4,0) -> 289152.86 | F29: =D29-E29 -> -119768.1 | G29: =IFERROR(F29/E29,0) -> -0.41420341
A30: 512125 | B30: 435910 | C30: =VLOOKUP(B30,TB!$A$4:$B$109,2,0) -> Furnishings | D30: =+VLOOKUP(B30,TB!$A$55:$D$109,3,0) -> 0 | E30: =+VLOOKUP(B30,TB!$A$55:$D$109,4,0) -> 0 | F30: =D30-E30 -> 0 | G30: =IFERROR(F30/E30,0) -> 0
A31: 512134 | B31: 427810 | C31: =VLOOKUP(B31,TB!$A$4:$B$109,2,0) -> Telephone and telefax charges | D31: =+VLOOKUP(B31,TB!$A$55:$D$109,3,0) -> 0 | E31: =+VLOOKUP(B31,TB!$A$55:$D$109,4,0) -> 0 | F31: =D31-E31 -> 0 | G31: =IFERROR(F31/E31,0) -> 0
A32: 512136 | B32: 426610 | C32: =VLOOKUP(B32,TB!$A$4:$B$109,2,0) -> Computer software licenses | D32: =+VLOOKUP(B32,TB!$A$55:$D$109,3,0) -> 0 | E32: =+VLOOKUP(B32,TB!$A$55:$D$109,4,0) -> 0 | F32: =D32-E32 -> 0 | G32: =IFERROR(F32/E32,0) -> 0
A33: 512144 | B33: 430330 | C33: =VLOOKUP(B33,TB!$A$4:$B$109,2,0) -> Rental - Motor vehicles | D33: =+VLOOKUP(B33,TB!$A$55:$D$109,3,0) -> 0 | E33: =+VLOOKUP(B33,TB!$A$55:$D$109,4,0) -> 0 | F33: =D33-E33 -> 0 | G33: =IFERROR(F33/E33,0) -> 0
A34: 512333 | B34: 428200 | C34: =VLOOKUP(B34,TB!$A$4:$B$109,2,0) -> Health,safety&environment awareness | D34: =+VLOOKUP(B34,TB!$A$55:$D$109,3,0) -> 0 | E34: =+VLOOKUP(B34,TB!$A$55:$D$109,4,0) -> 0 | F34: =D34-E34 -> 0 | G34: =IFERROR(F34/E34,0) -> 0
A35: 512151 | B35: 425900 | C35: =VLOOKUP(B35,TB!$A$4:$B$109,2,0) -> Entertainment and hospitality | D35: =+VLOOKUP(B35,TB!$A$55:$D$109,3,0) -> 0 | E35: =+VLOOKUP(B35,TB!$A$55:$D$109,4,0) -> 0 | F35: =D35-E35 -> 0 | G35: =IFERROR(F35/E35,0) -> 0
A36: 512152 | B36: 426900 | C36: =VLOOKUP(B36,TB!$A$4:$B$109,2,0) -> Postal, courier and other document delivery expenses | D36: =+VLOOKUP(B36,TB!$A$55:$D$109,3,0) -> 0 | E36: =+VLOOKUP(B36,TB!$A$55:$D$109,4,0) -> 0 | F36: =D36-E36 -> 0 | G36: =IFERROR(F36/E36,0) -> 0
A37: 512221 | B37: 425100 | C37: =VLOOKUP(B37,TB!$A$4:$B$109,2,0) -> Advertising | D37: =+VLOOKUP(B37,TB!$A$55:$D$109,3,0) -> 0 | E37: =+VLOOKUP(B37,TB!$A$55:$D$109,4,0) -> 0 | F37: =D37-E37 -> 0 | G37: =IFERROR(F37/E37,0) -> 0
A38: 512223 | B38: 425510 | C38: =VLOOKUP(B38,TB!$A$4:$B$109,2,0) -> Conferences, seminars and exhibitions and other events: - Local Events | D38: =+VLOOKUP(B38,TB!$A$55:$D$109,3,0) -> 350 | E38: =+VLOOKUP(B38,TB!$A$55:$D$109,4,0) -> 700 | F38: =D38-E38 -> -350 | G38: =IFERROR(F38/E38,0) -> -0.5
A39: 512225 | B39: 435519 | C39: =VLOOKUP(B39,TB!$A$4:$B$109,2,0) -> Photography - Consumable materials /Tools | D39: =+VLOOKUP(B39,TB!$A$55:$D$109,3,0) -> 0 | E39: =+VLOOKUP(B39,TB!$A$55:$D$109,4,0) -> 0 | F39: =D39-E39 -> 0 | G39: =IFERROR(F39/E39,0) -> 0
A40: 512241 | B40: 432120 | C40: =VLOOKUP(B40,TB!$A$4:$B$109,2,0) -> Bldg maintenance-Business premises | D40: =+VLOOKUP(B40,TB!$A$55:$D$109,3,0) -> 0 | E40: =+VLOOKUP(B40,TB!$A$55:$D$109,4,0) -> 0 | F40: =D40-E40 -> 0 | G40: =IFERROR(F40/E40,0) -> 0
... A45: 521116 | B45: 420130 | C45: =VLOOKUP(B45,TB!$A$4:$B$109,2,0) -> External Audit service | D45: =+VLOOKUP(B45,TB!$A$55:$D$109,3,0) -> 0 | E45: =+VLOOKUP(B45,TB!$A$55:$D$109,4,0) -> 0 | F45: =D45-E45 -> 0 | G45: =IFERROR(F45/E45,0) -> 0
...

Sheet Budget Comparison
A5: BUDGET COMPARISON - 2022 (BG 1 ONLY)
A7: Exp Category | B7: Oracle Code | C7: Oracle Account | D7: Budget (Jan - Dec 22) | E7: Expenses (Jan - Aug 22) | F7: Commitments | G7: Available Balance
A8: Personnel | B8: 412110 | C8: Consolidated pay (combined salaries and allowances) | D8: =_xlfn.IFNA(VLOOKUP(B8,[4]PIVOT!$A:$G,2,0),0) -> 3400 | E8: =_xlfn.IFNA(VLOOKUP(B8,[4]PIVOT!$A:$G,3,0),0) -> 0 | F8: =_xlfn.IFNA(VLOOKUP(B8,[4]PIVOT!$A:$G,4,0),0)+_xlfn.IFNA(VLOOKUP(B8,[4]PIVOT!$A:$G,5,0),0) -> 0 | G8: =+D8-E8-F8 -> 3400
B9: 412121 | C9: Basic salary | D9: =_xlfn.IFNA(VLOOKUP(B9,[4]PIVOT!$A:$G,2,0),0) -> 933059.13 | E9: =_xlfn.IFNA(VLOOKUP(B9,[4]PIVOT!$A:$G,3,0),0) -> 691592.5 | F9: =_xlfn.IFNA(VLOOKUP(B9,[4]PIVOT!$A:$G,4,0),0)+_xlfn.IFNA(VLOOKUP(B9,[4]PIVOT!$A:$G,5,0),0) -> 0 | G9: =+D9-E9-F9 -> 241466.63
B10: 412125 | C10: Cost of living adjustment pay (COLA) | D10: =_xlfn.IFNA(VLOOKUP(B10,[4]PIVOT!$A:$G,2,0),0) -> 522329 | E10: =_xlfn.IFNA(VLOOKUP(B10,[4]PIVOT!$A:$G,3,0),0) -> 355270.42 | F10: =_xlfn.IFNA(VLOOKUP(B10,[4]PIVOT!$A:$G,4,0),0)+_xlfn.IFNA(VLOOKUP(B10,[4]PIVOT!$A:$G,5,0),0) -> 0 | G10: =+D10-E10-F10 -> 167058.58
B11: 412184 | C11: Vacation pay (including cash in lieu payment) | D11: =_xlfn.IFNA(VLOOKUP(B11,[4]PIVOT!$A:$G,2,0),0) -> 0 | E11: =_xlfn.IFNA(VLOOKUP(B11,[4]PIVOT!$A:$G,3,0),0) -> 0 | F11: =_xlfn.IFNA(VLOOKUP(B11,[4]PIVOT!$A:$G,4,0),0)+_xlfn.IFNA(VLOOKUP(B11,[4]PIVOT!$A:$G,5,0),0) -> 0 | G11: =+D11-E11-F11 -> 0
B12: 412521 | C12: Administration allowance (including Mansab) | D12: =_xlfn.IFNA(VLOOKUP(B12,[4]PIVOT!$A:$G,2,0),0) -> 18100 | E12: =_xlfn.IFNA(VLOOKUP(B12,[4]PIVOT!$A:$G,3,0),0) -> 12000 | F12: =_xlfn.IFNA(VLOOKUP(B12,[4]PIVOT!$A:$G,4,0),0)+_xlfn.IFNA(VLOOKUP(B12,[4]PIVOT!$A:$G,5,0),0) -> 0 | G12: =+D12-E12-F12 -> 6100
B13: 412534 | C13: School fee reimbursements | D13: =_xlfn.IFNA(VLOOKUP(B13,[4]PIVOT!$A:$G,2,0),0) -> 29731 | E13: =_xlfn.IFNA(VLOOKUP(B13,[4]PIVOT!$A:$G,3,0),0) -> 21395.5 | F13: =_xlfn.IFNA(VLOOKUP(B13,[4]PIVOT!$A:$G,4,0),0)+_xlfn.IFNA(VLOOKUP(B13,[4]PIVOT!$A:$G,5,0),0) -> 0 | G13: =+D13-E13-F13 -> 8335.5
B14: 412542 | C14: Other allowances (miscellaneous) | D14: =_xlfn.IFNA(VLOOKUP(B14,[4]PIVOT!$A:$G,2,0),0) -> 0 | E14: =_xlfn.IFNA(VLOOKUP(B14,[4]PIVOT!$A:$G,3,0),0) -> 0 | F14: =_xlfn.IFNA(VLOOKUP(B14,[4]PIVOT!$A:$G,4,0),0)+_xlfn.IFNA(VLOOKUP(B14,[4]PIVOT!$A:$G,5,0),0) -> 0 | G14: =+D14-E14-F14 -> 0
B15: 412590 | C15: Rounding | D15: =_xlfn.IFNA(VLOOKUP(B15,[4]PIVOT!$A:$G,2,0),0) -> 10 | E15: =_xlfn.IFNA(VLOOKUP(B15,[4]PIVOT!$A:$G,3,0),0) -> 0.08 | F15: =_xlfn.IFNA(VLOOKUP(B15,[4]PIVOT!$A:$G,4,0),0)+_xlfn.IFNA(VLOOKUP(B15,[4]PIVOT!$A:$G,5,0),0) -> 0 | G15: =+D15-E15-F15 -> 9.92
B16: 414120 | C16: Gratuity - Non-pensionable employees | D16: =_xlfn.IFNA(VLOOKUP(B16,[4]PIVOT!$A:$G,2,0),0) -> 41721.62 | E16: =_xlfn.IFNA(VLOOKUP(B16,[4]PIVOT!$A:$G,3,0),0) -> 3624.64 | F16: =_xlfn.IFNA(VLOOKUP(B16,[4]PIVOT!$A:$G,4,0),0)+_xlfn.IFNA(VLOOKUP(B16,[4]PIVOT!$A:$G,5,0),0) -> 0 | G16: =+D16-E16-F16 -> 38096.98
B17: 415110 | C17: Govt contr - ADRB&Pension | D17: =_xlfn.IFNA(VLOOKUP(B17,[4]PIVOT!$A:$G,2,0),0) -> 0 | E17: =_xlfn.IFNA(VLOOKUP(B17,[4]PIVOT!$A:$G,3,0),0) -> 0 | F17: =_xlfn.IFNA(VLOOKUP(B17,[4]PIVOT!$A:$G,4,0),0)+_xlfn.IFNA(VLOOKUP(B17,[4]PIVOT!$A:$G,5,0),0) -> 0 | G17: =+D17-E17-F17 -> 0
B18: 415220 | C18: UAE visa requirement costs | D18: =_xlfn.IFNA(VLOOKUP(B18,[4]PIVOT!$A:$G,2,0),0) -> 0 | E18: =_xlfn.IFNA(VLOOKUP(B18,[4]PIVOT!$A:$G,3,0),0) -> 0 | F18: =_xlfn.IFNA(VLOOKUP(B18,[4]PIVOT!$A:$G,4,0),0)+_xlfn.IFNA(VLOOKUP(B18,[4]PIVOT!$A:$G,5,0),0) -> 0 | G18: =+D18-E18-F18 -> 0
B19: 415320 | C19: Employee Training costs - Travel and Accommodation | D19: =_xlfn.IFNA(VLOOKUP(B19,[4]PIVOT!$A:$G,2,0),0) -> 0 | E19: =_xlfn.IFNA(VLOOKUP(B19,[4]PIVOT!$A:$G,3,0),0) -> 0 | F19: =_xlfn.IFNA(VLOOKUP(B19,[4]PIVOT!$A:$G,4,0),0)+_xlfn.IFNA(VLOOKUP(B19,[4]PIVOT!$A:$G,5,0),0) -> 0 | G19: =+D19-E19-F19 -> 0
B20: 416110 | C20: Employee travel costs - Fares | D20: =_xlfn.IFNA(VLOOKUP(B20,[4]PIVOT!$A:$G,2,0),0) -> 13600 | E20: =_xlfn.IFNA(VLOOKUP(B20,[4]PIVOT!$A:$G,3,0),0) -> 2293.28 | F20: =_xlfn.IFNA(VLOOKUP(B20,[4]PIVOT!$A:$G,4,0),0)+_xlfn.IFNA(VLOOKUP(B20,[4]PIVOT!$A:$G,5,0),0) -> 0 | G20: =+D20-E20-F20 -> 11306.72
B21: 416310 | C21: Medical insurance premium | D21: =_xlfn.IFNA(VLOOKUP(B21,[4]PIVOT!$A:$G,2,0),0) -> 64170 | E21: =_xlfn.IFNA(VLOOKUP(B21,[4]PIVOT!$A:$G,3,0),0) -> 31464.74 | F21: =_xlfn.IFNA(VLOOKUP(B21,[4]PIVOT!$A:$G,4,0),0)+_xlfn.IFNA(VLOOKUP(B21,[4]PIVOT!$A:$G,5,0),0) -> 0 | G21: =+D21-E21-F21 -> 32705.26
A22: Operating | B22: 420900 | C22: Legal services | D22: =_xlfn.IFNA(VLOOKUP(B22,[4]PIVOT!$A:$G,2,0),0) -> 0 | E22: =_xlfn.IFNA(VLOOKUP(B22,[4]PIVOT!$A:$G,3,0),0) -> 0 | F22: =_xlfn.IFNA(VLOOKUP(B22,[4]PIVOT!$A:$G,4,0),0)+_xlfn.IFNA(VLOOKUP(B22,[4]PIVOT!$A:$G,5,0),0) -> 0 | G22: =+D22-E22-F22 -> 0
B23: 421000 | C23: Management consultancy | D23: =_xlfn.IFNA(VLOOKUP(B23,[4]PIVOT!$A:$G,2,0),0) -> 0 | E23: =_xlfn.IFNA(VLOOKUP(B23,[4]PIVOT!$A:$G,3,0),0) -> 0 | F23: =_xlfn.IFNA(VLOOKUP(B23,[4]PIVOT!$A:$G,4,0),0)+_xlfn.IFNA(VLOOKUP(B23,[4]PIVOT!$A:$G,5,0),0) -> 0 | G23: =+D23-E23-F23 -> 0
B24: 425100 | C24: Advertising | D24: =_xlfn.IFNA(VLOOKUP(B24,[4]PIVOT!$A:$G,2,0),0) -> 0 | E24: =_xlfn.IFNA(VLOOKUP(B24,[4]PIVOT!$A:$G,3,0),0) -> 0 | F24: =_xlfn.IFNA(VLOOKUP(B24,[4]PIVOT!$A:$G,4,0),0)+_xlfn.IFNA(VLOOKUP(B24,[4]PIVOT!$A:$G,5,0),0) -> 0 | G24: =+D24-E24-F24 -> 0
B25: 425300 | C25: Banking | D25: =_xlfn.IFNA(VLOOKUP(B25,[4]PIVOT!$A:$G,2,0),0) -> 0 | E25: =_xlfn.IFNA(VLOOKUP(B25,[4]PIVOT!$A:$G,3,0),0) -> 0 | F25: =_xlfn.IFNA(VLOOKUP(B25,[4]PIVOT!$A:$G,4,0),0)+_xlfn.IFNA(VLOOKUP(B25,[4]PIVOT!$A:$G,5,0),0) -> 0 | G25: =+D25-E25-F25 -> 0
B26: 425510 | C26: Conferences, seminars and exhibitions and other events: - Local Events | D26: =_xlfn.IFNA(VLOOKUP(B26,[4]PIVOT!$A:$G,2,0),0) -> 10000 | E26: =_xlfn.IFNA(VLOOKUP(B26,[4]PIVOT!$A:$G,3,0),0) -> 350 | F26: =_xlfn.IFNA(VLOOKUP(B26,[4]PIVOT!$A:$G,4,0),0)+_xlfn.IFNA(VLOOKUP(B26,[4]PIVOT!$A:$G,5,0),0) -> 0 | G26: =+D26-E26-F26 -> 9650
B27: 426610 | C27: Computer software licenses | D27: =_xlfn.IFNA(VLOOKUP(B27,[4]PIVOT!$A:$G,2,0),0) -> 0 | E27: =_xlfn.IFNA(VLOOKUP(B27,[4]PIVOT!$A:$G,3,0),0) -> 0 | F27: =_xlfn.IFNA(VLOOKUP(B27,[4]PIVOT!$A:$G,4,0),0)+_xlfn.IFNA(VLOOKUP(B27,[4]PIVOT!$A:$G,5,0),0) -> 0 | G27: =+D27-E27-F27 -> 0
B28: 426900 | C28: Postal, courier and other document delivery expenses | D28: =_xlfn.IFNA(VLOOKUP(B28,[4]PIVOT!$A:$G,2,0),0) -> 0 | E28: =_xlfn.IFNA(VLOOKUP(B28,[4]PIVOT!$A:$G,3,0),0) -> 0 | F28: =_xlfn.IFNA(VLOOKUP(B28,[4]PIVOT!$A:$G,4,0),0)+_xlfn.IFNA(VLOOKUP(B28,[4]PIVOT!$A:$G,5,0),0) -> 0 | G28: =+D28-E28-F28 -> 0
B29: 425741 | C29: Student stipend | D29: =_xlfn.IFNA(VLOOKUP(B29,[4]PIVOT!$A:$G,2,0),0) -> 0 | E29: =_xlfn.IFNA(VLOOKUP(B29,[4]PIVOT!$A:$G,3,0),0) -> 0 | F29: =_xlfn.IFNA(VLOOKUP(B29,[4]PIVOT!$A:$G,4,0),0)+_xlfn.IFNA(VLOOKUP(B29,[4]PIVOT!$A:$G,5,0),0) -> 0 | G29: =+D29-E29-F29 -> 0
B30: 425770 | C30: Academic Missions - Combined expenses | D30: =_xlfn.IFNA(VLOOKUP(B30,[4]PIVOT!$A:$G,2,0),0) -> 0 | E30: =_xlfn.IFNA(VLOOKUP(B30,[4]PIVOT!$A:$G,3,0),0) -> 0 | F30: =_xlfn.IFNA(VLOOKUP(B30,[4]PIVOT!$A:$G,4,0),0)+_xlfn.IFNA(VLOOKUP(B30,[4]PIVOT!$A:$G,5,0),0) -> 0 | G30: =+D30-E30-F30 -> 0
B31: 428090 | C31: Business Travel - Combined expenses | D31: =_xlfn.IFNA(VLOOKUP(B31,[4]PIVOT!$A:$G,2,0),0) -> 0 | E31: =_xlfn.IFNA(VLOOKUP(B31,[4]PIVOT!$A:$G,3,0),0) -> 0 | F31: =_xlfn.IFNA(VLOOKUP(B31,[4]PIVOT!$A:$G,4,0),0)+_xlfn.IFNA(VLOOKUP(B31,[4]PIVOT!$A:$G,5,0),0) -> 0 | G31: =+D31-E31-F31 -> 0
B32: 428200 | C32: Health,safety&environment awareness | D32: =_xlfn.IFNA(VLOOKUP(B32,[4]PIVOT!$A:$G,2,0),0) -> 0 | E32: =_xlfn.IFNA(VLOOKUP(B32,[4]PIVOT!$A:$G,3,0),0) -> 0 | F32: =_xlfn.IFNA(VLOOKUP(B32,[4]PIVOT!$A:$G,4,0),0)+_xlfn.IFNA(VLOOKUP(B32,[4]PIVOT!$A:$G,5,0),0) -> 0 | G32: =+D32-E32-F32 -> 0
B33: 428400 | C33: Sponsorship expenses/contributions | D33: =_xlfn.IFNA(VLOOKUP(B33,[4]PIVOT!$A:$G,2,0),0) -> 53835 | E33: =_xlfn.IFNA(VLOOKUP(B33,[4]PIVOT!$A:$G,3,0),0) -> 0 | F33: =_xlfn.IFNA(VLOOKUP(B33,[4]PIVOT!$A:$G,4,0),0)+_xlfn.IFNA(VLOOKUP(B33,[4]PIVOT!$A:$G,5,0),0) -> 0 | G33: =+D33-E33-F33 -> 53835
B34: 429900 | C34: Other services, not specifically mentioned elsewhere | D34: =_xlfn.IFNA(VLOOKUP(B34,[4]PIVOT!$A:$G,2,0),0) -> 0 | E34: =_xlfn.IFNA(VLOOKUP(B34,[4]PIVOT!$A:$G,3,0),0) -> 0 | F34: =_xlfn.IFNA(VLOOKUP(B34,[4]PIVOT!$A:$G,4,0),0)+_xlfn.IFNA(VLOOKUP(B34,[4]PIVOT!$A:$G,5,0),0) -> 0 | G34: =+D34-E34-F34 -> 0
... B42: 435910 | C42: Furnishings | D42: =_xlfn.IFNA(VLOOKUP(B42,[4]PIVOT!$A:$G,2,0),0) -> 0 | E42: =_xlfn.IFNA(VLOOKUP(B42,[4]PIVOT!$A:$G,3,0),0) -> 0 | F42: =_xlfn.IFNA(VLOOKUP(B42,[4]PIVOT!$A:$G,4,0),0)+_xlfn.IFNA(VLOOKUP(B42,[4]PIVOT!$A:$G,5,0),0) -> 0 | G42: =+D42-E42-F42 -> 0
A43: Capital | B43: 492200 | C43: Capital expense - Buildings | D43: =_xlfn.IFNA(VLOOKUP(B43,[4]PIVOT!$A:$G,2,0),0) -> 0 | E43: =_xlfn.IFNA(VLOOKUP(B43,[4]PIVOT!$A:$G,3,0),0) -> 0 | F43: =_xlfn.IFNA(VLOOKUP(B43,[4]PIVOT!$A:$G,4,0),0)+_xlfn.IFNA(VLOOKUP(B43,[4]PIVOT!$A:$G,5,0),0) -> 0 | G43: =+D43-E43-F43 -> 0
B44: 492308 | C44: Farming equipment & machinery | D44: =_xlfn.IFNA(VLOOKUP(B44,[4]PIVOT!$A:$G,2,0),0) -> 0 | E44: =_xlfn.IFNA(VLOOKUP(B44,[4]PIVOT!$A:$G,3,0),0) -> 0 | F44: =_xlfn.IFNA(VLOOKUP(B44,[4]PIVOT!$A:$G,4,0),0)+_xlfn.IFNA(VLOOKUP(B44,[4]PIVOT!$A:$G,5,0),0) -> 0 | G44: =+D44-E44-F44 -> 0
B45: 492316 | C45: Laboratory equipment | D45: =_xlfn.IFNA(VLOOKUP(B45,[4]PIVOT!$A:$G,2,0),0) -> 66900 | E45: =_xlfn.IFNA(VLOOKUP(B45,[4]PIVOT!$A:$G,3,0),0) -> 140198 | F45: =_xlfn.IFNA(VLOOKUP(B45,[4]PIVOT!$A:$G,4,0),0)+_xlfn.IFNA(VLOOKUP(B45,[4]PIVOT!$A:$G,5,0),0) -> -129789 | G45: =+D45-E45-F45 -> 56491
B46: 492610 | C46: Furniture & Fixtures - Offices | D46: =_xlfn.IFNA(VLOOKUP(B46,[4]PIVOT!$A:$G,2,0),0) -> 0 | E46: =_xlfn.IFNA(VLOOKUP(B46,[4]PIVOT!$A:$G,3,0),0) -> 0 | F46: =_xlfn.IFNA(VLOOKUP(B46,[4]PIVOT!$A:$G,4,0),0)+_xlfn.IFNA(VLOOKUP(B46,[4]PIVOT!$A:$G,5,0),0) -> 0 | G46: =+D46-E46-F46 -> 0
B47: 495140 | C47: Copyrights, patents and licenses | D47: =_xlfn.IFNA(VLOOKUP(B47,[4]PIVOT!$A:$G,2,0),0) -> 0 | E47: =_xlfn.IFNA(VLOOKUP(B47,[4]PIVOT!$A:$G,3,0),0) -> 0 | F47: =_xlfn.IFNA(VLOOKUP(B47,[4]PIVOT!$A:$G,4,0),0)+_xlfn.IFNA(VLOOKUP(B47,[4]PIVOT!$A:$G,5,0),0) -> 0 | G47: =+D47-E47-F47 -> 0
A48: Grand Total | D48: =SUM(D8:D47) -> 1947575.8 | E48: =SUM(E8:E47) -> 1427573.9 | F48: =SUM(F8:F47) -> -174474 | G48: =SUM(G8:G47) -> 694475.83
D49: =D48-[4]SYSTEM!$F$32 -> 0 | E49: =E48-[4]SYSTEM!$H$32 -> 0 | F49: =F48-[4]SYSTEM!$I$32-[4]SYSTEM!$J$32-[4]SYSTEM!$K$32 -> 0 | G49: =G48-[4]SYSTEM!$L$32 -> 0

Sheet In- Kind Summary
D1: In-Kind through Dec 31, 2022
A3: In - Kind Summary - 2022
A7: Other Support Services
B8: Support Services | C8: Plan 2022 | D8: Actual | E8: Balance
B9: Finance, HR, Facilities, Management, Marketing etc. | D9: =+'In Kind Calculation'!E14 -> 301581.01 | E9: =+C9-D9 -> -301581.01
B10: Space Cost | D10: =+'In Kind Calculation'!E26 -> 1110480 | E10: =+C10-D10 -> -1110480
B11: IT Package | D11: =+'In Kind Calculation'!E37 -> 59428.32 | E11: =+C11-D11 -> -59428.32
B12: Network and Multimedia Facilities | D12: =+'In Kind Calculation'!E44 -> 0 | E12: =+C12-D12 -> 0
B13: Total | C13: 200000 | D13: =SUM(D9:D12) -> 1471489.3 | E13: =SUM(E9:E12) -> -1471489.3
A15: Notes
A16: 1 | B16: Split of budget of AED 200K is not available
A17: 2 | B17: Rates are taken from the usual rates used by KU for the service pricing for the related parties

Sheet In Kind Calculation
A3: In Kind Contribution split
A5: Admin Support Cost
B6: Name of Staff | D6: No of Months | E6: Admin support cost recharge @ AED 5785.16
B7: Pradeep George | D7: 12 | E7: =ROUND(5785.16*D7,2) -> 69421.92
B8: Alia Ruzanna Binti Aziz | D8: =5+0.1 -> 5.1 | E8: =ROUND(5785.16*D8,2) -> 29504.32
B9: Meena Periya Samy | D9: =3+0.533333333333333 -> 3.5333333 | E9: =ROUND(5785.16*D9,2) -> 20440.9
B10: Abdulla Amer Hasan Ayyad | D10: 12 | E10: =ROUND(5785.16*D10,2) -> 69421.92
B11: Mohammed M M Alkrunz | D11: 12 | E11: =ROUND(5785.16*D11,2) -> 69421.92
B12: Laith Faisal Hussein Abuassi | D12: =4+0.0967741935483871 -> 4.0967742 | E12: =ROUND(5785.16*D12,2) -> 23700.49
B13: Ahmad Adnan Rashid Al Jarah | D13: =3+0.4 -> 3.4 | E13: =ROUND(5785.16*D13,2) -> 19669.54
B14: Total | E14: =SUM(E7:E13) -> 301581.01
A16: Space Cost
B17: Area details | C17: Area in sq mtr | D17: No of Months | E17: Space cost @ AED 2100
B18: L00021A | C18: 15.75 | D18: 12 | E18: =ROUND('[2]Price List'!$C$8/12*C18*D18,2) -> 33075
B19: L00021B | C19: 101.2 | D19: 12 | E19: =ROUND('[2]Price List'!$C$8/12*C19*D19,2) -> 212520
B20: L00021C | C20: 217.33 | D20: 12 | E20: =ROUND('[2]Price List'!$C$8/12*C20*D20,2) -> 456393
B21: L00021D | C21: 56.1 | D21: 12 | E21: =ROUND('[2]Price List'!$C$8/12*C21*D21,2) -> 117810
B22: L00021E | C22: 45.12 | D22: 12 | E22: =ROUND('[2]Price List'!$C$8/12*C22*D22,2) -> 94752
B23: L01027 | C23: 49.9 | D23: 12 | E23: =ROUND('[2]Price List'!$C$8/12*C23*D23,2) -> 104790
B24: L01027 A | C24: 22.9 | D24: 12 | E24: =ROUND('[2]Price List'!$C$8/12*C24*D24,2) -> 48090
B25: L01027 B | C25: 20.5 | D25: 12 | E25: =ROUND('[2]Price List'!$C$8/12*C25*D25,2) -> 43050
B26: Total | E26: =SUM(E18:E25) -> 1110480
A28: IT Package
B29: Name of Staff | D29: No of Months | E29: IT Package cost recharge @ AED 1140
B30: Pradeep George | D30: 12 | E30: =ROUND(1140*D30,2) -> 13680
B31: Alia Ruzanna Binti Aziz | D31: 5.1 | E31: =ROUND(1140*D31,2) -> 5814
B32: Meena Periya Samy | D32: 3.5333333 | E32: =ROUND(1140*D32,2) -> 4028
B33: Abdulla Amer Hasan Ayyad | D33: 12 | E33: =ROUND(1140*D33,2) -> 13680
B34: Mohammed M M Alkrunz | D34: 12 | E34: =ROUND(1140*D34,2) -> 13680
B35: Laith Faisal Hussein Abuassi | D35: 4.0967742 | E35: =ROUND(1140*D35,2) -> 4670.32
B36: Ahmad Adnan Rashid Al Jarah | D36: 3.4 | E36: =ROUND(1140*D36,2) -> 3876
B37: Total | E37: =SUM(E30:E36) -> 59428.32
A40: Network and Multimedia facilities
B41: Name of Staff | C41: No of Labs | D41: No of Months | E41: Multimedia cost recharge @ AED 65832
B44: Total | E44: =SUM(E42:E43) -> 0

Sheet Other Income
A5: Other Income Breakup
A6: Sr | B6: Inv No | C6: Date | D6: Client Name | E6: Particulars | F6: Amount
A7: 1
A8: =+A7+1 -> 2
A9: =+A8+1 -> 3
A10: =+A9+1 -> 4
A11: =+A10+1 -> 5
A12: =+A11+1 -> 6
A13: =+A12+1 -> 7
A14: =+A13+1 -> 8
A15: =+A14+1 -> 9
A16: =+A15+1 -> 10
A17: =+A16+1 -> 11
A18: =+A17+1 -> 12
F19: =SUM(F7:F18) -> 0 | I19: =+F19+TB!C54 -> 0

Sheet Fixed Assets
A3: FIXED ASSETS SCHEDULE
A4: =+BS!A4 -> As at 31 August 2022
B6: ASSETS | C6: GROSS BOOK VALUE | H6: ACCUMULATED DEPRECIATION | M6: NET BOOK VALUE
C7: OPENING BALANCE | D7: RECLASSIFICATIONS | E7: ADDITIONS | F7: RETIREMENTS | G7: CLOSING BALANCE | H7: OPENING BALANCE | I7: RECLASSIFICATIONS | J7: Depreciation for 2022 | K7: Retirements | L7: CLOSING BALANCE | M7: OPENING BALANCE | N7: CLOSING BALANCE
B9: Non-current assets
B10: Building | C10: =VLOOKUP(171220,'TB-Aug 22'!A:F,3,0) -> 7277144.4 | E10: =G10-C10 -> 0 | G10: =VLOOKUP(171220,TB!A:E,3,0) -> 7277144.4 | H10: =VLOOKUP(171260,'TB-Aug 22'!A:F,3,0) -> -1815200.1 | J10: =-VLOOKUP(475210,TB!A:E,3,0) -> -242508.9 | L10: =+H10+J10+I10+K10 -> -2057709 | M10: =+C10+H10 -> 5461944.3 | N10: =+G10+L10 -> 5219435.4
B11: Furniture & Fixtures | C11: =VLOOKUP(172020,'TB-Aug 22'!A:F,3,0) -> 112725 | E11: =G11-C11 -> 0 | G11: =VLOOKUP(172020,TB!A:E,3,0) -> 112725 | H11: =VLOOKUP(172060,'TB-Aug 22'!A:F,3,0) -> -108973.62 | J11: =-VLOOKUP(475240,TB!A:E,3,0) -> -3660.98 | L11: =+H11+J11+I11+K11 -> -112634.6 | M11: =+C11+H11 -> 3751.38 | N11: =+G11+L11 -> 90.4
B12: Plant, Machinery & Equipment | C12: =VLOOKUP(171320,'TB-Aug 22'!A:F,3,0) -> 6183421.3 | E12: =G12-C12 -> 19998 | G12: =VLOOKUP(171320,TB!A:E,3,0) -> 6203419.3 | H12: =VLOOKUP(171360,'TB-Aug 22'!A:F,3,0) -> -5630550.3 | J12: =-VLOOKUP(475220,TB!A:E,3,0) -> -272581.73 | L12: =+H12+J12+I12+K12 -> -5903132 | M12: =+C12+H12 -> 552871.04 | N12: =+G12+L12 -> 300287.31
B13: Intangible | C13: =VLOOKUP(173120,'TB-Aug 22'!A:F,3,0) -> 436988.01 | E13: =G13-C13 -> 0 | G13: =VLOOKUP(173120,TB!A:E,3,0) -> 436988.01 | H13: =VLOOKUP(173160,'TB-Aug 22'!A:F,3,0) -> -436988.01 | J13: =-VLOOKUP(475250,TB!A:E,3,0) -> 0 | L13: =+H13+J13+I13+K13 -> -436988.01 | M13: =+C13+H13 -> 0 | N13: =+G13+L13 -> 0
B14: Asset In Progress - Building | C14: 0 | G14: =+C14+E14+D14+F14 -> 0 | H14: 0 | L14: =+H14+J14+I14+K14 -> 0 | M14: =+C14+H14 -> 0 | N14: =+G14+L14 -> 0
B15: Asset In Progress - PME | C15: 0 | E15: =+'TB-Aug 22'!F28 -> 113350 | G15: =+C15+E15+D15+F15 -> 113350 | H15: 0 | L15: =+H15+J15+I15+K15 -> 0 | M15: =+C15+H15 -> 0 | N15: =+G15+L15 -> 113350
B16: Asset in Clearing | C16: 0 | E16: =+'TB-Aug 22'!F24 -> 0 | G16: =+C16+E16+D16+F16 -> 0 | H16: 0 | L16: =+H16+J16+I16+K16 -> 0 | M16: =+C16+H16 -> 0 | N16: =+G16+L16 -> 0
B17: TOTAL OPERATING ASSETS | C17: =SUM(C10:C16) -> 14010279 | D17: =SUM(D10:D16) -> 0 | E17: =SUM(E10:E16) -> 133348 | F17: =SUM(F10:F16) -> 0 | G17: =SUM(G10:G16) -> 14143627 | H17: =SUM(H10:H16) -> -7991712 | I17: =SUM(I10:I16) -> 0 | J17: =SUM(J10:J16) -> -518751.61 | ... N17: =SUM(N10:N16) -> 5633163.1
C18: =SUM('TB-Aug 22'!C24,'TB-Aug 22'!C25,'TB-Aug 22'!C27,'TB-Aug 22'!C28,'TB-Aug 22'!C30,'TB-Aug 22'!C32)-C17 -> 0 | J18: =J17+SUM(TB!C101:C103) -> 0 | N18: =SUM(TB!C25:C38)-N17 -> 0

Sheet Petty Cash
A5: Petty Cash
A6: Sr | B6: Employee Name | C6: Amount
A7: 1 | B7: Pradeep George | C7: 5000
C8: =SUM(C7:C7) -> 5000 | F8: =+C8-TB!C5 -> 0

Sheet Cash and Bank
A1: ARIC
A2: Monthly Bank Reconciliation Report
A3: FAB A/C: 4021003284369050
A4: Statement Date: 31/Aug/2022
F5: AED
A7: Balance as per Books
B8: Cash Account (102601) | E8: 1096737.3
B9: Clearing Account (105901) | E9: 0 | F9: =+E8+E9 -> 1096737.3 | G9: =F9-TB!C6-E9 -> 0
A11: Add Outstanding Checks issued :
A12: Date | B12: Check Number | C12: Amount
B23: Total Outstanding Checks | F23: =SUM(C13:C21) -> 0
A27: Subtotal | F27: =F9+F23 -> 1096737.3
A29: Subtract Checks to be recorded:
B31: Check Number | D31: Amount
B36: Total Checks to be recorded | F36: =SUM(D32:D34) -> 0
A38: Subtract Deposits in Transit:
B40: Total Deposits in Transit | F40: =+D39 -> 0
A42: Computed Book Balance | F42: =F27-F40-F36 -> 1096737.3
A45: Ending Balance from Bank Statement | F45: 1096737.3
A47: Difference | F47: =F42-F45 -> 0

Sheet Housing Advances
A5: Housing Advances
B6: Cheq-No. | C6: Emp No | D6: Name | E6: Paid Loan | F6: 2017 Balance | G6: 2018 Costing Report | H6: 2018 AP | I6: 2018 Balance
I10: =SUM(I7:I9) -> 0 | K10: =+I10-TB!C14 -> 0

Sheet Related Party Balance
A5: Due to Related Party
A6: Date | B6: Ref | C6: Description | D6: Amount (AED) | E6: Sub Total
C18: TOTAL | D18: =SUM(D7:D17) -> 0 | E18: =SUM(E7:E17) -> 0 | H18: =+E18+TB!C17 -> 0

Sheet AR
A5: Accounts Receivable
A6: Sr | B6: Inv No | C6: Date | D6: Client Name | E6: Particulars | F6: Amount
A7: 1 | B7: 406000007 | C7: 44785 | D7: Khalifa University of Science and Technology | E7: KUJ - ARIC transaction for July 2022 | F7: 14514
F10: =SUM(F7:F9) -> 14514 | I10: =+F10-TB!C12 -> 0

Sheet Other Deposits
A5: Other Deposits
A6: Sr | B6: Inv No | C6: Date | D6: Client Name | E6: Particulars | F6: Amount
A7: 1
F8: =SUM(F7:F7) -> 0 | I8: =+F8-TB!C24 -> 0

Sheet Advances to Vendors 
A2: Advances to Vendors-120330
A3: =TB!A2 -> 44804
A8: Vendor Name | B8: Inv No | C8: Date | D8: Amount | E8: Comment
A9: HOT ZONE SOLUTIONS MIDDLE EAST MEASUREMENT AND CONTROL EQUIPMENT L.L.C. | B9: 8434200070 | C9: 43638 | D9: 513398.54 | E9: 70% Advance PO (8434200070)
A10: TYGAVAC ADVANCED MATERIALS LTD | B10: 8434200096 | C10: 44538 | D10: 43559.52 | E10: 100% Advance payment
A11: TOTAL | D11: =SUM(D9:D10) -> 556958.06 | I11: =+[3]TB!C15-[3]TB!C15 -> 0
C13: TB | D13: =TB!C16 -> 556958.06
C14: Difference | D14: =D11-D13 -> 0

Sheet Expense AP Accrual 
A2: Expense AP Accrual ( Material Received, invoice not recorded)-211111
A3: =TB!A2 -> 44804
A5: Party Name | B5: PO Number | C5: 2021 Balance | D5: 2022 Movement | E5: 2022 Balance
A6: WOLLSCHLAEGER TECHNICAL SYSTEMS L.L.C. | B6: 8434200092 | C6: 48334 | D6: =-48334 -> -48334 | E6: =C6+D6 -> 0
A7: BESOMI ELECTRONIC L.L.C. | B7: 8434200104 | D7: =6850-6850 -> 0 | E7: =C7+D7 -> 0
A8: ATLAS COPCO SERVICES MIDDEL EAST OMC - DUBAI | B8: 8434200105 | D8: 14893.1 | E8: =C8+D8 -> 14893.1
A9: TOTAL | C9: =SUM(C6:C8) -> 48334 | D9: =SUM(D6:D8) -> -33440.9 | E9: =SUM(E6:E8) -> 14893.1
D12: TB | E12: =TB!C43 -> -14893.1
D13: Difference | E13: =E9+E12 -> 0

Sheet AP Ageing 
A2: AP Aging-200110
A3: =TB!A2 -> 44804
A7: Supplier Name | B7: Transaction Number | C7: Voucher Number | D7: Invoice Date | E7: Invoice Recieved Date | F7: Amount | G7: Days Due | H7: 0-30 | I7: 31-60 | J7: 61-90 | K7: 91-180 | L7: 181-360 | M7: More than 361 Days | N7: Total
A8: BESOMI ELECTRONIC L.L.C. | B8: SI-21936 | C8: 843J000723 | D8: 44737 | E8: 44799 | F8: 1015.35 | G8: =$A$3-E8 -> 5 | H8: =(IF(AND($G8>-100,$G8<31),+$F8,0)) -> 1015.35 | I8: =(IF(AND($G8>30,$G8<61),+$F8,0)) -> 0 | J8: =(IF(AND($G8>60,$G8<91),++$F8,0)) -> 0 | K8: =(IF(AND($G8>90,$G8<181),++$F8,0)) -> 0 | L8: =(IF(AND($G8>180,$G8<361),+$F8,0)) -> 0 | M8: =(IF(G8>361,+C8,0)) -> 0 | N8: =SUM(H8:M8) -> 1015.35
A9: BESOMI ELECTRONIC L.L.C. | B9: BES-2026236-01 | C9: 843J000724 | D9: 44733 | E9: 44799 | F9: 1837.5 | G9: =$A$3-E9 -> 5 | H9: =(IF(AND($G9>-100,$G9<31),+$F9,0)) -> 1837.5 | I9: =(IF(AND($G9>30,$G9<61),+$F9,0)) -> 0 | J9: =(IF(AND($G9>60,$G9<91),++$F9,0)) -> 0 | K9: =(IF(AND($G9>90,$G9<181),++$F9,0)) -> 0 | L9: =(IF(AND($G9>180,$G9<361),+$F9,0)) -> 0 | M9: =(IF(G9>361,+C9,0)) -> 0 | N9: =SUM(H9:M9) -> 1837.5
A10: BESOMI ELECTRONIC L.L.C. | B10: SI-32711 | C10: 843J000725 | D10: 44748 | E10: 44803 | F10: 2352 | G10: =$A$3-E10 -> 1 | H10: =(IF(AND($G10>-100,$G10<31),+$F10,0)) -> 2352 | I10: =(IF(AND($G10>30,$G10<61),+$F10,0)) -> 0 | J10: =(IF(AND($G10>60,$G10<91),++$F10,0)) -> 0 | K10: =(IF(AND($G10>90,$G10<181),++$F10,0)) -> 0 | L10: =(IF(AND($G10>180,$G10<361),+$F10,0)) -> 0 | M10: =(IF(G10>361,+C10,0)) -> 0 | N10: =SUM(H10:M10) -> 2352
A11: BESOMI ELECTRONIC L.L.C. | B11: SI-31231 | C11: 843J000726 | D11: 44725 | E11: 44803 | F11: 231 | G11: =$A$3-E11 -> 1 | H11: =(IF(AND($G11>-100,$G11<31),+$F11,0)) -> 231 | I11: =(IF(AND($G11>30,$G11<61),+$F11,0)) -> 0 | J11: =(IF(AND($G11>60,$G11<91),++$F11,0)) -> 0 | K11: =(IF(AND($G11>90,$G11<181),++$F11,0)) -> 0 | L11: =(IF(AND($G11>180,$G11<361),+$F11,0)) -> 0 | M11: =(IF(G11>361,+C11,0)) -> 0 | N11: =SUM(H11:M11) -> 231
A12: KHALIFA UNIVERSITY OF SCIENCE TECHNOLOGY AND RESEARCH | B12: 401000435 | C12: 843J000728 | D12: 44771 | E12: 44784 | F12: 10460.27 | G12: =$A$3-E12 -> 20 | H12: =(IF(AND($G12>-100,$G12<31),+$F12,0)) -> 10460.27 | I12: =(IF(AND($G12>30,$G12<61),+$F12,0)) -> 0 | J12: =(IF(AND($G12>60,$G12<91),++$F12,0)) -> 0 | K12: =(IF(AND($G12>90,$G12<181),++$F12,0)) -> 0 | L12: =(IF(AND($G12>180,$G12<361),+$F12,0)) -> 0 | M12: =(IF(G12>361,+C12,0)) -> 0 | N12: =SUM(H12:M12) -> 10460.27
A13: KHALIFA UNIVERSITY OF SCIENCE TECHNOLOGY AND RESEARCH | B13: 401000441 | C13: 843J000729 | D13: 44771 | E13: 44784 | F13: 7380 | G13: =$A$3-E13 -> 20 | H13: =(IF(AND($G13>-100,$G13<31),+$F13,0)) -> 7380 | I13: =(IF(AND($G13>30,$G13<61),+$F13,0)) -> 0 | J13: =(IF(AND($G13>60,$G13<91),++$F13,0)) -> 0 | K13: =(IF(AND($G13>90,$G13<181),++$F13,0)) -> 0 | L13: =(IF(AND($G13>180,$G13<361),+$F13,0)) -> 0 | M13: =(IF(G13>361,+C13,0)) -> 0 | N13: =SUM(H13:M13) -> 7380
A14: Total | F14: =SUM(F8:F13) -> 23276.12 | G14: =SUM(G11:G11) -> 1 | H14: =SUM(H8:H13) -> 23276.12 | I14: =SUM(I8:I13) -> 0 | J14: =SUM(J8:J13) -> 0 | K14: =SUM(K8:K13) -> 0 | L14: =SUM(L8:L13) -> 0 | M14: =SUM(M8:M13) -> 0 | N14: =SUM(N8:N13) -> 23276.12
M16: TB | N16: =VLOOKUP(200110,TB!A:C,3,0) -> -23276.12
M17: Difference | N17: =N14+N16 -> 0

Sheet AP Accruals
A2: AP Accruals-200130
A3: =TB!A2 -> 44804
B6: Period | C6: Party | D6: Reference | E6: 2021 Balance | F6: 2022 Transactions | G6: 2022 Balance
C7: Aerospace Holding | D7: Feb to Dec20 (Remaining Nov&Dec20) | E7: 58333.333 | G7: =E7+F7 -> 58333.333
C8: Aerospace Holding | D8: Jan to Dec 2021 | E8: 350000 | G8: =E8+F8 -> 350000
B9: 44531 | C9: PRECISE TRADING L.L.C. | D9: 843J000646 | E9: 1937 | F9: =-E9 -> -1937 | G9: =E9+F9 -> 0
B10: 44531 | C10: Deloitte | D10: Audit fee 2021 | E10: 45450 | F10: -22725 | G10: =E10+F10 -> 22725
B11: 44531 | C11: Deloitte | D11: Audit fee 2021 - Translation | E11: 5000 | G11: =E11+F11 -> 5000
C12: Aerospace Holding | D12: AHC recharge -Jan/May22 | F12: =(29166.67*3)+(29166.66*2) -> 145833.33 | G12: =E12+F12 -> 145833.33
B13: 44713 | C13: Aerospace Holding | D13: AHC recharge -June22 | F13: 29166.66 | G13: =E13+F13 -> 29166.66
B14: 44743 | C14: Aerospace Holding | D14: AHC recharge -July22 | F14: 29166.66 | G14: =E14+F14 -> 29166.66
B15: 44774 | C15: Aerospace Holding | D15: AHC recharge-Aug22 | F15: 29166.66 | G15: =E15+F15 -> 29166.66
B16: 44713 | C16: KUST | D16: KU Recharge- Dr. Wesley-Dn 401000429 | E16: 0 | F16: 10460.27 | G16: =E16+F16 -> 10460.27
B17: June | C17: KUST | D17: Satish payment chargebacks For Apr & May22-DN 406000004 & 4060000029,028.005 | E17: 0 | F17: 29028 | G17: =E17+F17 -> 29028
B18: July | C18: KUX | D18: Salary recharge for July 2022 DN- 402000242 | F18: 26404.1
B19: July | C19: KUST | D19: Salary Recharge of Researchers Payroll Jul 2022- 401000441 | F19: -7380
B20: 44774 | C20: KUX | D20: DN 402000251- Salary recharge Aug | F20: 17220 | G20: =E20+F20 -> 17220
B21: 44774 | C21: KUST | D21: DN 401000448- Salary recharge Aug Dr. Wesley | F21: 10460.27 | G21: =E21+F21 -> 10460.27
B22: 44795 | C22: KUST | D22: DN 401000452 -Salary recharges for Aug 2022 | F22: 7380 | G22: =E22+F22 -> 7380
B23: 44774 | C23: KUST | D23: DN 401000458-ARIC medical Insurance 202 | F23: 27281 | G23: =E23+F23 -> 27281
B24: TOTAL | E24: =SUM(E7:E21) -> 460720.33 | F24: =SUM(F7:F21) -> 294863.95 | G24: =SUM(G7:G23) -> 771221.18
G26: =VLOOKUP(200130,TB!A:E,3,0)+G24 -> 0.012727273

Sheet TB
A1: TRIAL BALANCE
A2: 44804
A4: ORACLE ACCOUNT | B4: ORACLE ACCOUNT TITLE | C4: =A2 -> 44804 | D4: =+C4-365 -> 44439 | E4: Balance Sheet / Income Statement Classification
A5: 101400 | B5: Cash holdings - imprest floats for general purpose (replenishable) | C5: =_xlfn.IFNA(VLOOKUP(A5,'TB-Aug 22'!A:F,6,0),0) -> 5000 | D5: =_xlfn.IFNA(VLOOKUP(A5,'TB-Aug21'!A:F,6,0),0) -> 5000 | E5: Bank Balances and Cash | I5: =VLOOKUP(#REF!,#REF!,9,FALSE) -> #REF!
A6: 102601 | B6: AED Bank Acct No.6 | C6: =_xlfn.IFNA(VLOOKUP(A6,'TB-Aug 22'!A:F,6,0),0) -> 1096737.3 | D6: =_xlfn.IFNA(VLOOKUP(A6,'TB-Aug21'!A:F,6,0),0) -> 2219755.9 | E6: Bank Balances and Cash | I6: =VLOOKUP(#REF!,#REF!,9,FALSE) -> #REF!
A7: 101901 | B7: Cash in Transit - AED | C7: =_xlfn.IFNA(VLOOKUP(A7,'TB-Aug 22'!A:F,6,0),0) -> 0 | D7: =_xlfn.IFNA(VLOOKUP(A7,'TB-Aug21'!A:F,6,0),0) -> 0 | E7: Bank Balances and Cash
A8: 102101 | B8: AED Current/Call Bank Acct | C8: =_xlfn.IFNA(VLOOKUP(A8,'TB-Aug 22'!A:F,6,0),0) -> 0 | D8: =_xlfn.IFNA(VLOOKUP(A8,'TB-Aug21'!A:F,6,0),0) -> 0 | E8: Bank Balances and Cash
A9: 105901 | B9: AED AP Pyt - Clearing Acct | C9: =_xlfn.IFNA(VLOOKUP(A9,'TB-Aug 22'!A:F,6,0),0) -> 0 | D9: =_xlfn.IFNA(VLOOKUP(A9,'TB-Aug21'!A:F,6,0),0) -> 0 | E9: Bank Balances and Cash
A10: 110101 | B10: AED Term Deposit - Bank No.1 | C10: =_xlfn.IFNA(VLOOKUP(A10,'TB-Aug 22'!A:F,6,0),0) -> 0 | D10: =_xlfn.IFNA(VLOOKUP(A10,'TB-Aug21'!A:F,6,0),0) -> 0 | E10: Bank Balances and Cash | I10: =VLOOKUP(#REF!,#REF!,9,FALSE) -> #REF!
A11: 120123 | B11: Goods and services Tax Receivable | C11: =_xlfn.IFNA(VLOOKUP(A11,'TB-Aug 22'!A:F,6,0),0) -> 0 | D11: =_xlfn.IFNA(VLOOKUP(A11,'TB-Aug21'!A:F,6,0),0) -> 47619.05 | E11: CL-Amount Due to a Related Party
A12: 120140 | B12: Goods and services sales receivable | C12: =_xlfn.IFNA(VLOOKUP(A12,'TB-Aug 22'!A:F,6,0),0) -> 14514 | D12: =_xlfn.IFNA(VLOOKUP(A12,'TB-Aug21'!A:F,6,0),0) -> -47619.05 | E12: CL-Amount Due to a Related Party
A13: 120180 | B13: Accounts Receivable - General | C13: =_xlfn.IFNA(VLOOKUP(A13,'TB-Aug 22'!A:F,6,0),0) -> 0 | D13: =_xlfn.IFNA(VLOOKUP(A13,'TB-Aug21'!A:F,6,0),0) -> 0 | E13: Prepayments and Other Receivables
A14: 120214 | B14: Rent support loans to employees | C14: =_xlfn.IFNA(VLOOKUP(A14,'TB-Aug 22'!A:F,6,0),0) -> 0 | D14: =_xlfn.IFNA(VLOOKUP(A14,'TB-Aug21'!A:F,6,0),0) -> 0 | E14: Prepayments and Other Receivables
A15: 120310 | B15: Contract advances | C15: =_xlfn.IFNA(VLOOKUP(A15,'TB-Aug 22'!A:F,6,0),0) -> 0 | D15: =_xlfn.IFNA(VLOOKUP(A15,'TB-Aug21'!A:F,6,0),0) -> 0 | E15: Prepayments and Other Receivables | I15: =VLOOKUP(#REF!,#REF!,9,FALSE) -> #REF!
A16: 120330 | B16: Other advances to vendors | C16: =_xlfn.IFNA(VLOOKUP(A16,'TB-Aug 22'!A:F,6,0),0) -> 556958.06 | D16: =_xlfn.IFNA(VLOOKUP(A16,'TB-Aug21'!A:F,6,0),0) -> 513398.54 | E16: Prepayments and Other Receivables | I16: =VLOOKUP(#REF!,#REF!,9,FALSE) -> #REF!
A17: 121010 | B17: Inter-company Receivable(Payable) | C17: =_xlfn.IFNA(VLOOKUP(A17,'TB-Aug 22'!A:F,6,0),0) -> 0 | D17: =_xlfn.IFNA(VLOOKUP(A17,'TB-Aug21'!A:F,6,0),0) -> 0 | E17: CL-Amount Due to a Related Party
A18: 125110 | B18: Accrued Interest on bank deposits | C18: =_xlfn.IFNA(VLOOKUP(A18,'TB-Aug 22'!A:F,6,0),0) -> 0 | D18: =_xlfn.IFNA(VLOOKUP(A18,'TB-Aug21'!A:F,6,0),0) -> 0 | E18: Prepayments and Other Receivables | I18: =VLOOKUP(#REF!,#REF!,9,FALSE) -> #REF!
A19: 126510 | B19: Input VAT recoverable | C19: =_xlfn.IFNA(VLOOKUP(A19,'TB-Aug 22'!A:F,6,0),0) -> 17977.08 | D19: =_xlfn.IFNA(VLOOKUP(A19,'TB-Aug21'!A:F,6,0),0) -> 103441.83 | E19: Prepayments and Other Receivables
A20: 126550 | B20: R C input VAT recoverable on Services | C20: =_xlfn.IFNA(VLOOKUP(A20,'TB-Aug 22'!A:F,6,0),0) -> 415.11 | D20: =_xlfn.IFNA(VLOOKUP(A20,'TB-Aug21'!A:F,6,0),0) -> 19398.17 | E20: Prepayments and Other Receivables
A21: 130112 | B21: Material cost:Receipt (pre-inspection) | C21: =_xlfn.IFNA(VLOOKUP(A21,'TB-Aug 22'!A:F,6,0),0) -> 0 | D21: =_xlfn.IFNA(VLOOKUP(A21,'TB-Aug21'!A:F,6,0),0) -> 0 | E21: Prepayments and Other Receivables
A22: 132021 | B22: Prepayments-Asset Clearing (for setup) | C22: =_xlfn.IFNA(VLOOKUP(A22,'TB-Aug 22'!A:F,6,0),0) -> 0 | D22: =_xlfn.IFNA(VLOOKUP(A22,'TB-Aug21'!A:F,6,0),0) -> 0 | E22: Prepayments and Other Receivables
A23: 132020 | B23: Prepayments-Asset Cost (for setup) | C23: =_xlfn.IFNA(VLOOKUP(A23,'TB-Aug 22'!A:F,6,0),0) -> 0 | D23: =_xlfn.IFNA(VLOOKUP(A23,'TB-Aug21'!A:F,6,0),0) -> 0 | E23: Prepayments and Other Receivables
A24: 133090 | B24: Other deposits | C24: =_xlfn.IFNA(VLOOKUP(A24,'TB-Aug 22'!A:F,6,0),0) -> 0 | D24: =_xlfn.IFNA(VLOOKUP(A24,'TB-Aug21'!A:F,6,0),0) -> 0 | E24: Prepayments and Other Receivables
A25: 171050 | B25: Provisional Asset (all categories for setup acct for accrual | C25: =_xlfn.IFNA(VLOOKUP(A25,'TB-Aug 22'!A:F,6,0),0) -> 0 | D25: =_xlfn.IFNA(VLOOKUP(A25,'TB-Aug21'!A:F,6,0),0) -> -203.88 | E25: NCA-Furniture and Equipment
A26: 171220 | B26: Buildings:Asset cost | C26: =_xlfn.IFNA(VLOOKUP(A26,'TB-Aug 22'!A:F,6,0),0) -> 7277144.4 | D26: =_xlfn.IFNA(VLOOKUP(A26,'TB-Aug21'!A:F,6,0),0) -> 7277144.4 | E26: NCA-Furniture and Equipment | I26: =VLOOKUP(#REF!,#REF!,9,FALSE) -> #REF!
A27: 171221 | B27: Buildings:Asset clearing | C27: =_xlfn.IFNA(VLOOKUP(A27,'TB-Aug 22'!A:F,6,0),0) -> 0 | D27: =_xlfn.IFNA(VLOOKUP(A27,'TB-Aug21'!A:F,6,0),0) -> 0 | E27: NCA-Furniture and Equipment
A28: 171230 | B28: Buildings:CIP cost | C28: =_xlfn.IFNA(VLOOKUP(A28,'TB-Aug 22'!A:F,6,0),0) -> 0 | D28: =_xlfn.IFNA(VLOOKUP(A28,'TB-Aug21'!A:F,6,0),0) -> 0 | E28: NCA-Furniture and Equipment | I28: =VLOOKUP(#REF!,#REF!,9,FALSE) -> #REF!
A29: 171260 | B29: Buildings:Accumulated depreciation/amortization (Provision) | C29: =_xlfn.IFNA(VLOOKUP(A29,'TB-Aug 22'!A:F,6,0),0) -> -2057709 | D29: =_xlfn.IFNA(VLOOKUP(A29,'TB-Aug21'!A:F,6,0),0) -> -1693446.7 | E29: NCA-Furniture and Equipment
A30: 171320 | B30: Plant, machinery & equipment:Asset cost | C30: =_xlfn.IFNA(VLOOKUP(A30,'TB-Aug 22'!A:F,6,0),0) -> 6203419.3 | D30: =_xlfn.IFNA(VLOOKUP(A30,'TB-Aug21'!A:F,6,0),0) -> 6119400.7 | E30: NCA-Furniture and Equipment
A31: 171321 | B31: Plant, machinery & equipment:Asset clearing | C31: =_xlfn.IFNA(VLOOKUP(A31,'TB-Aug 22'!A:F,6,0),0) -> 113350 | D31: =_xlfn.IFNA(VLOOKUP(A31,'TB-Aug21'!A:F,6,0),0) -> 40453.6 | E31: NCA-Furniture and Equipment
A32: 171360 | B32: Plant, machinery & equipment:Accumulated depreciation/amortization (Provision) | C32: =_xlfn.IFNA(VLOOKUP(A32,'TB-Aug 22'!A:F,6,0),0) -> -5903132 | D32: =_xlfn.IFNA(VLOOKUP(A32,'TB-Aug21'!A:F,6,0),0) -> -5445480.6 | E32: NCA-Furniture and Equipment
A33: 172020 | B33: Furniture & fixtures:Asset cost | C33: =_xlfn.IFNA(VLOOKUP(A33,'TB-Aug 22'!A:F,6,0),0) -> 112725 | D33: =_xlfn.IFNA(VLOOKUP(A33,'TB-Aug21'!A:F,6,0),0) -> 112725 | E33: NCA-Furniture and Equipment
A34: 172021 | B34: Furniture & fixtures:Asset clearing | C34: =_xlfn.IFNA(VLOOKUP(A34,'TB-Aug 22'!A:F,6,0),0) -> 0 | D34: =_xlfn.IFNA(VLOOKUP(A34,'TB-Aug21'!A:F,6,0),0) -> 0 | E34: NCA-Furniture and Equipment
A35: 172060 | B35: Furniture & fixtures:Accumulated depreciation/amortization (Provision) | C35: =_xlfn.IFNA(VLOOKUP(A35,'TB-Aug 22'!A:F,6,0),0) -> -112634.6 | D35: =_xlfn.IFNA(VLOOKUP(A35,'TB-Aug21'!A:F,6,0),0) -> -106355.5 | E35: NCA-Furniture and Equipment
A36: 173120 | B36: Intangible Asset: Asset cost | C36: =_xlfn.IFNA(VLOOKUP(A36,'TB-Aug 22'!A:F,6,0),0) -> 436988.01 | D36: =_xlfn.IFNA(VLOOKUP(A36,'TB-Aug21'!A:F,6,0),0) -> 436988.01 | E36: NCA-Furniture and Equipment | I36: =VLOOKUP(#REF!,#REF!,9,FALSE) -> #REF!
A37: 173121 | B37: Intangible Asset: Asset clearing | C37: =_xlfn.IFNA(VLOOKUP(A37,'TB-Aug 22'!A:F,6,0),0) -> 0 | D37: =_xlfn.IFNA(VLOOKUP(A37,'TB-Aug21'!A:F,6,0),0) -> 0 | E37: NCA-Furniture and Equipment
A38: 173160 | B38: Intangible Asset: Accumulated depreciation/amortization (Provision) | C38: =_xlfn.IFNA(VLOOKUP(A38,'TB-Aug 22'!A:F,6,0),0) -> -436988.01 | D38: =_xlfn.IFNA(VLOOKUP(A38,'TB-Aug21'!A:F,6,0),0) -> -425025.77 | E38: NCA-Furniture and Equipment | I38: =VLOOKUP(#REF!,#REF!,9,FALSE) -> #REF!
A39: 200110 | B39: Approved invoices - for payment | C39: =_xlfn.IFNA(VLOOKUP(A39,'TB-Aug 22'!A:F,6,0),0) -> -23276.12 | D39: =_xlfn.IFNA(VLOOKUP(A39,'TB-Aug21'!A:F,6,0),0) -> 0 | E39: CL-Accounts Payable and Accruals | I39: =VLOOKUP(#REF!,#REF!,9,FALSE) -> #REF!
A40: 200130 | B40: Accrued purchases - Invoice received pending approval | C40: =_xlfn.IFNA(VLOOKUP(A40,'TB-Aug 22'!A:F,6,0),0) -> -771221.17 | D40: =_xlfn.IFNA(VLOOKUP(A40,'TB-Aug21'!A:F,6,0),0) -> -683588.08 | E40: CL-Accounts Payable and Accruals | I40: -20000
A41: 202510 | B41: Output VAT payable | C41: =_xlfn.IFNA(VLOOKUP(A41,'TB-Aug 22'!A:F,6,0),0) -> -47619.05 | D41: =_xlfn.IFNA(VLOOKUP(A41,'TB-Aug21'!A:F,6,0),0) -> -95238.1 | E41: CL-Accounts Payable and Accruals
...

Sheet TB-Aug 22
C1: ADERP Trial Balance
C3: Ledger: KUJ - Ledger
C4: Period: 08-2022
C5: Currency: AED
A8: Entity: | B8: 843 Khalifa University
A9: Budget Group:
A11: Account | B11: Description | C11: Beginning Balance | D11: Debits | E11: Credits | F11: Ending Balance
A12: 101101 | B12: Cash holdings with collectors | C12: 0 | D12: 43542 | E12: 43542 | F12: 0
A13: 101400 | B13: Cash holdings - imprest floats for general purpose (replenishable) | C13: 0 | D13: 5000 | E13: 0 | F13: 5000
A14: 101901 | B14: Cash in Transit - AED | C14: 0 | D14: 1076053.2 | E14: 1076053.2 | F14: 0
A15: 102601 | B15: AED Bank Acct No.6 | C15: 1199888.9 | D15: 1422020.7 | E15: 1525172.3 | F15: 1096737.3
A16: 105901 | B16: AED AP Pyt - Clearing Acct | C16: 0 | D16: 494976.16 | E16: 494976.16 | F16: 0
A17: 120123 | B17: Goods and services Tax Receivable | C17: 0 | D17: 47619.05 | E17: 47619.05 | F17: 0
A18: 120140 | B18: Goods and services sales receivable | C18: 0 | D18: 2148029.4 | E18: 2133515.4 | F18: 14514
A19: 120330 | B19: Other advances to vendors | C19: 556958.06 | D19: 0 | E19: 0 | F19: 556958.06
A20: 120985 | B20: Discrepancies resulting from mispostings / fictitious entries | C20: 0 | D20: 8274.74 | E20: 8274.74 | F20: 0
A21: 126510 | B21: Input VAT recoverable | C21: 127749.33 | D21: 18112.93 | E21: 127885.18 | F21: 17977.08
A22: 126550 | B22: R C input VAT recoverable on Services | C22: 21920.52 | D22: 415.11 | E22: 21920.52 | F22: 415.11
A23: 130112 | B23: Material cost:Receipt (pre-inspection) | C23: 0 | D23: 225476.1 | E23: 225476.1 | F23: 0
... A62: 502100 | B62: General Fund (general reserve) | C62: -6018566.8 | D62: 0 | E62: 0 | F62: -6018566.8
B63: Total: | C63: 0 | D63: 11227025 | E63: 11227025 | F63: 0

Sheet TB-Aug21
C1: ADERP Trial Balance
C3: Ledger: KUJ - Ledger
C4: Period: 08-2021
C5: Currency: AED
A8: Entity: | B8: 843 Khalifa University
A9: Budget Group:
A11: Account | B11: Description | C11: Beginning Balance | D11: Debits | E11: Credits | F11: Ending Balance
A12: 101400 | B12: Cash holdings - imprest floats for general purpose (replenishable) | C12: 0 | D12: 5000 | E12: 0 | F12: 5000
A13: 101901 | B13: Cash in Transit - AED | C13: 0 | D13: 1000000 | E13: 1000000 | F13: 0
A14: 102601 | B14: AED Bank Acct No.6 | C14: 2706205.7 | D14: 1000000 | E14: 1486449.8 | F14: 2219755.9
A15: 105901 | B15: AED AP Pyt - Clearing Acct | C15: -5509.5 | D15: 706029.01 | E15: 700519.51 | F15: 0
A16: 120123 | B16: Goods and services Tax Receivable | C16: 0 | D16: 47619.05 | E16: 0 | F16: 47619.05
A17: 120140 | B17: Goods and services sales receivable | C17: 0 | D17: 952380.95 | E17: 1000000 | F17: -47619.05
A18: 120330 | B18: Other advances to vendors | C18: 513398.54 | D18: 0 | E18: 0 | F18: 513398.54
A19: 120985 | B19: Discrepancies resulting from mispostings / fictitious entries | C19: 0 | D19: 96679.23 | E19: 96679.23 | F19: 0
A20: 126510 | B20: Input VAT recoverable | C20: 88030.1 | D20: 15411.73 | E20: 0 | F20: 103441.83
A21: 126550 | B21: R C input VAT recoverable on Services | C21: 14877.11 | D21: 4521.06 | E21: 0 | F21: 19398.17
A22: 130112 | B22: Material cost:Receipt (pre-inspection) | C22: 0 | D22: 211533.37 | E22: 211533.37 | F22: 0
A23: 171050 | B23: Provisional Asset (all categories for setup acct for accrual | C23: 0 | D23: 26499.72 | E23: 26703.6 | F23: -203.88
... A62: 502100 | B62: General Fund (general reserve) | C62: -7200530.3 | D62: 0 | E62: 0 | F62: -7200530.3
B63: Total: | C63: 0 | D63: 8753368.1 | E63: 8753368.1 | F63: 0

Sheet Accrued Insurance
A4: Accrued Insurance
A5: 213600
B6: Emp No | C6: Employee Name | D6: Balance
D10: =SUM(D7:D9) -> 0

Sheet Retention
A5: Retention- Short Term
B6: Particulars | C6: Amount | D6: Dec Transactions | E6: Net | F6: Remarks
C9: =SUM(C7:C8) -> 0 | D9: =SUM(D7:D8) -> 0 | E9: =SUM(E7:E8) -> 0 | I9: =+E9+TB!C47 -> 0

Sheet Payroll Accrual
A5: Payroll Accrual
B6: Emp No | C6: Name | D6: Remarks | E6: Amount
E8: =SUM(E7:E7) -> 0 | H8: =+E8+TB!C45 -> 0

Sheet Related Party
A5: Related Party Payable
A6: Sr | B6: Inv No | C6: Date | D6: Particulars | E6: Amount | F6: Dec Transactions | G6: Amount
A7: 1
A8: =+A7+1 -> 2
A9: =+A8+1 -> 3
A10: =+A9+1 -> 4
E13: =SUM(E7:E12) -> 0 | F13: =SUM(F7:F12) -> 0 | G13: =SUM(G7:G12) -> 0 | J13: =+G13+TB!C51 -> -14514
