Workbook

Sheet 2019 - 2025 PVT Budget Chp-1 
A2: Future-02 | B2: Chapter-01
A4: Row Labels | B4: 2019 Actual | C4: 2020 Actual | D4: 2021 Actual | E4: 2022 Budget | F4: 2022 Estimates Full Year Actual | G4: 2022 - Jun Actual | H4: 2022 PR | I4: 2022 PO | J4: Sum of 2023 Budget | K4: Sum of 2024 Budget | L4: Sum of 2025 Budget
A5: Chapter-01 | B5: 734104574 | C5: 541385100 | D5: 583579295 | E5: 622545692 | F5: 601695721 | G5: 273667080 | H5: 1643996 | I5: 7959693 | J5: 6.9619905e+08 | K5: 714862760 | L5: 779727079
A6: Grand Total | B6: 734104574 | C6: 541385100 | D6: 583579295 | E6: 622545692 | F6: 601695721 | G6: 273667080 | H6: 1643996 | I6: 7959693 | J6: 6.9619905e+08 | K6: 714862760 | L6: 779727079
A12: 2022 - Proposal | F12: 2022 - Revised | K12: 2023 - Proposal
C13: Budget | D13: Count | H13: Budget | I13: Counts | M13: Budget | N13: Count
A14: KU | B14: Current Employees | C14: 519842486 | D14: 776 | F14: Initial Budget | H14: 621695721 | K14: Exisiting Employees (May 2022) | L14: Salaries & Allowances | M14: 4.7495487e+08 | N14: 782
L15: Benefits | M15: 50564576
B16: Total | C16: =C14 -> 519842486 | D16: 776 | F16: Current Existing Costs (May 2022) | H16: =516184646.27-18000000 -> 4.9818465e+08 | I16: 799 | L16: Total | M16: 5.2551945e+08 | N16: 782 | O16: 378 Faculty, 389 Staff, 15 Off-Chart
A18: Expected Hires | B18: Hires 2021 | C18: 38335362 | D18: 68 | F18: New Hires Costs | G18: Hires 2022 | H18: 10917438 | I18: 91 | J18: =I16+I18 -> 890 | K18: Expected Hires | L18: To be Hired in 2022 | M18: 55245963 | N18: 80 | O18: 30 Faculty, 50 Staff
B19: Hires 2022 | C19: 39782098 | D19: 112 | L19: Manpower Plan 2023 | M19: 55306324 | N19: 139 | O19: 65 Faculty, 74 Staff
B20: Total | C20: =C18+C19 -> 78117460 | D20: 180 | E20: =D16+D20 -> 956 | L20: Total | M20: 1.1055229e+08 | N20: 219 | O20: =N16+N20 -> 1001
A21: Outsourced Employees | B21: Current Employees - Ankabut | C21: 22024007 | D21: 43 | F21: Outsourced Employees | H21: 36000000 | I21: IT 43 staff and Other staff | K21: Outsourced Employees | L21: Ankabut Employees | M21: 23136769 | N21: 43 | O21: Total current 43 in KUST + 23 in KUA (Total positions on chart 71)
B22: Hires 2022 - Ankabut | C22: 1112762 | D22: 4 | L22: Other Outsourced | M22: 13105000
B23: Total | C23: 23136769 | D23: 47 | L23: Total | M23: =SUM(M21:M22) -> 36241769 | N23: 43
A25: Central Budget and Other | B25: Total | C25: 2953893 | F25: Central Budget and Other | H25: 56593636 | K25: Central Budget and Other | L25: Total | M25: 23885544
F27: Grand Total | G27: Total | H27: 601695721
A28: Grand Total | B28: Total | C28: 624050608 | K28: Grand Total | L28: Total | M28: =M16+M20+M23+M25 -> 6.9619905e+08
F29: ** surplus budget | H29: =H14-H27 -> 20000000
N32: 45119736
N33: =N32-M21 -> 21982967

Sheet Analysis Opex
C1: Chapter 2 (operating):
C2: Grand Total | D2: =SUM(D4:D92) -> 579850000 | E2: =SUM(E4:E92) -> 2.7320624e+08 | F2: =SUM(F4:F92) -> 8.9798134e+08 | G2: =SUM(G4:G92) -> 3.1813134e+08
A3: Chp | B3: Account Code | C3: Account | D3: 2022 Budget | E3: Jun 2022 (Actula , PR, PO) | F3: 2023 Budget | G3: Sum of Diff | H3: 2023 % Compared to Budget 2022 | I3: 2023 % Budget Difference compared to total difference | J3: Comments
A4: FA179-Opex Expense | B4: 425749 | C4: 425749-Postgraduate Student Salaries | D4: 135037862 | E4: 66630460 | F4: 244626000 | G4: =F4-D4 -> 109588138 | H4: =G4/D4 -> 0.81153638 | I4: =G4/$G$2 -> 0.34447451 | J4: Compared to FY2022 budgeted graduate salary has increased by 81% and new intake students -2022 Fall = 303 -2023 Spring = 152 -2023 Fall = 303 Exiting students as of Jun 2022 = 492 | K4: Compared to year 2021-22 intake increaed in 2022-23 in percentage 76%. 2021-2022 PG students intkae 431, in 2022-23 PG students 758
A5: FA179-Opex Expense | B5: 420811 | C5: 420811-IT Systems & Support expenses-Application/Systems Operation | D5: 12949400 | E5: 276944.2 | F5: 27999051 | G5: =F5-D5 -> 15049651 | H5: =G5/D5 -> 1.162189 | I5: =G5/$G$2 -> 0.047306408 | J5: Opex IT systems & support expense compared to FY2022 increased 116%. Ankbout27M SLA adding 20M SLA support and Research computing AED 5M | K5: UPDATED
A6: FA179-Opex Expense | B6: 420570 | C6: 420570-Academic Collaborative Partnership Services | D6: 26364292 | E6: 64153.81 | F6: 56595297 | G6: =F6-D6 -> 30231005 | H6: =G6/D6 -> 1.1466648 | I6: =G6/$G$2 -> 0.095026805 | J6: Academic Collaborative Partnership Services Opex: it increased by 53% compared to FY2022. • CoM AED 33M SSMC-SEHA agreement AED 33m • The office of EVP: potential affiliation partnership for the graduate school AED 15M • President office 5M, Provost Office 3m | K6: UPDATED
A7: FA179-Opex Expense | B7: 430120 | C7: 430120-Rental - Buildings, other than staff residences | D7: 0 | E7: 0 | F7: 22219870 | G7: =F7-D7 -> 22219870 | H7: 1 | I7: =G7/$G$2 -> 0.069844958 | J7: • MASDER complex 2022 rental AED 4.587M • MASDER complex 2023 rental AED 4.632M • MASDER complex 2023 rental shortage for 275 students - new requirement from student services FY22/23 AED 5M • SAN Student Rental Accommodation four month for total of 700 students FY23 (Sep-23 to Dec-23), per project plan SAN accommodation will hand over for contractor in Sep-23
A8: FA179-Opex Expense | B8: 425741 | C8: 425741-Student stipend | D8: 80501600 | E8: 38326680 | F8: 98652604 | G8: =F8-D8 -> 18151004 | H8: =G8/D8 -> 0.22547383 | I8: =G8/$G$2 -> 0.057055064 | J8: UG stipend budget increased by 18%, Due to 2022 intake increaed by 923 and student moved to higher GPA. FY2023 new intake 650
A9: FA179-Opex Expense | B9: 435508 | C9: 435508-Laboratory - Scientific | D9: 7985186 | E9: 4531173.7 | F9: 33397354 | G9: =F9-D9 -> 25412168 | H9: =G9/D9 -> 3.182414 | I9: =G9/$G$2 -> 0.079879486 | J9: The 435508-Laboratory - Scientific increased 318% compared to FY2022 budget increased, • CoM 644% and AED 14M budgeted • CoAS 82% AED 2M • CoE 24% AED 2M • Research Lab 410% AED 1.3M | K9: UPDATED
A10: FA179-Opex Expense | B10: 435523 | C10: 435523-Scientific | D10: 100917600 | E10: 40551573 | F10: 113648860 | G10: =F10-D10 -> 12731260 | H10: =G10/D10 -> 0.126155 | I10: =G10/$G$2 -> 0.04001888 | J10: Compared FY2022 overall budget increased by 13%, exiting project 81M and new FY2023 projects awards 31M | K10: Intake year - UG and Student 2019-2020 - 798 2020-2021- 1144 2021-2022- 923 2022-2023- 650 Total - 3515
A11: FA179-Opex Expense | B11: 432120 | C11: 432120-Bldg maintenance-Business premises | D11: 22798578 | E11: 21138493 | F11: 34225569 | G11: =F11-D11 -> 11426991 | H11: =G11/D11 -> 0.50121508 | I11: =G11/$G$2 -> 0.035919099 | J11: Opex Building Maintenance overall 50% increase compared to FY2022. • It consist of Hard Service agreement 30M • Property maintaining budget for upgrade, replaced and Refurbishment AED 4M
A12: FA179-Opex Expense | B12: 425100 | C12: 425100-Advertising Services (General) | D12: 6447464 | E12: 4732387.4 | F12: 15916000 | G12: =F12-D12 -> 9468536 | H12: =G12/D12 -> 1.4685675 | I12: =G12/$G$2 -> 0.029762978 | J12: Communication budget has overall increased in FY2023 147%, it more of budget in Advertisement services which increased in compared to FY2022 157%: • General DM campaign, news content preparation, magazine content development,etc, AED 2M • Updating content in the website, creating pages, creating websites and new system AED 1M • Branding for the university rank AED 2.4M • Monthly basis operations which is varies from (TV commercials, radio, Social Media) AED 5.4M
A13: FA179-Opex Expense | B13: 421000 | C13: 421000-Management consultancy | D13: 2525900 | E13: 1542000 | F13: 8290000 | G13: =F13-D13 -> 5764100 | H13: =G13/D13 -> 2.2819985 | I13: =G13/$G$2 -> 0.018118617 | J13: Overall increased 228% compared to FY2022, • FMS consultancy service for Qruin AlAish Masterplan AED5 • PMO FM projects (Open blanket agreement) AED2
A14: FA179-Opex Expense | B14: 426610 | C14: 426610-Computer software licenses-Software License Renewal | D14: 17172519 | E14: 11830690 | F14: 21231889 | G14: =F14-D14 -> 4059370 | H14: =G14/D14 -> 0.23638757 | I14: =G14/$G$2 -> 0.012760044 | J14: Significant increase in the research computer compared FY2022 it increased by AED2.7M budget amount AED5.4m
A15: FA179-Opex Expense | B15: 428640 | C15: 428640-Events - Awards, prizes & gifts | D15: 1588000 | E15: 242575.55 | F15: 4947721 | G15: =F15-D15 -> 3359721 | H15: =G15/D15 -> 2.1156933 | I15: =G15/$G$2 -> 0.010560799 | J15: • Office of the Provost AED 2M • HR AED 1M • Communication AED 998K • Electrical & Computer Engineering AED 302K • Others 13 department budgeted AED 647
A16: FA179-Opex Expense | B16: 425550 | C16: 425550-Conferences, seminars and exhibitions and other events: - Overseas event | D16: 1796957 | E16: 87596.72 | F16: 5035030 | G16: =F16-D16 -> 3238073 | H16: =G16/D16 -> 1.8019758 | I16: =G16/$G$2 -> 0.010178416 | J16: Communication budgeted AED 2.1M and CoM budgeted AED 1.1
A17: FA179-Opex Expense | B17: 428111 | C17: 428111-Electricity consumption charges | D17: 15465717 | E17: 4197494.3 | F17: 18698211 | G17: =F17-D17 -> 3232494 | H17: =G17/D17 -> 0.20901029 | I17: =G17/$G$2 -> 0.010160879 | J17: Due to increased in the rental
A18: FA179-Opex Expense | B18: 429900 | C18: 429900-Other services, not specifically mentioned elsewhere | D18: 99510 | E18: 41250 | F18: 3288000 | G18: =F18-D18 -> 3188490 | H18: =G18/D18 -> 32.041905 | I18: =G18/$G$2 -> 0.010022559 | J18: KUST - Executive Vice President Office budgeted AED 3M for Special Projects (Projects that gets assigned by the chairman and the board) Like Khalifa COVID FACE MASK and Satellites.
A19: FA179-Opex Expense | B19: 421700 | C19: 421700-Standards Certification Services (e.g. ISO) | D19: 2271312 | E19: 368465.86 | F19: 5220000 | G19: =F19-D19 -> 2948688 | H19: =G19/D19 -> 1.2982312 | I19: =G19/$G$2 -> 0.0092687756 | J19: Provost office: 23 x CAA accreditation of programs @ 150K each + 5 x new Programs @ 150K each AED 3.45M
A20: FA179-Opex Expense | B20: 425740 | C20: 425740-Scholarships & other financial aid | D20: 694710 | E20: 0 | F20: 3600012 | G20: =F20-D20 -> 2905302 | H20: =G20/D20 -> 4.1820357 | I20: =G20/$G$2 -> 0.0091323979 | J20: KUST - Office of the Provost AED 3.6M
A21: FA179-Opex Expense | B21: 425510 | C21: 425510-Conferences, seminars and exhibitions and other events: - Local Events | D21: 8184179 | E21: 6097762.2 | F21: 10949900 | G21: =F21-D21 -> 2765721 | H21: =G21/D21 -> 0.33793506 | I21: =G21/$G$2 -> 0.0086936452 | J21: • This includes the major Events hosted such as (Graduation, National Day,KU Century Challenge ) AED 5M • KUST - Dean Of Medicine: Communication Dept. - This includes the major exhibitions participation such as (ADIPEC, IDEX, NAJAH, AD Book Fair) AED 1.12M • KUST - Career Services: Career Fair, Alumni Re-union, etc AED 1M
A22: FA179-Opex Expense | B22: 432209 | C22: 432209-Laboratory equipment | D22: 17441427 | E22: 13569787 | F22: 21267845 | G22: =F22-D22 -> 3826418 | H22: =G22/D22 -> 0.21938675 | I22: =G22/$G$2 -> 0.012027793 | J22: Compared to FY2022 budget in 2023 budget increased 22%; • CoAS:Chemistry 226% AED 980,000 • CoE:Petroleum Engineering 221% AED 979,000 • Research Laboratories 16% AED 17,597,270
... A27: FA179-Opex Expense | B27: 428090 | C27: 428090-Business Travel - Combined expenses | D27: 3458093 | E27: 76231.87 | F27: 5535090 | G27: =F27-D27 -> 2076997 | H27: =G27/D27 -> 0.60061919 | I27: =G27/$G$2 -> 0.0065287406 | J27: KUST - Executive Vice President Office Budgeted AED 1M and KUST - Office of the President AED 1M, remaining all other college budget AED 3M
A28: FA179-Opex Expense | B28: 425770 | C28: 425770-Academic Missions - Combined expenses | D28: 5589749 | E28: 519162.08 | F28: 7561925 | G28: =F28-D28 -> 1972176 | H28: =G28/D28 -> 0.35282014 | I28: =G28/$G$2 -> 0.0061992509
A29: FA179-Opex Expense | B29: 420900 | C29: 420900-Legal services | D29: 3355444 | E29: 2498518.7 | F29: 5298500 | G29: =F29-D29 -> 1943056 | H29: =G29/D29 -> 0.57907568 | I29: =G29/$G$2 -> 0.0061077164
A30: FA179-Opex Expense | B30: 425900 | C30: 425900-Entertainment and hospitality | D30: 1480064 | E30: 125625.32 | F30: 3419632 | G30: =F30-D30 -> 1939568 | H30: =G30/D30 -> 1.3104623 | I30: =G30/$G$2 -> 0.0060967524
A31: FA179-Opex Expense | B31: 425745 | C31: 425745-Student relocation & travel exps | D31: 1995663 | E31: 841645 | F31: 3929115 | G31: =F31-D31 -> 1933452 | H31: =G31/D31 -> 0.9688269 | I31: =G31/$G$2 -> 0.0060775276
A32: FA179-Opex Expense | B32: 425750 | C32: 425750-Skill assessment service | D32: 887069 | E32: 92850.06 | F32: 2704485 | G32: =F32-D32 -> 1817416 | H32: =G32/D32 -> 2.0487876 | I32: =G32/$G$2 -> 0.0057127852
A33: FA179-Opex Expense | B33: 425720 | C33: 425720-Education-Outsourced training service | D33: 2677815 | E33: 1834395.3 | F33: 4400850 | G33: =F33-D33 -> 1723035 | H33: =G33/D33 -> 0.64344811 | I33: =G33/$G$2 -> 0.0054161121
A34: FA179-Opex Expense | B34: 420550 | C34: 420550-Academic Advisory Service | D34: 1917312 | E34: 156883.8 | F34: 3540830 | G34: =F34-D34 -> 1623518 | H34: =G34/D34 -> 0.84676777 | I34: =G34/$G$2 -> 0.0051032947
A35: FA179-Opex Expense | B35: 435350 | C35: 435350-Academic Publications | D35: 2894920 | E35: 575666.04 | F35: 4515000 | G35: =F35-D35 -> 1620080 | H35: =G35/D35 -> 0.55962859 | I35: =G35/$G$2 -> 0.0050924879
A36: FA179-Opex Expense | B36: 427100 | C36: 427100-Public relations | D36: 1157850 | E36: 909458.75 | F36: 2500000 | G36: =F36-D36 -> 1342150 | H36: =G36/D36 -> 1.1591743 | I36: =G36/$G$2 -> 0.004218855
A37: FA179-Opex Expense | B37: 422900 | C37: 422900-Other specialised professional services, not mentioned elsewhere | D37: 416100 | E37: 416100 | F37: 1710000 | G37: =F37-D37 -> 1293900 | H37: =G37/D37 -> 3.109589 | I37: =G37/$G$2 -> 0.0040671881
A38: FA179-Opex Expense | B38: 430330 | C38: 430330-Rental - Motor vehicles | D38: 967680 | E38: 771960 | F38: 1870125 | G38: =F38-D38 -> 902445 | H38: =G38/D38 -> 0.93258619 | I38: =G38/$G$2 -> 0.0028367057
A39: FA179-Opex Expense | B39: 430250 | C39: 430250-Rental - Computer hardware-Rental/Subscription - Computer hardware | D39: 1021317 | E39: 1019273.8 | F39: 1864650 | G39: =F39-D39 -> 843333 | H39: =G39/D39 -> 0.82573089 | I39: =G39/$G$2 -> 0.0026508957
... A62: FA179-Opex Expense | B62: 425763 | C62: 425763-Student Project Expenses | D62: 2802590 | E62: 988267.84 | F62: 2809795 | G62: =F62-D62 -> 7205 | H62: =G62/D62 -> 0.0025708363 | I62: =G62/$G$2 -> 2.2647879e-05
A63: FA179-Opex Expense | B63: 420810 | C63: 420810-IT Systems & Support expenses | D63: 0 | E63: 0 | F63: 0 | G63: =F63-D63 -> 0 | H63: 0 | I63: =G63/$G$2 -> 0
A64: FA179-Opex Expense | B64: 422100 | C64: 422100-Waste management service | D64: 12000 | E64: 0 | F64: 12000 | G64: =F64-D64 -> 0 | H64: =G64/D64 -> 0 | I64: =G64/$G$2 -> 0
A65: FA179-Opex Expense | B65: 422400 | C65: 422400-Medical services | D65: 0 | E65: 0 | F65: 0 | G65: =F65-D65 -> 0 | H65: 0 | I65: =G65/$G$2 -> 0
A66: FA179-Opex Expense | B66: 426210 | C66: 426210-Insurance - Cash and fidelity | D66: 0 | E66: 0 | F66: 0 | G66: =F66-D66 -> 0 | H66: 0 | I66: =G66/$G$2 -> 0
...

Sheet Analysis Capex
C1: Chapter 3 (Capex):
C2: Grand Total | D2: =SUM(D4:D13) -> 110301000 | E2: =SUM(E4:E13) -> 1.0108274e+08 | F2: =SUM(F4:F13) -> 279895425 | G2: =SUM(G4:G13) -> 169594425
A3: Chp | B3: Account Code | C3: Account | D3: 2022 Budget | E3: Jun 2022 (Actula , PR, PO) | F3: 2023 Budget | G3: 2023 and 2022 Difference | H3: 2023 % Compared to Budget 2022 | I3: 2023 Budget Difference compared to total difference in % | J3: Comments
A4: FA180-Capex Expense | B4: 492316 | C4: 492316-Laboratory equipment | D4: 54372197 | E4: 48639176 | F4: 150888360 | G4: =F4-D4 -> 96516163 | H4: =G4/D4 -> 1.7751014 | I4: =G4/$G$2 -> 0.56909986 | J4: Capex 492316-Laboratory equip compared to FY2022 overall increased in percentage 178%. FY2023 Budget compared to FY2022 increased; • Research Lab Cost Center 413% AED 81M • Research Computing 570% AED 22M. • CoE 66% AED 5.5M. • CoAS 89% AED 5M • CoM 35% AED 23M.
A5: FA180-Capex Expense | B5: 492200 | C5: 492200-Capital expense - Buildings | D5: 46279509 | E5: 44899320 | F5: 104517560 | G5: =F5-D5 -> 58238051 | H5: =G5/D5 -> 1.2583982 | I5: =G5/$G$2 -> 0.34339602 | J5: • Capex Building increased compared to FY2022 by 126%, due to multiple building renovation. • Habshan Building Renovation AED 36M. • Technology and Innovation Center Phase-2 AED 11M • Central Gas network for arzanah lab (Phase 2/1) AED 6m and Road connection SAN to Arzanah 5M. Many other sundry renovations adding up to AED 44M
A6: FA180-Capex Expense | B6: 492610 | C6: 492610-Furniture & Fixtures - Offices | D6: 2099461 | E6: 884839 | F6: 6326594 | G6: =F6-D6 -> 4227133 | H6: =G6/D6 -> 2.0134373 | I6: =G6/$G$2 -> 0.024924953 | J6: FMS has significant amount in budget AED 6 M Medical equipment, High Fidelity Simulators, Task Trainers Construction supply and installation of self-contained cold store for 8 bodies (MS) Class room fit out and office, labs
A7: FA180-Capex Expense | B7: 495113 | C7: 495113-Computer software-Application, Platform | D7: 1630974 | E7: 1263794.8 | F7: 5722572 | G7: =F7-D7 -> 4091598 | H7: =G7/D7 -> 2.5086838 | I7: =G7/$G$2 -> 0.024125781 | J7: • Human resource has budget for 4.4M and it increaed by 100%,ERP Solution AED 3M • New implementation of system for Archiving Solution AED 1M
A8: FA180-Capex Expense | B8: 492356 | C8: 492356-Hardware & peripherals-Conferencing & AV | D8: 650000 | E8: 583836 | F8: 4018539 | G8: =F8-D8 -> 3368539 | H8: =G8/D8 -> 5.1823677 | I8: =G8/$G$2 -> 0.019862322 | J8: • Major Classroom Renovations to adopt hybrid learning in classrooms: AED3.3 • AV equipment for Merged Classrooms in SAN Campus and Main Campus - Part 2. AV Equipment AED 702
A9: FA180-Capex Expense | B9: 492354 | C9: 492354-Hardware & peripherals-Peripherals & Infrastructure Components | D9: 321500 | E9: 321320 | F9: 2238800 | G9: =F9-D9 -> 1917300 | H9: =G9/D9 -> 5.9636081 | I9: =G9/$G$2 -> 0.011305207
A10: FA180-Capex Expense | B10: 495110 | C10: 495110-Computer software | D10: 0 | E10: 0 | F10: 1859500 | G10: =F10-D10 -> 1859500 | H10: 1 | I10: =G10/$G$2 -> 0.010964393
A11: FA180-Capex Expense | B11: 492310 | C11: 492310-Hardware & peripherals | D11: 2884648 | E11: 2444879 | F11: 2916500 | G11: =F11-D11 -> 31852 | H11: =G11/D11 -> 0.011041902 | I11: =G11/$G$2 -> 0.00018781278
A12: FA180-Capex Expense | B12: 495140 | C12: 495140-Copyrights, patents and licenses | D12: 46409 | E12: 30302.25 | F12: 18000 | G12: =F12-D12 -> -28409 | H12: =G12/D12 -> -0.6121442 | I12: =G12/$G$2 -> -0.0001675114
A13: FA180-Capex Expense | B13: 492352 | C13: 492352-Hardware & peripherals-Network Devices | D13: 2016302 | E13: 2015272.6 | F13: 1389000 | G13: =F13-D13 -> -627302 | H13: =G13/D13 -> -0.3111151 | I13: =G13/$G$2 -> -0.0036988362
D14: =SUM(D4:D13) -> 110301000 | E14: =SUM(E4:E13) -> 1.0108274e+08 | F14: =SUM(F4:F13) -> 279895425 | G14: =SUM(G4:G13) -> 169594425
E15: 2.7320624e+08
E16: =SUM(E14:E15) -> 3.7428898e+08

Sheet 2019 - 2025 DB Master
A1: Cost Center Code - Group | B1: GL Account Combination | C1: Cost Center Code | D1: Cost Center Description | E1: Account Code | F1: Account Code and Description | G1: Future-01 | H1: Future-01 Description | I1: Future-02 | J1: Future-02 Description | K1: 2019 Actual | L1: 2020 Actual | M1: 2021 Actual | N1: 2022 Budget | O1: 2022 Estimates Full Year Actual | P1: 2022 - Jun Actual | Q1: 2022 PR | R1: 2022 PO | S1: 2023 Budget | T1: 2023 Budget Scenario 90% | U1: 2023 Budget Scenario 80% | V1: 2023 Budget Scenario 70% | W1: 2024 Budget | X1: 2025 Budget | Y1: Diff
A2: Chapter-01 | B2: Chapter-01 | C2: Chapter-01 | D2: Chapter-01 | E2: Chapter-01 | F2: Chapter-01 | G2: Chapter-01 | H2: Chapter-01 | I2: Chapter-01 | J2: Chapter-01 | K2: 734104574 | L2: 541385100 | M2: 583579295 | N2: 622545692 | O2: 601695721 | P2: 273667080 | Q2: 1643996 | R2: 7959693 | S2: 6.9619905e+08 | W2: 714862760 | X2: 779727079 | Y2: 0
A3: Academic and Student Services Office | B3: 847.8470230.1.420550.000000.847001.200179 | C3: 8470230 | D3: KUST - Graduate Studies | E3: 420550 | F3: 420550-Academic Advisory Service | G3: 847001 | H3: KUST - General | I3: 200179 | J3: FA179-Opex Expense | K3: 346386 | L3: 79120 | M3: 56949 | N3: 1020620 | O3: 1020620 | P3: 0 | Q3: 0 | R3: 0 | S3: 2009826 | T3: 1808843 | U3: 1607861 | V3: 1406878 | W3: 2764960 | X3: 5655600 | Y3: =S3-N3 -> 989206
A4: Academic and Student Services Office | B4: 847.8470230.1.425100.000000.847001.200179 | C4: 8470230 | D4: KUST - Graduate Studies | E4: 425100 | F4: 425100-Advertising Services (General) | G4: 847001 | H4: KUST - General | I4: 200179 | J4: FA179-Opex Expense | K4: 251555 | L4: 0 | M4: 0 | N4: 300000 | O4: 300000 | P4: 0 | Q4: 0 | R4: 0 | S4: 300000 | T4: 270000 | U4: 240000 | V4: 210000 | W4: 300000 | X4: 300000 | Y4: =S4-N4 -> 0
A5: Academic and Student Services Office | B5: 847.8470230.1.425510.000000.847001.200179 | C5: 8470230 | D5: KUST - Graduate Studies | E5: 425510 | F5: 425510-Conferences, seminars and exhibitions and other events: - Local Events | G5: 847001 | H5: KUST - General | I5: 200179 | J5: FA179-Opex Expense | K5: 46161 | L5: 17919 | M5: 3706 | N5: 34000 | O5: 34000 | P5: 0 | Q5: 0 | R5: 0 | S5: 38400 | T5: 34560 | U5: 30720 | V5: 26880 | W5: 48000 | X5: 64000 | Y5: =S5-N5 -> 4400
A6: Academic and Student Services Office | B6: 847.8470230.1.425550.000000.847001.200179 | C6: 8470230 | D6: KUST - Graduate Studies | E6: 425550 | F6: 425550-Conferences, seminars and exhibitions and other events: - Overseas event | G6: 847001 | H6: KUST - General | I6: 200179 | J6: FA179-Opex Expense | K6: 347020 | L6: 25200 | M6: 3326 | N6: 222000 | O6: 222000 | P6: 22420.5 | Q6: 0 | R6: 0 | S6: 355200 | T6: 319680 | U6: 284160 | V6: 248640 | W6: 444000 | X6: 592000 | Y6: =S6-N6 -> 133200
A7: Academic and Student Services Office | B7: 847.8470230.1.425743.000000.847001.200179 | C7: 8470230 | D7: KUST - Graduate Studies | E7: 425743 | F7: 425743-Graduation rewards | G7: 847001 | H7: KUST - General | I7: 200179 | J7: FA179-Opex Expense | K7: 7340000 | L7: 2010000 | M7: 960000 | N7: 240000 | O7: 240000 | P7: 240000 | Q7: 0 | R7: 0 | S7: 0 | T7: 0 | U7: 0 | V7: 0 | W7: 0 | X7: 0 | Y7: =S7-N7 -> -240000
A8: Academic and Student Services Office | B8: 847.8470230.1.425744.000000.847001.200179 | C8: 8470230 | D8: KUST - Graduate Studies | E8: 425744 | F8: 425744-Student medical insurance | G8: 847001 | H8: KUST - General | I8: 200179 | J8: FA179-Opex Expense | K8: 0 | L8: 0 | M8: 0 | N8: 4816800 | O8: 4816800 | P8: 588624.57 | Q8: 0 | R8: 0 | S8: 3700000 | T8: 3330000 | U8: 2960000 | V8: 2590000 | W8: 4380000 | X8: 4824000 | Y8: =S8-N8 -> -1116800
A9: Academic and Student Services Office | B9: 847.8470230.1.425745.000000.847001.200179 | C9: 8470230 | D9: KUST - Graduate Studies | E9: 425745 | F9: 425745-Student relocation & travel exps | G9: 847001 | H9: KUST - General | I9: 200179 | J9: FA179-Opex Expense | K9: 2585909 | L9: 1706509 | M9: 1286175 | N9: 1971263 | O9: 1971263 | P9: 817645 | Q9: 0 | R9: 0 | S9: 3104115 | T9: 2793704 | U9: 2483292 | V9: 2172881 | W9: 3663925 | X9: 3931250 | Y9: =S9-N9 -> 1132852
A10: Academic and Student Services Office | B10: 847.8470230.1.425749.000000.847001.200179 | C10: 8470230 | D10: KUST - Graduate Studies | E10: 425749 | F10: 425749-Postgraduate Student Salaries | G10: 847001 | H10: KUST - General | I10: 200179 | J10: FA179-Opex Expense | K10: 0 | L10: 22420057 | M10: 84701166 | N10: 110824684 | O10: 110824684 | P10: 55768460 | Q10: 0 | R10: 0 | S10: 203750000 | T10: 183375000 | U10: 163000000 | V10: 142625000 | W10: 249200000 | X10: 274120000 | Y10: =S10-N10 -> 92925316
A11: Academic and Student Services Office | B11: 847.8470230.1.425761.000000.847001.200179 | C11: 8470230 | D11: KUST - Graduate Studies | E11: 425761 | F11: 425761-Student Field trips | G11: 847001 | H11: KUST - General | I11: 200179 | J11: FA179-Opex Expense | K11: 0 | L11: 0 | M11: 0 | N11: 150000 | O11: 150000 | P11: 0 | Q11: 0 | R11: 0 | S11: 180000 | T11: 162000 | U11: 144000 | V11: 126000 | W11: 225000 | X11: 300000 | Y11: =S11-N11 -> 30000
A12: Academic and Student Services Office | B12: 847.8470230.1.425762.000000.847001.200179 | C12: 8470230 | D12: KUST - Graduate Studies | E12: 425762 | F12: 425762-Student Internship | G12: 847001 | H12: KUST - General | I12: 200179 | J12: FA179-Opex Expense | K12: 0 | L12: 0 | M12: 0 | N12: 150000 | O12: 150000 | P12: 0 | Q12: 0 | R12: 0 | S12: 180000 | T12: 162000 | U12: 144000 | V12: 126000 | W12: 225000 | X12: 300000 | Y12: =S12-N12 -> 30000
A13: Academic and Student Services Office | B13: 847.8470230.1.425900.000000.847001.200179 | C13: 8470230 | D13: KUST - Graduate Studies | E13: 425900 | F13: 425900-Entertainment and hospitality | G13: 847001 | H13: KUST - General | I13: 200179 | J13: FA179-Opex Expense | K13: 16320 | L13: 6993 | M13: 0 | N13: 45648 | O13: 45648 | P13: 0 | Q13: 0 | R13: 0 | S13: 60078 | T13: 54070 | U13: 48062 | V13: 42055 | W13: 64320 | X13: 77720 | Y13: =S13-N13 -> 14430
A14: Academic and Student Services Office | B14: 847.8470230.1.426610.000000.847001.200179 | C14: 8470230 | D14: KUST - Graduate Studies | E14: 426610 | F14: 426610-Computer software licenses-Software License Renewal | G14: 847001 | H14: KUST - General | I14: 200179 | J14: FA179-Opex Expense | K14: 0 | L14: 0 | M14: 0 | N14: 10000 | O14: 10000 | P14: 0 | Q14: 0 | R14: 0 | S14: 10000 | T14: 9000 | U14: 8000 | V14: 7000 | W14: 10000 | X14: 10000 | Y14: =S14-N14 -> 0
... A108: College of Arts & Science | B108: 847.8470415.1.428640.000000.847001.200179 | C108: 8470415 | D108: KUST - Chemistry | E108: 428640 | F108: 428640-Events - Awards, prizes & gifts | G108: 847001 | H108: KUST - General | I108: 200179 | J108: FA179-Opex Expense | K108: 426 | L108: 0 | M108: 0 | N108: 15000 | O108: 15000 | P108: 0 | Q108: 0 | R108: 0 | S108: 20000 | T108: 18000 | U108: 16000 | V108: 14000 | W108: 20000 | X108: 25000 | Y108: =S108-N108 -> 5000
A109: College of Arts & Science | B109: 847.8470415.1.432209.000000.847001.200179 | C109: 8470415 | D109: KUST - Chemistry | E109: 432209 | F109: 432209-Laboratory equipment | G109: 847001 | H109: KUST - General | I109: 200179 | J109: FA179-Opex Expense | K109: 130434 | L109: 71550 | M109: 85887 | N109: 301000 | O109: 301000 | P109: 39104 | Q109: 82964.1 | R109: 82628.61 | S109: 980000 | T109: 391500 | U109: 348000 | V109: 304500 | W109: 478500 | X109: 526000 | Y109: =S109-N109 -> 679000 | Z109: =Y109/N109 -> 2.255814
A110: College of Arts & Science | B110: 847.8470415.1.435350.000000.847001.200179 | C110: 8470415 | D110: KUST - Chemistry | E110: 435350 | F110: 435350-Academic Publications | G110: 847001 | H110: KUST - General | I110: 200179 | J110: FA179-Opex Expense | K110: 0 | L110: 18074 | M110: 15798 | N110: 70000 | O110: 70000 | P110: 5138 | Q110: 0 | R110: 0 | S110: 180000 | T110: 162000 | U110: 144000 | V110: 126000 | W110: 240000 | X110: 300000 | Y110: =S110-N110 -> 110000
A111: College of Arts & Science | B111: 847.8470415.1.435508.000000.847001.200179 | C111: 8470415 | D111: KUST - Chemistry | E111: 435508 | F111: 435508-Laboratory - Scientific | G111: 847001 | H111: KUST - General | I111: 200179 | J111: FA179-Opex Expense | K111: 374661 | L111: 267320 | M111: 146217 | N111: 525000 | O111: 525000 | P111: 89206.58 | Q111: 36675 | R111: 76210 | S111: 1200000 | T111: 675000 | U111: 600000 | V111: 525000 | W111: 925000 | X111: 900000 | Y111: =S111-N111 -> 675000
A112: College of Arts & Science | B112: 847.8470415.1.492316.000000.847001.300180 | C112: 8470415 | D112: KUST - Chemistry | E112: 492316 | F112: 492316-Laboratory equipment | G112: 847001 | H112: KUST - General | I112: 300180 | J112: FA180-Capex Expense | K112: 129251 | L112: 0 | M112: 751050 | N112: 1891417 | O112: 1891417 | P112: 0 | Q112: 1774402 | R112: 102313 | S112: 3386780 | T112: 103856 | U112: 92316 | V112: 80777 | W112: 4494200 | X112: 346260 | Y112: =S112-N112 -> 1495363
A113: College of Arts & Science | B113: 847.8470425.1.425510.000000.847001.200179 | C113: 8470425 | D113: KUST - Physics | E113: 425510 | F113: 425510-Conferences, seminars and exhibitions and other events: - Local Events | G113: 847001 | H113: KUST - General | I113: 200179 | J113: FA179-Opex Expense | K113: 0 | L113: 0 | M113: 0 | N113: 45000 | O113: 45000 | P113: 0 | Q113: 0 | R113: 0 | S113: 290000 | T113: 40500 | U113: 36000 | V113: 31500 | W113: 275000 | X113: 295000 | Y113: =S113-N113 -> 245000
A114: College of Arts & Science | B114: 847.8470425.1.425550.000000.847001.200179 | C114: 8470425 | D114: KUST - Physics | E114: 425550 | F114: 425550-Conferences, seminars and exhibitions and other events: - Overseas event | G114: 847001 | H114: KUST - General | I114: 200179 | J114: FA179-Opex Expense | K114: 0 | L114: 0 | M114: 0 | N114: 225000 | O114: 225000 | P114: 0 | Q114: 0 | R114: 0 | S114: 247500 | T114: 222750 | U114: 198000 | V114: 173250 | W114: 270000 | X114: 337500 | Y114: =S114-N114 -> 22500
A115: College of Arts & Science | B115: 847.8470425.1.425770.000000.847001.200179 | C115: 8470425 | D115: KUST - Physics | E115: 425770 | F115: 425770-Academic Missions - Combined expenses | G115: 847001 | H115: KUST - General | I115: 200179 | J115: FA179-Opex Expense | K115: 126527 | L115: 66413 | M115: 717 | N115: 60000 | O115: 60000 | P115: 11830 | Q115: 0 | R115: 0 | S115: 67500 | T115: 60750 | U115: 54000 | V115: 47250 | W115: 90000 | X115: 112500 | Y115: =S115-N115 -> 7500
A116: College of Arts & Science | B116: 847.8470425.1.425900.000000.847001.200179 | C116: 8470425 | D116: KUST - Physics | E116: 425900 | F116: 425900-Entertainment and hospitality | G116: 847001 | H116: KUST - General | I116: 200179 | J116: FA179-Opex Expense | K116: 5798 | L116: 5058 | M116: 0 | N116: 10116 | O116: 10116 | P116: 0 | Q116: 0 | R116: 0 | S116: 145000 | T116: 112500 | U116: 100000 | V116: 87500 | W116: 120000 | X116: 120000 | Y116: =S116-N116 -> 134884
A117: College of Arts & Science | B117: 847.8470425.1.426610.000000.847001.200179 | C117: 8470425 | D117: KUST - Physics | E117: 426610 | F117: 426610-Computer software licenses-Software License Renewal | G117: 847001 | H117: KUST - General | I117: 200179 | J117: FA179-Opex Expense | K117: 0 | L117: 0 | M117: 0 | N117: 212000 | O117: 212000 | P117: 0 | Q117: 0 | R117: 22497.13 | S117: 200000 | T117: 180000 | U117: 160000 | V117: 140000 | W117: 450000 | X117: 400000 | Y117: =S117-N117 -> -12000
A118: College of Arts & Science | B118: 847.8470425.1.428090.000000.847001.200179 | C118: 8470425 | D118: KUST - Physics | E118: 428090 | F118: 428090-Business Travel - Combined expenses | G118: 847001 | H118: KUST - General | I118: 200179 | J118: FA179-Opex Expense | K118: 0 | L118: 0 | M118: 0 | N118: 128000 | O118: 128000 | P118: 0 | Q118: 0 | R118: 0 | S118: 128000 | T118: 115200 | U118: 102400 | V118: 89600 | W118: 192000 | X118: 112500 | Y118: =S118-N118 -> 0
A119: College of Arts & Science | B119: 847.8470425.1.435350.000000.847001.200179 | C119: 8470425 | D119: KUST - Physics | E119: 435350 | F119: 435350-Academic Publications | G119: 847001 | H119: KUST - General | I119: 200179 | J119: FA179-Opex Expense | K119: 14753 | L119: 39563 | M119: 31871 | N119: 120000 | O119: 120000 | P119: 21287.77 | Q119: 0 | R119: 0 | S119: 150000 | T119: 135000 | U119: 120000 | V119: 105000 | W119: 150000 | X119: 250000 | Y119: =S119-N119 -> 30000
A120: College of Arts & Science | B120: 847.8470425.1.435508.000000.847001.200179 | C120: 8470425 | D120: KUST - Physics | E120: 435508 | F120: 435508-Laboratory - Scientific | G120: 847001 | H120: KUST - General | I120: 200179 | J120: FA179-Opex Expense | K120: 4600 | L120: 42606 | M120: 227 | N120: 551566 | O120: 551566 | P120: 0 | Q120: 0 | R120: 152675 | S120: 854700 | T120: 35100 | U120: 31200 | V120: 27300 | W120: 840000 | X120: 1000000 | Y120: =S120-N120 -> 303134
A121: College of Arts & Science | B121: 847.8470425.1.492310.000000.847001.300180 | C121: 8470425 | D121: KUST - Physics | E121: 492310 | F121: 492310-Hardware & peripherals | G121: 847001 | H121: KUST - General | I121: 300180 | J121: FA180-Capex Expense | K121: 0 | L121: 0 | M121: 0 | N121: 151348 | O121: 151348 | P121: 35280 | Q121: 0 | R121: 0 | S121: 800000 | T121: 720000 | U121: 640000 | V121: 560000 | W121: 750000 | X121: 750000 | Y121: =S121-N121 -> 648652
... A177: College of Arts & Science | B177: 847.8470455.1.435350.000000.847001.200179 | C177: 8470455 | D177: KUST – Biology | E177: 435350 | F177: 435350-Academic Publications | G177: 847001 | H177: KUST - General | I177: 200179 | J177: FA179-Opex Expense | K177: 0 | L177: 0 | M177: 0 | N177: 80000 | O177: 80000 | P177: 25142.2 | Q177: 0 | R177: 0 | S177: 140000 | T177: 126000 | U177: 112000 | V177: 98000 | W177: 170000 | X177: 200000 | Y177: =S177-N177 -> 60000
A178: College of Arts & Science | B178: 847.8470455.1.435508.000000.847001.200179 | C178: 8470455 | D178: KUST – Biology | E178: 435508 | F178: 435508-Laboratory - Scientific | G178: 847001 | H178: KUST - General | I178: 200179 | J178: FA179-Opex Expense | K178: 0 | L178: 0 | M178: 0 | N178: 675000 | O178: 675000 | P178: 9208.45 | Q178: 432250 | R178: 0 | S178: 781000 | T178: 702900 | U178: 624800 | V178: 546700 | W178: 275000 | X178: 1122000 | Y178: =S178-N178 -> 106000 | Z178: =Y92+Y111+Y120+Y128+Y131+Y167+Y178 -> 1517634 | AA178: =N92+N111+N120+N128+N131+N167+N178 -> 1852666 | AB178: `
A179: College of Arts & Science | B179: 847.8470455.1.436110.000000.847001.200179 | C179: 8470455 | D179: KUST – Biology | E179: 436110 | F179: 436110-Printing supplies | G179: 847001 | H179: KUST - General | I179: 200179 | J179: FA179-Opex Expense | K179: 0 | L179: 0 | M179: 0 | N179: 5000 | O179: 5000 | P179: 0 | Q179: 0 | R179: 0 | S179: 7000 | T179: 6300 | U179: 5600 | V179: 4900 | W179: 9000 | X179: 10000 | Y179: =S179-N179 -> 2000
A180: College of Arts & Science | B180: 847.8470455.1.492316.000000.847001.300180 | C180: 8470455 | D180: KUST – Biology | E180: 492316 | F180: 492316-Laboratory equipment | G180: 847001 | H180: KUST - General | I180: 300180 | J180: FA180-Capex Expense | K180: 0 | L180: 0 | M180: 0 | N180: 1754263 | O180: 1754263 | P180: 0 | Q180: 1603654 | R180: 106062.5 | S180: 2014622 | T180: 1813160 | U180: 1611698 | V180: 1410235 | W180: 2700000 | X180: 3000000 | Y180: =S180-N180 -> 260359 | Z180: =Y82+Y112+Y122+Y169+Y180 -> 4763255 | AA180: =N82+N112+N122+N169+N180 -> 5350397 | AB180: =Z180/AA180 -> 0.89026197
A181: College of Engineering | B181: 847.8470305.1.420550.000000.847001.200179 | C181: 8470305 | D181: KUST - Dean Of Engineering | E181: 420550 | F181: 420550-Academic Advisory Service | G181: 847001 | H181: KUST - General | I181: 200179 | J181: FA179-Opex Expense | K181: 0 | L181: 0 | M181: 0 | N181: 100000 | O181: 100000 | P181: 92165.34 | Q181: 0 | R181: 0 | S181: 100000 | T181: 90000 | U181: 0 | V181: 70000 | W181: 100000 | X181: 100000 | Y181: =S181-N181 -> 0
A182: College of Engineering | B182: 847.8470305.1.420570.000000.847001.200179 | C182: 8470305 | D182: KUST - Dean Of Engineering | E182: 420570 | F182: 420570-Academic Collaborative Partnership Services | G182: 847001 | H182: KUST - General | I182: 200179 | J182: FA179-Opex Expense | K182: 4591 | L182: 4591 | M182: 4591 | N182: 10000 | O182: 10000 | P182: 0 | Q182: 0 | R182: 0 | S182: 10000 | T182: 9000 | U182: 0 | V182: 7000 | W182: 10000 | X182: 15000 | Y182: =S182-N182 -> 0
A183: College of Engineering | B183: 847.8470305.1.421700.000000.847001.200179 | C183: 8470305 | D183: KUST - Dean Of Engineering | E183: 421700 | F183: 421700-Standards Certification Services (e.g. ISO) | G183: 847001 | H183: KUST - General | I183: 200179 | J183: FA179-Opex Expense | K183: 391361 | L183: 597851 | M183: 123489 | N183: 506004 | O183: 506004 | P183: 32000 | Q183: 0 | R183: 0 | S183: 300000 | T183: 270000 | U183: 0 | V183: 210000 | W183: 90000 | X183: 150000 | Y183: =S183-N183 -> -206004
A184: College of Engineering | B184: 847.8470305.1.425510.000000.847001.200179 | C184: 8470305 | D184: KUST - Dean Of Engineering | E184: 425510 | F184: 425510-Conferences, seminars and exhibitions and other events: - Local Events | G184: 847001 | H184: KUST - General | I184: 200179 | J184: FA179-Opex Expense | K184: 38554 | L184: 10444 | M184: -252 | N184: 20000 | O184: 20000 | P184: 5286 | Q184: 0 | R184: 0 | S184: 20000 | T184: 18000 | U184: 0 | V184: 14000 | W184: 30000 | X184: 60000 | Y184: =S184-N184 -> 0
A185: College of Engineering | B185: 847.8470305.1.425720.000000.847001.200179 | C185: 8470305 | D185: KUST - Dean Of Engineering | E185: 425720 | F185: 425720-Education-Outsourced training service | G185: 847001 | H185: KUST - General | I185: 200179 | J185: FA179-Opex Expense | K185: 29384 | L185: 0 | M185: -3416 | N185: 0 | O185: 0 | P185: 0 | Q185: 0 | R185: 0 | S185: 40000 | T185: 36000 | U185: 0 | V185: 28000 | W185: 80000 | X185: 40000 | Y185: =S185-N185 -> 40000
A186: College of Engineering | B186: 847.8470305.1.425763.000000.847001.200179 | C186: 8470305 | D186: KUST - Dean Of Engineering | E186: 425763 | F186: 425763-Student Project Expenses | G186: 847001 | H186: KUST - General | I186: 200179 | J186: FA179-Opex Expense | K186: 19184 | L186: 617638 | M186: 55390 | N186: 170000 | O186: 170000 | P186: 20000 | Q186: 112260.3 | R186: 0 | S186: 120000 | T186: 108000 | U186: 0 | V186: 84000 | W186: 120000 | X186: 120000 | Y186: =S186-N186 -> -50000
A187: College of Engineering | B187: 847.8470305.1.425770.000000.847001.200179 | C187: 8470305 | D187: KUST - Dean Of Engineering | E187: 425770 | F187: 425770-Academic Missions - Combined expenses | G187: 847001 | H187: KUST - General | I187: 200179 | J187: FA179-Opex Expense | K187: 96239 | L187: 7219 | M187: 22015 | N187: 579499 | O187: 579499 | P187: 51565 | Q187: 0 | R187: 0 | S187: 1000000 | T187: 900000 | U187: 0 | V187: 700000 | W187: 1160000 | X187: 1100000 | Y187: =S187-N187 -> 420501
A188: College of Engineering | B188: 847.8470305.1.425900.000000.847001.200179 | C188: 8470305 | D188: KUST - Dean Of Engineering | E188: 425900 | F188: 425900-Entertainment and hospitality | G188: 847001 | H188: KUST - General | I188: 200179 | J188: FA179-Opex Expense | K188: 19369 | L188: -10521 | M188: -131 | N188: 18000 | O188: 18000 | P188: 2625 | Q188: 0 | R188: 0 | S188: 30000 | T188: 27000 | U188: 0 | V188: 21000 | W188: 40000 | X188: 30000 | Y188: =S188-N188 -> 12000
...

Sheet XXPVT 2023
A1: Future-02 | B1: (All)
A3: Future-02 Description | B3: Account Code and Description | C3: Account Code | D3: Sum of 2023 Budget
A4: Chapter-01 | B4: Chapter-01 | C4: Chapter-01 | D4: 6.9619905e+08
A5: FA179-Opex Expense | B5: 420120-Internal Audit service | C5: 420120 | D5: 520000
A6: FA179-Opex Expense | B6: 420130-External Audit service | C6: 420130 | D6: 236850
A7: FA179-Opex Expense | B7: 420310-Cleaning Services: Business premises | C7: 420310 | D7: 8921788
A8: FA179-Opex Expense | B8: 420550-Academic Advisory Service | C8: 420550 | D8: 3540830
A9: FA179-Opex Expense | B9: 420570-Academic Collaborative Partnership Services | C9: 420570 | D9: 56595297
A10: FA179-Opex Expense | B10: 420810-IT Systems & Support expenses | C10: 420810 | D10: 0
A11: FA179-Opex Expense | B11: 420811-IT Systems & Support expenses-Application/Systems Operation | C11: 420811 | D11: 27999051
A12: FA179-Opex Expense | B12: 420900-Legal services | C12: 420900 | D12: 5298500
A13: FA179-Opex Expense | B13: 421000-Management consultancy | C13: 421000 | D13: 8290000
A14: FA179-Opex Expense | B14: 421100-Manpower supply "Other Than IT Related" | C14: 421100 | D14: 0
A15: FA179-Opex Expense | B15: 421600-Security service | C15: 421600 | D15: 8915130
A16: FA179-Opex Expense | B16: 421700-Standards Certification Services (e.g. ISO) | C16: 421700 | D16: 5220000
... A103: FA180-Capex Expense | B103: 495140-Copyrights, patents and licenses | C103: 495140 | D103: 18000
A104: Grand Total | D104: 1874075813

Sheet 2019 - 2025 PVT Budget Summary
A4: Row Labels | B4: 2019 Actual | C4: 2020 Actual | D4: 2021 Actual | E4: 2022 Budget | F4: 2022 Estimates Full Year Actual | G4: 2022 - Jun Actual | H4: 2022 PR | I4: 2022 PO | J4: 2023 Budget | K4: 2023 budget % | L4: Sum of 2023 Budget Scenario 90% | M4: Sum of 2023 Budget Scenario 80% | N4: Sum of 2023 Budget Scenario 70% | O4: 2024 Budget | P4: 2025 Budget
A5: Chapter-01 | B5: 734104574 | C5: 541385100 | D5: 583579295 | E5: 622545692 | F5: 601695721 | G5: 273667080 | H5: 1643996 | I5: 7959693 | J5: 6.9619905e+08 | K5: 0.11830996 | O5: 714862760 | P5: 779727079
A6: FA179-Opex Expense | B6: 453454660 | C6: 436208140 | D6: 441110791 | E6: 579850000 | F6: 579850000 | G6: 1.8911659e+08 | H6: 33388070 | I6: 50701580 | J6: 8.9798134e+08 | K6: 0.5486442 | L6: 7.2668401e+08 | M6: 4.4706592e+08 | N6: 5.6583185e+08 | O6: 1016511648 | P6: 1116963424
A7: FA180-Capex Expense | B7: 156951792 | C7: 84546442 | D7: 82262231 | E7: 110301000 | F7: 110301000 | G7: 22847250 | H7: 40206186 | I7: 38029304 | J7: 279895425 | K7: 1.5375602 | L7: 1.5353053e+08 | M7: 1.0605958e+08 | N7: 1.2106332e+08 | O7: 133843452 | P7: 85950261
A8: Grand Total | B8: 1344511026 | C8: 1062139682 | D8: 1106952317 | E8: 1312696692 | F8: 1291846721 | G8: 4.8563092e+08 | H8: 75238252 | I8: 96690577 | J8: 1874075813 | K8: 0.42765334 | L8: 8.8021453e+08 | M8: 5.5312551e+08 | N8: 6.8689517e+08 | O8: 1865217860 | P8: 1982640764

Sheet 2019 - 2025 PVT Budget Master
A2: Future-02 Description | B2: FA179-Opex Expense
A3: Grand Total | B3: 453454660 | C3: 436208140 | D3: 441110791 | E3: 579850000 | F3: 579850000 | G3: 187138724 | H3: 32891483 | I3: 50586956 | J3: 9.1060796e+08 | K3: 7.2995401e+08 | L3: 4.138768e+08 | M3: 5.6774201e+08 | N3: 981703638 | O3: 1078691613
A4: Row Labels | B4: 2019 Actual | C4: 2020 Actual | D4: 2021 Actual | E4: 2022 Budget | F4: 2022 Estimates Full Year Actual | G4: 2022 - Jun Actual | H4: 2022 PR | I4: 2022 PO | J4: 2023 Budget | K4: 2023 Budget Scenario 90% | L4: Sum of 2023 Budget Scenario 80% | M4: Sum of 2023 Budget Scenario 70% | N4: 2024 Budget | O4: 2025 Budget
A5: Academic and Student Services Office | B5: 172187679 | C5: 146304242 | D5: 163185443 | E5: 243450134 | F5: 243450134 | G5: 1.0819914e+08 | H5: 2840501.8 | I5: 6961704.4 | J5: 364075874 | K5: 3.260365e+08 | L5: 2.8981022e+08 | M5: 2.5358394e+08 | N5: 438825848 | O5: 497434881
A6: Senior Vice President, Research Office | B6: 86138315 | C6: 113736508 | D6: 113399833 | E6: 129843909 | F6: 129843909 | G6: 39615564 | H6: 8839209.5 | I6: 10502599 | J6: 163100430 | K6: 1.1777973e+08 | L6: 25327181 | M6: 92239635 | N6: 185279342 | O6: 207394237
A7: SVP/ Support Services Office | B7: 135037634 | C7: 127285760 | D7: 115378848 | E7: 95346032 | F7: 95346032 | G7: 21689077 | H7: 11781162 | I7: 27404447 | J7: 1.5346846e+08 | K7: 1.1220246e+08 | L7: 92977350 | M7: 87268580 | N7: 172307627 | O7: 172132859
A8: College of Medicine & Health Sciences | B8: 6964244 | C8: 13219211 | D8: 35241461 | E8: 61076587 | F8: 61076587 | G8: 13193664 | H8: 1126199.7 | I8: 2982880.2 | J8: 111377365 | K8: 100239631 | L8: 0 | M8: 77964157 | N8: 117633995 | O8: 123318820
A9: Executive Vice President Office | B9: 18081624 | C9: 5434003 | D9: 6636134 | E9: 15481527 | F9: 15481527 | G9: 3186778.2 | H9: 7012626.8 | I9: 862624 | J9: 48832983 | K9: 23005420 | L9: 20449262 | M9: 17893105 | N9: 50144220 | O9: 53053060
A10: College of Engineering | B10: 7538448 | C10: 5920794 | D10: 6067820 | E10: 13353579 | F10: 13353579 | G10: 2240265.3 | H10: 658897.37 | I10: 1524753.9 | J10: 17321285 | K10: 14699057 | L10: 0 | M10: 11432600 | N10: 17570423 | O10: 17626371
A11: College of Arts & Science | B11: 3165325 | C11: 1656687 | D11: 803563 | E11: 12241156 | F11: 12241156 | G11: 825355.75 | H11: 629472.87 | I11: 462571.83 | J11: 16260022 | K11: 11980780 | L11: 10649582 | M11: 9318385 | N11: 12760754 | O11: 21945034
A12: Provost | B12: 0 | C12: 0 | D12: 0 | E12: 1814597 | F12: 1814597 | G12: 45405 | H12: 0 | I12: 0 | J12: 13229516 | K12: 11906565 | L12: 0 | M12: 9260661 | N12: 10957230 | O12: 11736443
A13: President's Office | B13: 24341391 | C13: 22650935 | D13: 260675 | E13: 6740109 | F13: 6740109 | G13: 100575.82 | H13: 500000 | I13: 0 | J13: 9904889 | K13: 8464400 | L13: 7523911 | M13: 6583422 | N13: 10521389 | O13: 11772639
A14: Continuing Education | B14: 0 | C14: 0 | D14: 137014 | E14: 502370 | F14: 502370 | G14: 20760 | H14: 0 | I14: 0 | J14: 410520 | K14: 369468 | L14: 328416 | M14: 287364 | N14: 510820 | O14: 549080
A15: Grand Total | B15: 453454660 | C15: 436208140 | D15: 441110791 | E15: 579850000 | F15: 579850000 | G15: 1.8911659e+08 | H15: 33388070 | I15: 50701580 | J15: 8.9798134e+08 | K15: 7.2668401e+08 | L15: 4.4706592e+08 | M15: 5.6583185e+08 | N15: 1016511648 | O15: 1116963424

Sheet UG & PG Summary Table
B2: 2021-2022 | C2: 2022-2023 | D2: 2023-2024 | E2: 2024-2025 | F2: 2025-2026 | G2: 2026-2027 | H2: 2027-2028
A3: Continuing Students - UG | B3: 2381 | C3: 2957.22 | D3: =D7-D5 -> 3257 | E3: =E7-E5 -> 3444 | F3: =F7-F5 -> 3619 | G3: =G7-G5 -> 3793 | H3: =H7-H5 -> 3976
A4: Continuing Students - PG | B4: 560 | C4: =SUM([2]UGProjections!J31,[2]UGProjections!J40)-C6 -> 819.53 | D4: =SUM([2]UGProjections!L31,[2]UGProjections!L40)-D6 -> 1042.5293 | E4: =SUM([2]UGProjections!N31,[2]UGProjections!N40)-E6 -> 1197.4187 | F4: =SUM([2]UGProjections!P31,[2]UGProjections!P40)-F6 -> 1322.2992 | G4: =SUM([2]UGProjections!R31,[2]UGProjections!R40)-G6 -> 1459.2723 | H4: =SUM([2]UGProjections!T31,[2]UGProjections!T40)-H6 -> 1573.6406
A5: Intake - UG | B5: 923 | C5: 650 | D5: 550 | E5: =SUM([2]UGProjections!L9:M9) -> 550 | F5: =SUM([2]UGProjections!M9:N9) -> 550 | G5: =SUM([2]UGProjections!N9:O9) -> 550 | H5: =SUM([2]UGProjections!O9:P9) -> 550
A6: Intake - PG | B6: 417 | C6: 460 | D6: 460 | E6: 460 | F6: 500 | G6: 500 | H6: 500
A7: Total UG | B7: =SUM(B5,B3) -> 3304 | C7: 3607.22 | D7: 3807 | E7: 3994 | F7: 4169 | G7: 4343 | H7: 4526
A8: Total PG | B8: =SUM(B4,B6) -> 977 | C8: =SUM(C4,C6) -> 1279.53 | D8: =SUM(D4,D6) -> 1502.5293 | E8: =SUM(E4,E6) -> 1657.4187 | F8: =SUM(F4,F6) -> 1822.2992 | G8: =SUM(G4,G6) -> 1959.2723 | H8: =SUM(H4,H6) -> 2073.6406
A9: Grand Total | B9: =SUM(B7:B8) -> 4281 | C9: =SUM(C7:C8) -> 4886.75 | D9: =SUM(D7:D8) -> 5309.5293 | E9: =SUM(E7:E8) -> 5651.4187 | F9: =SUM(F7:F8) -> 5991.2992 | G9: =SUM(G7:G8) -> 6302.2723 | H9: =SUM(H7:H8) -> 6599.6406
A10: UG | B10: =B7/B9 -> 0.77178229 | C10: =C7/C9 -> 0.7381634 | D10: =D7/D9 -> 0.71701271 | E10: =E7/E9 -> 0.70672519 | F10: =F7/F9 -> 0.6958424 | G10: =G7/G9 -> 0.68911652 | H10: =H7/H9 -> 0.68579492
A11: PG | B11: =B8/B9 -> 0.22821771 | C11: =C8/C9 -> 0.2618366 | D11: =D8/D9 -> 0.28298729 | E11: =E8/E9 -> 0.29327481 | F11: =F8/F9 -> 0.3041576 | G11: =G8/G9 -> 0.31088348 | H11: =H8/H9 -> 0.31420508
A13: Actual Intake
B14: 2019-2020 | C14: 2020-2021 | D14: 2021-2022 | E14: 2022-2023 | F14: Compared to 2022 Intake | G14: Diff | I14: Compared to year 2021-22 increaed 76%. 2021-2022 PG students 431, in 20212022 PG students 758
A15: Intake - UG | B15: 798 | C15: 1144 | D15: 923 | E15: 650 | F15: =(E15-D15)/E15 -> -0.42 | G15: =E15-D15 -> -273
A16: Intake - PG | B16: 287 | C16: 386 | D16: 431 | E16: 758 | F16: =(E16-D16)/431 -> 0.7587007 | G16: =E16-D16 -> 327
A17: Medical | B17: 30 | C17: 36 | D17: 49 | E17: 60 | F17: =(E17-D17)/D17 -> 0.2244898 | G17: =E17-D17 -> 11
A26: Intake - UG | B26: Student Numbers
A27: 2019-2020 | B27: 798
A28: 2020-2021 | B28: 1144
A29: 2021-2022 | B29: 923
A30: 2022-2023 | B30: 650
B31: =SUM(B27:B30) -> 3515

Sheet 2023 Iteamized Capex and Opex
A2: Future-2 Description | B2: (All)
A4: Account Code and Description | B4: Itemised Details/Calculation method | C4: Quantity of measruing units | D4: Rate (expected) | E4: Sum of 2023 Budget
A5: 425749-Postgraduate Student Salaries | E5: 244626000
A6: 492316-Laboratory equipment | E6: 1.5088836e+08
A7: 435523-Scientific | E7: 1.1364886e+08
A8: 492200-Capital expense - Buildings | E8: 104517560
A9: 425741-Student stipend | E9: 98652604
A10: 420570-Academic Collaborative Partnership Services | E10: 56595297
A11: 432120-Bldg maintenance-Business premises | E11: 34225569
A12: 435508-Laboratory - Scientific | E12: 33397354
A13: 420811-IT Systems & Support expenses-Application/Systems Operation | E13: 27999050
A14: 430120-Rental - Buildings, other than staff residences | E14: 22219870
A15: 432209-Laboratory equipment | E15: 21267845
A16: 426610-Computer software licenses | E16: 20346378
... A100: 425300-Banking service charges / Fees | E100: 2400
A101: 420811-- | B101: Not requested | C101: 1 | D101: 1 | E101: 1
A102: 426210-Insurance - Cash and fidelity | E102: 0
A103: 430230-Rental - Equipment | E103: 0
A104: 422400-- | E104: 0
A105: 425743-Graduation rewards | E105: 0
A106: 436220-Road signs | E106: 0
A107: 425747-Student Accommodation | E107: 0
A108: (blank) | B108: (blank) | C108: (blank) | D108: (blank)
A109: 432690-Plant, machinery and heavy equipment, not mentioned elsewhere | E109: 0
A110: 421100-Manpower supply | E110: 0
A111: 420810-IT Systems & Support expenses | E111: 0
A112: Grand Total | E112: 1.1901755e+09

Sheet 2023 Detail B-01
A1: Account Group | B1: Content Expert | C1: Cost Center Code - Group | D1: Entity | E1: Cost Center Code | F1: Cost Center Description | G1: BG | H1: Account Code | I1: Account Code and Description | J1: Activity | K1: Future-1 Description | L1: Future-1 | M1: Future-2 Description | N1: Future-2 | O1: GL Account Combination | P1: 2021Actual | Q1: 2022 Budget | R1: 2022 Estimates Full Year Actual | S1: Budget Driver | T1: Measruing unit | U1: Quantity of measruing units | V1: Rate (expected) | W1: Itemised Details/Calculation method | X1: 2023 Budget | Y1: Budget Activity Type | Z1: Expenditure Frequency | AA1: 2023 Budget Scenario 90% | AB1: 2023 Budget Scenario 80% | AC1: 2023 Budget Scenario 70% | AD1: 90% Budget Scenario Impact | AE1: 80% Budget Impact | AF1: 70% Budget Impact | AG1: Jan-23 | AH1: Feb-23 | AI1: Mar-23 | AJ1: Apr-23 | AK1: May-23 | AL1: Jun-23 | AM1: Jul-23 | AN1: Aug-23 | AO1: Sep-23 | AP1: Oct-23 | AQ1: Nov-23 | AR1: Dec-23 | AS1: Total | AT1: KU Strategy | AU1: Comments
A2: - | B2: - | C2: SVP/ Support Services Office | D2: 847 | E2: 8470810 | F2: KUST - Ankabut office | G2: 1 | H2: 413328 | I2: 413328 - IT Manpower supply-IT Support resources | J2: 000000 | K2: KUST - General | L2: 847001 | M2: FA178-Manpower Expense | N2: 100178 | O2: 847.8470810.1.413328.000000.847001.100178 | R2: 8000000 | S2: Manpower Resources as per DGS Contract | T2: Months | U2: 12 | V2: 832200 | W2: Manpower Outsourcing as per DGS contract for 2023 - List Attached | X2: 9986400 | Y2: KU Regular operations | Z2: Recurring | AA2: =X2*0.9 -> 8987760 | AB2: =X2*0.8 -> 7989120 | AC2: =X2*0.7 -> 6990480 | AD2: Affects KU Core Operations and Non Compliance with contract terms | AE2: Affects KU Core Operations and Non Compliance with contract terms | AF2: Affects KU Core Operations and Non Compliance with contract terms | AG2: 832200 | AH2: 832200 | AI2: 832200 | AJ2: 832200 | AK2: 832200 | AL2: 832200 | AM2: 832200 | AN2: 832200 | AO2: 832200 | AP2: 832200 | AQ2: 832200 | AR2: 832200 | AS2: 9986400 | AU2: IT manpower should be moved to Chp-01
A3: 0 | B3: No Applicable | C3: SVP/ Support Services Office | D3: 847 | E3: 8470810 | F3: KUST - Ankabut office | G3: 1 | H3: 420810 | I3: 420810-IT Systems & Support expenses | J3: 000000 | K3: KUST - General | L3: 847001 | M3: FA179-Opex Expense | N3: 200179 | O3: 847.8470810.1.420810.000000.847001.200179 | P3: 300000 | Q3: 0 | T3: -_ | U3: 1 | X3: 0 | AA3: =X3*0.9 -> 0 | AB3: =X3*0.8 -> 0 | AC3: =X3*0.7 -> 0 | AH3: 0 | AS3: 0
A4: IT | B4: Director, Technology Development | C4: SVP/ Support Services Office | D4: 847 | E4: 8470810 | F4: KUST - Ankabut office | G4: 1 | H4: 420811 | I4: 420811-IT Systems & Support expenses-Application/Systems Operation | J4: 000000 | K4: KUST - General | L4: 847001 | M4: FA179-Opex Expense | N4: 200179 | O4: 847.8470810.1.420811.000000.847001.200179 | P4: - | Q4: 10351793 | R4: 10351793 | S4: 420811.IT Systems & Support expenses-Application/Systems Operation-professional services scope/deliverables-Month | T4: Month | U4: 12 | V4: 3759978 | W4: Managed IT Services Contract between KU and Ankabut | X4: 21982967 | Y4: KU Regular operations | Z4: Recurring | AA4: =X4*0.9 -> 19784670 | AB4: =X4*0.8 -> 17586374 | AC4: =X4*0.7 -> 15388077 | AD4: Affects KU Core Operations and Non Compliance with contract terms | AE4: Affects KU Core Operations and Non Compliance with contract terms | AF4: Affects KU Core Operations and Non Compliance with contract terms | AG4: 45119736 | AS4: 45119736 | AT4: Utilize state-of-the-art technologies and facilities in an optimal and efficient manner | AU4: Ankoubt Service agreement including Chp-01 manapower and other IT services
A5: HR | B5: No Applicable | C5: SVP/ Support Services Office | D5: 847 | E5: 8470810 | F5: KUST - Ankabut office | G5: 1 | H5: 421100 | I5: 421100-Manpower supply | J5: 000000 | K5: KUST - General | L5: 847001 | M5: FA179-Opex Expense | N5: 200179 | O5: 847.8470810.1.421100.000000.847001.200179 | P5: 1705887.1 | Q5: 445192 | R5: 445192 | T5: -_ | X5: 0 | AA5: =X5*0.9 -> 0 | AB5: =X5*0.8 -> 0 | AC5: =X5*0.7 -> 0 | AH5: 0 | AS5: 0
A6: IT | B6: Director, Technology Development | C6: SVP/ Support Services Office | D6: 847 | E6: 8470810 | F6: KUST - Ankabut office | G6: 1 | H6: 426610 | I6: 426610-Computer software licenses | J6: 000000 | K6: KUST - General | L6: 847001 | M6: FA179-Opex Expense | N6: 200179 | O6: 847.8470810.1.426610.000000.847001.200179 | P6: 8722313.4 | Q6: 7632571 | R6: 7632571 | S6: 426610.Computer software licenses-Software License Renewal-service level agreement-Service | T6: Service | U6: 1 | V6: 1235304 | W6: Microsoft Licensing Agreement Renewal (EES - 3 Years) - Licenses for multiple products | X6: 1235304 | Y6: KU Regular operations | Z6: Recurring | AA6: =X6*0.9 -> 1111773.6 | AB6: =X6*0.8 -> 988243.2 | AC6: =X6*0.7 -> 864712.8 | AD6: Affects KU Core Operations and Non Compliance with contract terms | AE6: Affects KU Core Operations and Non Compliance with contract terms | AF6: Affects KU Core Operations and Non Compliance with contract terms | AH6: 0 | AK6: 1235304 | AS6: 1235304 | AT6: Utilize state-of-the-art technologies and facilities in an optimal and efficient manner
A7: IT | B7: Director, Technology Development | C7: SVP/ Support Services Office | D7: 847 | E7: 8470810 | F7: KUST - Ankabut office | G7: 1 | H7: 426610 | I7: 426610-Computer software licenses | J7: 000000 | K7: KUST - General | L7: 847001 | M7: FA179-Opex Expense | N7: 200179 | O7: 847.8470810.1.426610.000000.847001.200179 | S7: 426610.Computer software licenses-Software License Renewal-service level agreement-Service | T7: Service | U7: 1 | V7: 856000 | W7: Learning Management System Blackboard LMS License Renewal and Annual Support (License based on storage and number of users - rate based on 8000 slab limit) | X7: 856000 | Y7: KU Regular operations | Z7: Recurring | AA7: =X7*0.9 -> 770400 | AB7: =X7*0.8 -> 684800 | AC7: =X7*0.7 -> 599200 | AD7: Affects KU Core Operations and Non Compliance with contract terms | AE7: Affects KU Core Operations and Non Compliance with contract terms | AF7: Affects KU Core Operations and Non Compliance with contract terms | AH7: 0 | AI7: 856000 | AS7: 856000 | AT7: Utilize state-of-the-art technologies and facilities in an optimal and efficient manner
A8: IT | B8: Director, Technology Development | C8: SVP/ Support Services Office | D8: 847 | E8: 8470810 | F8: KUST - Ankabut office | G8: 1 | H8: 426610 | I8: 426610-Computer software licenses | J8: 000000 | K8: KUST - General | L8: 847001 | M8: FA179-Opex Expense | N8: 200179 | O8: 847.8470810.1.426610.000000.847001.200179 | S8: 426610.Computer software licenses-Software License Renewal-service level agreement-Service | T8: Service | U8: 1 | V8: 756066 | W8: Manage Engine subscriptions for ServideskPlus, Desktop Central, OpManager, AD Manager, Exchange Reporter, App Manager and other Infrastructure Monitoring Tools. | X8: 756066 | Y8: KU Regular operations | Z8: Recurring | AA8: =X8*0.9 -> 680459.4 | AB8: =X8*0.8 -> 604852.8 | AC8: =X8*0.7 -> 529246.2 | AD8: Affects KU Core IT Operations and Non Compliance with contract terms | AE8: Affects KU Core IT Operations and Non Compliance with contract terms | AF8: Affects KU Core IT Operations and Non Compliance with contract terms | AH8: 0 | AM8: 756066 | AS8: 756066 | AT8: Utilize state-of-the-art technologies and facilities in an optimal and efficient manner
A9: IT | B9: Director, Technology Development | C9: SVP/ Support Services Office | D9: 847 | E9: 8470810 | F9: KUST - Ankabut office | G9: 1 | H9: 426610 | I9: 426610-Computer software licenses | J9: 000000 | K9: KUST - General | L9: 847001 | M9: FA179-Opex Expense | N9: 200179 | O9: 847.8470810.1.426610.000000.847001.200179 | S9: 426610.Computer software licenses-Software License Renewal-service level agreement-Service | T9: Service | U9: 1 | V9: 589375 | W9: Student Admissions Slate License and Support Renewal (5Y Service Order)- License based on number of applicants for UG/PG | X9: 589375 | Y9: KU Regular operations | Z9: Recurring | AA9: =X9*0.9 -> 530437.5 | AB9: =X9*0.8 -> 471500 | AC9: =X9*0.7 -> 412562.5 | AD9: Affects KU Core Operations and Non Compliance with contract terms | AE9: Affects KU Core Operations and Non Compliance with contract terms | AF9: Affects KU Core Operations and Non Compliance with contract terms | AH9: 0 | AK9: 589375 | AS9: 589375 | AT9: Utilize state-of-the-art technologies and facilities in an optimal and efficient manner
A10: IT | B10: Director, Technology Development | C10: SVP/ Support Services Office | D10: 847 | E10: 8470810 | F10: KUST - Ankabut office | G10: 1 | H10: 426610 | I10: 426610-Computer software licenses | J10: 000000 | K10: KUST - General | L10: 847001 | M10: FA179-Opex Expense | N10: 200179 | O10: 847.8470810.1.426610.000000.847001.200179 | S10: 426610.Computer software licenses-Software License Renewal-service level agreement-Service | T10: Service | U10: 1 | V10: 617276 | W10: Student Information System (SIS) License Renewal and Support from Elucian Banner | X10: 617276 | Y10: KU Regular operations | Z10: Recurring | AA10: =X10*0.9 -> 555548.4 | AB10: =X10*0.8 -> 493820.8 | AC10: =X10*0.7 -> 432093.2 | AD10: License cannot be reduced. Affects KU Core Operations and Non Compliance with contract terms | AE10: License cannot be reduced. Affects KU Core Operations and Non Compliance with contract terms | AF10: License cannot be reduced. Affects KU Core Operations and Non Compliance with contract terms | AH10: 0 | AK10: 617276 | AS10: 617276 | AT10: Utilize state-of-the-art technologies and facilities in an optimal and efficient manner
A11: IT | B11: Director, Technology Development | C11: SVP/ Support Services Office | D11: 847 | E11: 8470810 | F11: KUST - Ankabut office | G11: 1 | H11: 426610 | I11: 426610-Computer software licenses | J11: 000000 | K11: KUST - General | L11: 847001 | M11: FA179-Opex Expense | N11: 200179 | O11: 847.8470810.1.426610.000000.847001.200179 | S11: 426610.Computer software licenses-Software License Renewal-service level agreement-Service | T11: Service | U11: 1 | V11: 909500 | W11: Fortinet Systems Subscription Renewals for FortiClient EMS FortiEDR, FortiAnalyzer, FortiGate 101F FortiGate 40F-3G4G, FortiGate 601E FortiGate 61E, FortiManager, FortiSOAR and Incident Response Services Subscription | X11: 909500 | Y11: KU Regular operations | Z11: Recurring | AA11: =X11*0.9 -> 818550 | AB11: =X11*0.8 -> 727600 | AC11: =X11*0.7 -> 636650 | AD11: Affects KU Core IT Operations and Non Compliance with contract terms | AE11: Affects KU Core IT Operations and Non Compliance with contract terms | AF11: Affects KU Core IT Operations and Non Compliance with contract terms | AH11: 0 | AM11: 909500 | AS11: 909500 | AT11: Utilize state-of-the-art technologies and facilities in an optimal and efficient manner
