Workbook
Name Budget_2022: 'Main Page'!$B$9

Sheet Main Page
B6: KU Budget Template for Years 2023 to 2025
B8: Budget Menu
B9: Budget 2022
B10: Budget 2023
B11: Budget 2024
B12: Check List
B13: Drivers
B14: Account Code

Sheet Budget 2023
H1: Cost Center Description : | I1: =IFERROR(VLOOKUP(I2,'Cost Center'!$A:$B,2,FALSE),"")
H2: Cost Center Code : | P2: Return to Main Page | X2: Duplicated | Y2: Duplicated | AA2: Add Strategic Project
H3: Year | I3: 2023 | AV3: Updated 2023 | AW3: Updated 2023
H4: Account - Drop Box List | R4: Required | S4: Drop Box List | T4: Required | U4: Required | W4: Required | X4: Required | Y4: Required | Z4: Required | AA4: Required - Drop Box | AB4: Required - Drop Box | AF4: Required | AG4: Required | AH4: Required | AI4: Required | AV4: Drop Box List | AW4: Required | AX4: Required
A5: Account Group | B5: Content Expert | C5: Cost Center Code - Group | D5: Entity | E5: Cost Center Code | F5: Cost Center Description | G5: Budget Group | H5: Account Code | I5: Account Description | J5: Cost Center Code2 | K5: Future-1 Description | L5: Future-1 | M5: Future-2 Description | N5: Future-2 | O5: GL Account Combination | P5: 2021Actual | Q5: 2022 Budget | R5: 2022 Estimates full year Actual | S5: Budget Driver | T5: Measruing unit | U5: Quantity of measruing units | V5: Rate (expected) | W5: Itemised Details/Calculation method | X5: Quantity (expected) | Y5: Rate (expected)2 | Z5: 2023 Budget | AA5: Budget Activity Type | AB5: Expenditure Frequency | AC5: 2023 Budget Scenario 90% | AD5: 2023 Budget Scenario 80% | AE5: 2023 Budget Scenario 70% | AF5: 90% Budget Scenario Impact | AG5: 80% Budget Impact | AH5: 70% Budget Impact | AI5: Jan-23 | AJ5: Feb-23 | AK5: Mar-23 | AL5: Apr-23 | AM5: May-23 | AN5: Jun-23 | AO5: Jul-23 | AP5: Aug-23 | AQ5: Sep-23 | AR5: Oct-23 | AS5: Nov-23 | AT5: Dec-23 | AU5: Total | AV5: KU Strategy | AW5: Department operation Objective | AX5: Contract or Agreement or PO or budgetary Quotation - Uploaded in KU Driver
A6: =VLOOKUP(H6,'Accoount Code Combination'!$D:$L,8,FALSE) -> HR | B6: =VLOOKUP(Table1[[#This Row],[Account Code]],'Accoount Code Combination'!$D:$L,9,FALSE) -> Outsourcing | C6: =VLOOKUP(Table1[[#This Row],[Cost Center Code]],'Cost Center Group'!A:B,2,FALSE) -> President's Office | D6: 847 | E6: 8470110 | F6: KUST - Office of the President | G6: 1 | H6: 421100 | I6: =IFERROR(VLOOKUP(Table1[[#This Row],[Account Code]],'Accoount Code Combination'!$D:$H,2,FALSE),"") -> Manpower supply | J6: 8470110 | K6: COVID-19 Pandemic | L6: =IFERROR(VLOOKUP(Table1[[#This Row],[Future-1 Description]],'Other '!E1:$F10,2,FALSE),"") -> 847951 | N6: 200179 | P6: 29118.02 | Q6: 29119 | S6: Trips | T6: Number | U6: 50 | V6: 10000 | W6: %@1000 | Z6: =Table1[[#This Row],[Quantity of measruing units]]*Table1[[#This Row],[Rate (expected)]] -> 500000 | AC6: =Table1[[#This Row],[Quantity (expected)]]*Table1[[#This Row],[Rate (expected)2]]*0.9 -> 0 | AD6: =Table1[[#This Row],[Quantity (expected)]]*Table1[[#This Row],[Rate (expected)2]]*0.8 -> 0 | AE6: =Table1[[#This Row],[Quantity (expected)]]*Table1[[#This Row],[Rate (expected)2]]*0.7 -> 0 | AQ6: 0 | AR6: 0 | AS6: 0 | AU6: =SUM(Table1[[#This Row],[Jan-23]:[Dec-23]]) -> 0 | AV6: Develop the university innovation and entrepreneurship system | AY6: List : Yes/NO
A7: =VLOOKUP(H7,'Accoount Code Combination'!$D:$L,8,FALSE) -> Other support | B7: =VLOOKUP(Table1[[#This Row],[Account Code]],'Accoount Code Combination'!$D:$L,9,FALSE) -> Legal and professional fees | C7: =VLOOKUP(Table1[[#This Row],[Cost Center Code]],'Cost Center Group'!A:B,2,FALSE) -> Information Technology/ANKABUT | D7: 847 | E7: 8470810 | G7: 1 | H7: 420900 | I7: =VLOOKUP(Table1[[#This Row],[Account Code]],'Accoount Code Combination'!$D:$H,2,FALSE) -> Legal services | J7: 8470110 | K7: KUST- Masdar city campus | L7: =VLOOKUP(Table1[[#This Row],[Future-1 Description]],'Other '!E2:$F11,2,FALSE) -> 847030 | N7: 200179 | Z7: =Table1[[#This Row],[Quantity of measruing units]]*Table1[[#This Row],[Rate (expected)]] -> 0 | AC7: =Table1[[#This Row],[Quantity (expected)]]*Table1[[#This Row],[Rate (expected)2]]*0.9 -> 0 | AD7: =Table1[[#This Row],[Quantity (expected)]]*Table1[[#This Row],[Rate (expected)2]]*0.8 -> 0 | AE7: =Table1[[#This Row],[Quantity (expected)]]*Table1[[#This Row],[Rate (expected)2]]*0.7 -> 0 | AU7: =SUM(Table1[[#This Row],[Jan-23]:[Dec-23]]) -> 0
A8: =VLOOKUP(H8,'Accoount Code Combination'!$D:$L,8,FALSE) -> Academic | B8: =VLOOKUP(Table1[[#This Row],[Account Code]],'Accoount Code Combination'!$D:$L,9,FALSE) -> No Applicable | C8: =VLOOKUP(Table1[[#This Row],[Cost Center Code]],'Cost Center Group'!A:B,2,FALSE) -> President's Office | D8: 847 | E8: 8470110 | G8: 1 | H8: 425770 | I8: =VLOOKUP(Table1[[#This Row],[Account Code]],'Accoount Code Combination'!$D:$H,2,FALSE) -> Academic Missions - Combined expenses | J8: 8470110 | L8: =VLOOKUP(Table1[[#This Row],[Future-1 Description]],'Other '!E3:$F12,2,FALSE) -> #N/A | Z8: =Table1[[#This Row],[Quantity of measruing units]]*Table1[[#This Row],[Rate (expected)]] -> 0 | AC8: =Table1[[#This Row],[Quantity (expected)]]*Table1[[#This Row],[Rate (expected)2]]*0.9 -> 0 | AD8: =Table1[[#This Row],[Quantity (expected)]]*Table1[[#This Row],[Rate (expected)2]]*0.8 -> 0 | AE8: =Table1[[#This Row],[Quantity (expected)]]*Table1[[#This Row],[Rate (expected)2]]*0.7 -> 0 | AU8: =SUM(Table1[[#This Row],[Jan-23]:[Dec-23]]) -> 0
A9: =VLOOKUP(H9,'Accoount Code Combination'!$D:$L,8,FALSE) -> Other support | B9: =VLOOKUP(Table1[[#This Row],[Account Code]],'Accoount Code Combination'!$D:$L,9,FALSE) -> No Applicable | C9: =VLOOKUP(Table1[[#This Row],[Cost Center Code]],'Cost Center Group'!A:B,2,FALSE) -> President's Office | D9: 847 | E9: 8470110 | G9: 1 | H9: 425900 | I9: =VLOOKUP(Table1[[#This Row],[Account Code]],'Accoount Code Combination'!$D:$H,2,FALSE) -> Entertainment and hospitality | J9: 8470110 | K9: KUST - GRC Operations | L9: =VLOOKUP(Table1[[#This Row],[Future-1 Description]],'Other '!E4:$F13,2,FALSE) -> 847040 | Z9: =Table1[[#This Row],[Quantity of measruing units]]*Table1[[#This Row],[Rate (expected)]] -> 0 | AC9: =Table1[[#This Row],[Quantity (expected)]]*Table1[[#This Row],[Rate (expected)2]]*0.9 -> 0 | AD9: =Table1[[#This Row],[Quantity (expected)]]*Table1[[#This Row],[Rate (expected)2]]*0.8 -> 0 | AE9: =Table1[[#This Row],[Quantity (expected)]]*Table1[[#This Row],[Rate (expected)2]]*0.7 -> 0 | AU9: =SUM(Table1[[#This Row],[Jan-23]:[Dec-23]]) -> 0
A10: =VLOOKUP(H10,'Accoount Code Combination'!$D:$L,8,FALSE) -> Other support | B10: =VLOOKUP(Table1[[#This Row],[Account Code]],'Accoount Code Combination'!$D:$L,9,FALSE) -> Legal and professional fees | C10: =VLOOKUP(Table1[[#This Row],[Cost Center Code]],'Cost Center Group'!A:B,2,FALSE) -> President's Office | D10: 847 | E10: 8470110 | G10: 1 | H10: 420900 | I10: =VLOOKUP(Table1[[#This Row],[Account Code]],'Accoount Code Combination'!$D:$H,2,FALSE) -> Legal services | J10: 8470110 | K10: KUST - GRC Operations | L10: =VLOOKUP(Table1[[#This Row],[Future-1 Description]],'Other '!E5:$F14,2,FALSE) -> 847040 | Z10: =Table1[[#This Row],[Quantity of measruing units]]*Table1[[#This Row],[Rate (expected)]] -> 0 | AC10: =Table1[[#This Row],[Quantity (expected)]]*Table1[[#This Row],[Rate (expected)2]]*0.9 -> 0 | AD10: =Table1[[#This Row],[Quantity (expected)]]*Table1[[#This Row],[Rate (expected)2]]*0.8 -> 0 | AE10: =Table1[[#This Row],[Quantity (expected)]]*Table1[[#This Row],[Rate (expected)2]]*0.7 -> 0 | AU10: =SUM(Table1[[#This Row],[Jan-23]:[Dec-23]]) -> 0
A11: =VLOOKUP(H11,'Accoount Code Combination'!$D:$L,8,FALSE) -> #N/A | B11: =VLOOKUP(Table1[[#This Row],[Account Code]],'Accoount Code Combination'!$D:$L,9,FALSE) -> #N/A | C11: =VLOOKUP(Table1[[#This Row],[Cost Center Code]],'Cost Center Group'!A:B,2,FALSE) -> President's Office | D11: 847 | E11: 8470110 | G11: 1 | I11: =VLOOKUP(Table1[[#This Row],[Account Code]],'Accoount Code Combination'!$D:$H,2,FALSE) -> #N/A | J11: 8470110 | L11: =VLOOKUP(Table1[[#This Row],[Future-1 Description]],'Other '!E6:$F15,2,FALSE) -> #N/A | Z11: =Table1[[#This Row],[Quantity of measruing units]]*Table1[[#This Row],[Rate (expected)]] -> 0 | AC11: =Table1[[#This Row],[Quantity (expected)]]*Table1[[#This Row],[Rate (expected)2]]*0.9 -> 0 | AD11: =Table1[[#This Row],[Quantity (expected)]]*Table1[[#This Row],[Rate (expected)2]]*0.8 -> 0 | AE11: =Table1[[#This Row],[Quantity (expected)]]*Table1[[#This Row],[Rate (expected)2]]*0.7 -> 0 | AU11: =SUM(Table1[[#This Row],[Jan-23]:[Dec-23]]) -> 0
A12: =VLOOKUP(H12,'Accoount Code Combination'!$D:$L,8,FALSE) -> #N/A | B12: =VLOOKUP(Table1[[#This Row],[Account Code]],'Accoount Code Combination'!$D:$L,9,FALSE) -> #N/A | C12: =VLOOKUP(Table1[[#This Row],[Cost Center Code]],'Cost Center Group'!A:B,2,FALSE) -> President's Office | D12: 847 | E12: 8470110 | G12: 1 | I12: =VLOOKUP(Table1[[#This Row],[Account Code]],'Accoount Code Combination'!$D:$H,2,FALSE) -> #N/A | J12: 8470110 | L12: =VLOOKUP(Table1[[#This Row],[Future-1 Description]],'Other '!E7:$F16,2,FALSE) -> #N/A | Z12: =Table1[[#This Row],[Quantity of measruing units]]*Table1[[#This Row],[Rate (expected)]] -> 0 | AC12: =Table1[[#This Row],[Quantity (expected)]]*Table1[[#This Row],[Rate (expected)2]]*0.9 -> 0 | AD12: =Table1[[#This Row],[Quantity (expected)]]*Table1[[#This Row],[Rate (expected)2]]*0.8 -> 0 | AE12: =Table1[[#This Row],[Quantity (expected)]]*Table1[[#This Row],[Rate (expected)2]]*0.7 -> 0 | AU12: =SUM(Table1[[#This Row],[Jan-23]:[Dec-23]]) -> 0
A13: =VLOOKUP(H13,'Accoount Code Combination'!$D:$L,8,FALSE) -> #N/A | B13: =VLOOKUP(Table1[[#This Row],[Account Code]],'Accoount Code Combination'!$D:$L,9,FALSE) -> #N/A | C13: =VLOOKUP(Table1[[#This Row],[Cost Center Code]],'Cost Center Group'!A:B,2,FALSE) -> President's Office | D13: 847 | E13: 8470110 | G13: 1 | I13: =VLOOKUP(Table1[[#This Row],[Account Code]],'Accoount Code Combination'!$D:$H,2,FALSE) -> #N/A | J13: 8470110 | L13: =VLOOKUP(Table1[[#This Row],[Future-1 Description]],'Other '!E8:$F17,2,FALSE) -> #N/A | Z13: =Table1[[#This Row],[Quantity of measruing units]]*Table1[[#This Row],[Rate (expected)]] -> 0 | AC13: =Table1[[#This Row],[Quantity (expected)]]*Table1[[#This Row],[Rate (expected)2]]*0.9 -> 0 | AD13: =Table1[[#This Row],[Quantity (expected)]]*Table1[[#This Row],[Rate (expected)2]]*0.8 -> 0 | AE13: =Table1[[#This Row],[Quantity (expected)]]*Table1[[#This Row],[Rate (expected)2]]*0.7 -> 0 | AU13: =SUM(Table1[[#This Row],[Jan-23]:[Dec-23]]) -> 0
A14: =VLOOKUP(H14,'Accoount Code Combination'!$D:$L,8,FALSE) -> #N/A | B14: =VLOOKUP(Table1[[#This Row],[Account Code]],'Accoount Code Combination'!$D:$L,9,FALSE) -> #N/A | C14: =VLOOKUP(Table1[[#This Row],[Cost Center Code]],'Cost Center Group'!A:B,2,FALSE) -> President's Office | D14: 847 | E14: 8470110 | G14: 1 | I14: =VLOOKUP(Table1[[#This Row],[Account Code]],'Accoount Code Combination'!$D:$H,2,FALSE) -> #N/A | J14: 8470110 | L14: =VLOOKUP(Table1[[#This Row],[Future-1 Description]],'Other '!E2:$F11,2,FALSE) -> #N/A | Z14: =Table1[[#This Row],[Quantity of measruing units]]*Table1[[#This Row],[Rate (expected)]] -> 0 | AC14: =Table1[[#This Row],[Quantity (expected)]]*Table1[[#This Row],[Rate (expected)2]]*0.9 -> 0 | AD14: =Table1[[#This Row],[Quantity (expected)]]*Table1[[#This Row],[Rate (expected)2]]*0.8 -> 0 | AE14: =Table1[[#This Row],[Quantity (expected)]]*Table1[[#This Row],[Rate (expected)2]]*0.7 -> 0 | AU14: =SUM(Table1[[#This Row],[Jan-23]:[Dec-23]]) -> 0
A15: =VLOOKUP(H15,'Accoount Code Combination'!$D:$L,8,FALSE) -> Academic | B15: =VLOOKUP(Table1[[#This Row],[Account Code]],'Accoount Code Combination'!$D:$L,9,FALSE) -> No Applicable | C15: =VLOOKUP(Table1[[#This Row],[Cost Center Code]],'Cost Center Group'!A:B,2,FALSE) -> President's Office | D15: 847 | E15: 8470110 | F15: KUST - Office of the President | G15: 1 | H15: 420570 | I15: =IFERROR(VLOOKUP(Table1[[#This Row],[Account Code]],'Accoount Code Combination'!$D:$H,2,FALSE),"") -> Academic Collaborative Partnership Services | J15: 8470110 | L15: =IFERROR(VLOOKUP(Table1[[#This Row],[Future-1 Description]],'Other '!E3:$F12,2,FALSE),"") | P15: 0 | Q15: 1 | Z15: =Table1[[#This Row],[Quantity of measruing units]]*Table1[[#This Row],[Rate (expected)]] -> 0 | AC15: =Table1[[#This Row],[Quantity (expected)]]*Table1[[#This Row],[Rate (expected)2]]*0.9 -> 0 | AD15: =Table1[[#This Row],[Quantity (expected)]]*Table1[[#This Row],[Rate (expected)2]]*0.8 -> 0 | AE15: =Table1[[#This Row],[Quantity (expected)]]*Table1[[#This Row],[Rate (expected)2]]*0.7 -> 0 | AU15: =SUM(Table1[[#This Row],[Jan-23]:[Dec-23]]) -> 0
A16: =VLOOKUP(H16,'Accoount Code Combination'!$D:$L,8,FALSE) -> Other support | B16: =VLOOKUP(Table1[[#This Row],[Account Code]],'Accoount Code Combination'!$D:$L,9,FALSE) -> Legal and professional fees | C16: =VLOOKUP(Table1[[#This Row],[Cost Center Code]],'Cost Center Group'!A:B,2,FALSE) -> President's Office | D16: 847 | E16: 8470110 | F16: KUST - Office of the President | G16: 1 | H16: 420900 | I16: =IFERROR(VLOOKUP(Table1[[#This Row],[Account Code]],'Accoount Code Combination'!$D:$H,2,FALSE),"") -> Legal services | J16: 8470110 | L16: =IFERROR(VLOOKUP(Table1[[#This Row],[Future-1 Description]],'Other '!E4:$F13,2,FALSE),"") | P16: 1845 | Q16: 1501 | Z16: =Table1[[#This Row],[Quantity of measruing units]]*Table1[[#This Row],[Rate (expected)]] -> 0 | AC16: =Table1[[#This Row],[Quantity (expected)]]*Table1[[#This Row],[Rate (expected)2]]*0.9 -> 0 | AD16: =Table1[[#This Row],[Quantity (expected)]]*Table1[[#This Row],[Rate (expected)2]]*0.8 -> 0 | AE16: =Table1[[#This Row],[Quantity (expected)]]*Table1[[#This Row],[Rate (expected)2]]*0.7 -> 0 | AU16: =SUM(Table1[[#This Row],[Jan-23]:[Dec-23]]) -> 0
A17: =VLOOKUP(H17,'Accoount Code Combination'!$D:$L,8,FALSE) -> HR | B17: =VLOOKUP(Table1[[#This Row],[Account Code]],'Accoount Code Combination'!$D:$L,9,FALSE) -> Consultancy | C17: =VLOOKUP(Table1[[#This Row],[Cost Center Code]],'Cost Center Group'!A:B,2,FALSE) -> President's Office | D17: 847 | E17: 8470110 | F17: KUST - Office of the President | G17: 1 | H17: 421000 | I17: =IFERROR(VLOOKUP(Table1[[#This Row],[Account Code]],'Accoount Code Combination'!$D:$H,2,FALSE),"") -> Management consultancy | J17: 8470110 | L17: =IFERROR(VLOOKUP(Table1[[#This Row],[Future-1 Description]],'Other '!E5:$F14,2,FALSE),"") | P17: 0 | Q17: 1 | Z17: =Table1[[#This Row],[Quantity of measruing units]]*Table1[[#This Row],[Rate (expected)]] -> 0 | AC17: =Table1[[#This Row],[Quantity (expected)]]*Table1[[#This Row],[Rate (expected)2]]*0.9 -> 0 | AD17: =Table1[[#This Row],[Quantity (expected)]]*Table1[[#This Row],[Rate (expected)2]]*0.8 -> 0 | AE17: =Table1[[#This Row],[Quantity (expected)]]*Table1[[#This Row],[Rate (expected)2]]*0.7 -> 0 | AU17: =SUM(Table1[[#This Row],[Jan-23]:[Dec-23]]) -> 0
A18: =VLOOKUP(H18,'Accoount Code Combination'!$D:$L,8,FALSE) -> Academic | B18: =VLOOKUP(Table1[[#This Row],[Account Code]],'Accoount Code Combination'!$D:$L,9,FALSE) -> No Applicable | C18: =VLOOKUP(Table1[[#This Row],[Cost Center Code]],'Cost Center Group'!A:B,2,FALSE) -> President's Office | D18: 847 | E18: 8470110 | F18: KUST - Office of the President | G18: 1 | H18: 421700 | I18: =IFERROR(VLOOKUP(Table1[[#This Row],[Account Code]],'Accoount Code Combination'!$D:$H,2,FALSE),"") -> Standards certification (e.g. ISO) | J18: 8470110 | L18: =IFERROR(VLOOKUP(Table1[[#This Row],[Future-1 Description]],'Other '!E6:$F15,2,FALSE),"") | P18: 0 | Q18: 25000 | Z18: =Table1[[#This Row],[Quantity of measruing units]]*Table1[[#This Row],[Rate (expected)]] -> 0 | AC18: =Table1[[#This Row],[Quantity (expected)]]*Table1[[#This Row],[Rate (expected)2]]*0.9 -> 0 | AD18: =Table1[[#This Row],[Quantity (expected)]]*Table1[[#This Row],[Rate (expected)2]]*0.8 -> 0 | AE18: =Table1[[#This Row],[Quantity (expected)]]*Table1[[#This Row],[Rate (expected)2]]*0.7 -> 0 | AU18: =SUM(Table1[[#This Row],[Jan-23]:[Dec-23]]) -> 0
A19: =VLOOKUP(H19,'Accoount Code Combination'!$D:$L,8,FALSE) -> Communiction & Marketing | B19: =VLOOKUP(Table1[[#This Row],[Account Code]],'Accoount Code Combination'!$D:$L,9,FALSE) -> Advertising | C19: =VLOOKUP(Table1[[#This Row],[Cost Center Code]],'Cost Center Group'!A:B,2,FALSE) -> President's Office | D19: 847 | E19: 8470110 | F19: KUST - Office of the President | G19: 1 | H19: 425100 | I19: =IFERROR(VLOOKUP(Table1[[#This Row],[Account Code]],'Accoount Code Combination'!$D:$H,2,FALSE),"") -> Advertising | J19: 8470110 | L19: =IFERROR(VLOOKUP(Table1[[#This Row],[Future-1 Description]],'Other '!E7:$F16,2,FALSE),"") | P19: 0 | Q19: 0 | Z19: =Table1[[#This Row],[Quantity of measruing units]]*Table1[[#This Row],[Rate (expected)]] -> 0 | AC19: =Table1[[#This Row],[Quantity (expected)]]*Table1[[#This Row],[Rate (expected)2]]*0.9 -> 0 | AD19: =Table1[[#This Row],[Quantity (expected)]]*Table1[[#This Row],[Rate (expected)2]]*0.8 -> 0 | AE19: =Table1[[#This Row],[Quantity (expected)]]*Table1[[#This Row],[Rate (expected)2]]*0.7 -> 0 | AU19: =SUM(Table1[[#This Row],[Jan-23]:[Dec-23]]) -> 0
A20: =VLOOKUP(H20,'Accoount Code Combination'!$D:$L,8,FALSE) -> Communiction & Marketing | B20: =VLOOKUP(Table1[[#This Row],[Account Code]],'Accoount Code Combination'!$D:$L,9,FALSE) -> Events | C20: =VLOOKUP(Table1[[#This Row],[Cost Center Code]],'Cost Center Group'!A:B,2,FALSE) -> President's Office | D20: 847 | E20: 8470110 | F20: KUST - Office of the President | G20: 1 | H20: 425510 | I20: =IFERROR(VLOOKUP(Table1[[#This Row],[Account Code]],'Accoount Code Combination'!$D:$H,2,FALSE),"") -> Conferences, seminars and exhibitions and other events: - Local Events | J20: 8470110 | L20: =IFERROR(VLOOKUP(Table1[[#This Row],[Future-1 Description]],'Other '!E8:$F17,2,FALSE),"") | P20: 277368 | Q20: 0 | Z20: =Table1[[#This Row],[Quantity of measruing units]]*Table1[[#This Row],[Rate (expected)]] -> 0 | AC20: =Table1[[#This Row],[Quantity (expected)]]*Table1[[#This Row],[Rate (expected)2]]*0.9 -> 0 | AD20: =Table1[[#This Row],[Quantity (expected)]]*Table1[[#This Row],[Rate (expected)2]]*0.8 -> 0 | AE20: =Table1[[#This Row],[Quantity (expected)]]*Table1[[#This Row],[Rate (expected)2]]*0.7 -> 0 | AU20: =SUM(Table1[[#This Row],[Jan-23]:[Dec-23]]) -> 0
A21: =VLOOKUP(H21,'Accoount Code Combination'!$D:$L,8,FALSE) -> Communiction & Marketing | B21: =VLOOKUP(Table1[[#This Row],[Account Code]],'Accoount Code Combination'!$D:$L,9,FALSE) -> No Applicable | C21: =VLOOKUP(Table1[[#This Row],[Cost Center Code]],'Cost Center Group'!A:B,2,FALSE) -> President's Office | D21: 847 | E21: 8470110 | F21: KUST - Office of the President | G21: 1 | H21: 425550 | I21: =IFERROR(VLOOKUP(Table1[[#This Row],[Account Code]],'Accoount Code Combination'!$D:$H,2,FALSE),"") -> Conferences, seminars and exhibitions and other events: - Overseas event | J21: 8470110 | L21: =IFERROR(VLOOKUP(Table1[[#This Row],[Future-1 Description]],'Other '!E9:$F18,2,FALSE),"") | P21: 0 | Q21: 0 | Z21: =Table1[[#This Row],[Quantity of measruing units]]*Table1[[#This Row],[Rate (expected)]] -> 0 | AC21: =Table1[[#This Row],[Quantity (expected)]]*Table1[[#This Row],[Rate (expected)2]]*0.9 -> 0 | AD21: =Table1[[#This Row],[Quantity (expected)]]*Table1[[#This Row],[Rate (expected)2]]*0.8 -> 0 | AE21: =Table1[[#This Row],[Quantity (expected)]]*Table1[[#This Row],[Rate (expected)2]]*0.7 -> 0 | AU21: =SUM(Table1[[#This Row],[Jan-23]:[Dec-23]]) -> 0
A22: =VLOOKUP(H22,'Accoount Code Combination'!$D:$L,8,FALSE) -> Academic | B22: =VLOOKUP(Table1[[#This Row],[Account Code]],'Accoount Code Combination'!$D:$L,9,FALSE) -> No Applicable | C22: =VLOOKUP(Table1[[#This Row],[Cost Center Code]],'Cost Center Group'!A:B,2,FALSE) -> President's Office | D22: 847 | E22: 8470110 | F22: KUST - Office of the President | G22: 1 | H22: 425770 | I22: =IFERROR(VLOOKUP(Table1[[#This Row],[Account Code]],'Accoount Code Combination'!$D:$H,2,FALSE),"") -> Academic Missions - Combined expenses | J22: 8470110 | L22: =IFERROR(VLOOKUP(Table1[[#This Row],[Future-1 Description]],'Other '!E10:$F19,2,FALSE),"") | P22: -13420 | Q22: 0 | Z22: =Table1[[#This Row],[Quantity of measruing units]]*Table1[[#This Row],[Rate (expected)]] -> 0 | AC22: =Table1[[#This Row],[Quantity (expected)]]*Table1[[#This Row],[Rate (expected)2]]*0.9 -> 0 | AD22: =Table1[[#This Row],[Quantity (expected)]]*Table1[[#This Row],[Rate (expected)2]]*0.8 -> 0 | AE22: =Table1[[#This Row],[Quantity (expected)]]*Table1[[#This Row],[Rate (expected)2]]*0.7 -> 0 | AU22: =SUM(Table1[[#This Row],[Jan-23]:[Dec-23]]) -> 0
A23: =VLOOKUP(H23,'Accoount Code Combination'!$D:$L,8,FALSE) -> Other support | B23: =VLOOKUP(Table1[[#This Row],[Account Code]],'Accoount Code Combination'!$D:$L,9,FALSE) -> No Applicable | C23: =VLOOKUP(Table1[[#This Row],[Cost Center Code]],'Cost Center Group'!A:B,2,FALSE) -> President's Office | D23: 847 | E23: 8470110 | F23: KUST - Office of the President | G23: 1 | H23: 425900 | I23: =IFERROR(VLOOKUP(Table1[[#This Row],[Account Code]],'Accoount Code Combination'!$D:$H,2,FALSE),"") -> Entertainment and hospitality | J23: 8470110 | L23: =IFERROR(VLOOKUP(Table1[[#This Row],[Future-1 Description]],'Other '!E11:$F20,2,FALSE),"") | P23: 13355.7 | Q23: 10000 | Z23: =Table1[[#This Row],[Quantity of measruing units]]*Table1[[#This Row],[Rate (expected)]] -> 0 | AC23: =Table1[[#This Row],[Quantity (expected)]]*Table1[[#This Row],[Rate (expected)2]]*0.9 -> 0 | AD23: =Table1[[#This Row],[Quantity (expected)]]*Table1[[#This Row],[Rate (expected)2]]*0.8 -> 0 | AE23: =Table1[[#This Row],[Quantity (expected)]]*Table1[[#This Row],[Rate (expected)2]]*0.7 -> 0 | AU23: =SUM(Table1[[#This Row],[Jan-23]:[Dec-23]]) -> 0
A24: =VLOOKUP(H24,'Accoount Code Combination'!$D:$L,8,FALSE) -> IT | B24: =VLOOKUP(Table1[[#This Row],[Account Code]],'Accoount Code Combination'!$D:$L,9,FALSE) -> Software Operating | C24: =VLOOKUP(Table1[[#This Row],[Cost Center Code]],'Cost Center Group'!A:B,2,FALSE) -> President's Office | D24: 847 | E24: 8470110 | F24: KUST - Office of the President | G24: 1 | H24: 426610 | I24: =IFERROR(VLOOKUP(Table1[[#This Row],[Account Code]],'Accoount Code Combination'!$D:$H,2,FALSE),"") -> Computer software licenses | J24: 8470110 | L24: =IFERROR(VLOOKUP(Table1[[#This Row],[Future-1 Description]],'Other '!E12:$F21,2,FALSE),"") | P24: 42239.5 | Q24: 80204 | Z24: =Table1[[#This Row],[Quantity of measruing units]]*Table1[[#This Row],[Rate (expected)]] -> 0 | AC24: =Table1[[#This Row],[Quantity (expected)]]*Table1[[#This Row],[Rate (expected)2]]*0.9 -> 0 | AD24: =Table1[[#This Row],[Quantity (expected)]]*Table1[[#This Row],[Rate (expected)2]]*0.8 -> 0 | AE24: =Table1[[#This Row],[Quantity (expected)]]*Table1[[#This Row],[Rate (expected)2]]*0.7 -> 0 | AU24: =SUM(Table1[[#This Row],[Jan-23]:[Dec-23]]) -> 0
A25: =VLOOKUP(H25,'Accoount Code Combination'!$D:$L,8,FALSE) -> Academic | B25: =VLOOKUP(Table1[[#This Row],[Account Code]],'Accoount Code Combination'!$D:$L,9,FALSE) -> No Applicable | C25: =VLOOKUP(Table1[[#This Row],[Cost Center Code]],'Cost Center Group'!A:B,2,FALSE) -> President's Office | D25: 847 | E25: 8470110 | F25: KUST - Office of the President | G25: 1 | H25: 427710 | I25: =IFERROR(VLOOKUP(Table1[[#This Row],[Account Code]],'Accoount Code Combination'!$D:$H,2,FALSE),"") -> Subscriptions and membership fees: Trade organisations | J25: 8470110 | L25: =IFERROR(VLOOKUP(Table1[[#This Row],[Future-1 Description]],'Other '!E13:$F22,2,FALSE),"") | P25: 3882.17 | Q25: 1880 | Z25: =Table1[[#This Row],[Quantity of measruing units]]*Table1[[#This Row],[Rate (expected)]] -> 0 | AC25: =Table1[[#This Row],[Quantity (expected)]]*Table1[[#This Row],[Rate (expected)2]]*0.9 -> 0 | AD25: =Table1[[#This Row],[Quantity (expected)]]*Table1[[#This Row],[Rate (expected)2]]*0.8 -> 0 | AE25: =Table1[[#This Row],[Quantity (expected)]]*Table1[[#This Row],[Rate (expected)2]]*0.7 -> 0 | AU25: =SUM(Table1[[#This Row],[Jan-23]:[Dec-23]]) -> 0
A26: =VLOOKUP(H26,'Accoount Code Combination'!$D:$L,8,FALSE) -> Other support | B26: =VLOOKUP(Table1[[#This Row],[Account Code]],'Accoount Code Combination'!$D:$L,9,FALSE) -> No Applicable | C26: =VLOOKUP(Table1[[#This Row],[Cost Center Code]],'Cost Center Group'!A:B,2,FALSE) -> President's Office | D26: 847 | E26: 8470110 | F26: KUST - Office of the President | G26: 1 | H26: 427900 | I26: =IFERROR(VLOOKUP(Table1[[#This Row],[Account Code]],'Accoount Code Combination'!$D:$H,2,FALSE),"") -> Translation and interpretation service | J26: 8470110 | L26: =IFERROR(VLOOKUP(Table1[[#This Row],[Future-1 Description]],'Other '!E14:$F23,2,FALSE),"") | P26: 0 | Q26: 12585 | Z26: =Table1[[#This Row],[Quantity of measruing units]]*Table1[[#This Row],[Rate (expected)]] -> 0 | AC26: =Table1[[#This Row],[Quantity (expected)]]*Table1[[#This Row],[Rate (expected)2]]*0.9 -> 0 | AD26: =Table1[[#This Row],[Quantity (expected)]]*Table1[[#This Row],[Rate (expected)2]]*0.8 -> 0 | AE26: =Table1[[#This Row],[Quantity (expected)]]*Table1[[#This Row],[Rate (expected)2]]*0.7 -> 0 | AU26: =SUM(Table1[[#This Row],[Jan-23]:[Dec-23]]) -> 0
... A631: =VLOOKUP(H631,'Accoount Code Combination'!$D:$L,8,FALSE) -> 0 | B631: =VLOOKUP(Table1[[#This Row],[Account Code]],'Accoount Code Combination'!$D:$L,9,FALSE) -> Software Capital | C631: =VLOOKUP(Table1[[#This Row],[Cost Center Code]],'Cost Center Group'!A:B,2,FALSE) -> College of Medicine & Health Sciences | D631: 847 | E631: 8471305 | F631: KUST - Dean Of Medicine | G631: 1 | H631: 495140 | I631: =IFERROR(VLOOKUP(Table1[[#This Row],[Account Code]],'Accoount Code Combination'!$D:$H,2,FALSE),"") -> Copyrights, patents and licenses | J631: 8471305 | L631: =IFERROR(VLOOKUP(Table1[[#This Row],[Future-1 Description]],'Other '!E619:$F628,2,FALSE),"") | P631: 0 | Q631: 500000 | Z631: =Table1[[#This Row],[Quantity of measruing units]]*Table1[[#This Row],[Rate (expected)]] -> 0 | AC631: =Table1[[#This Row],[Quantity (expected)]]*Table1[[#This Row],[Rate (expected)2]]*0.9 -> 0 | AD631: =Table1[[#This Row],[Quantity (expected)]]*Table1[[#This Row],[Rate (expected)2]]*0.8 -> 0 | AE631: =Table1[[#This Row],[Quantity (expected)]]*Table1[[#This Row],[Rate (expected)2]]*0.7 -> 0 | AU631: =SUM(Table1[[#This Row],[Jan-23]:[Dec-23]]) -> 0
A632: =VLOOKUP(H632,'Accoount Code Combination'!$D:$L,8,FALSE) -> #N/A | B632: =VLOOKUP(Table1[[#This Row],[Account Code]],'Accoount Code Combination'!$D:$L,9,FALSE) -> #N/A | C632: =VLOOKUP(Table1[[#This Row],[Cost Center Code]],'Cost Center Group'!A:B,2,FALSE) -> #N/A | D632: 847 | G632: 1 | I632: =IFERROR(VLOOKUP(Table1[[#This Row],[Account Code]],'Accoount Code Combination'!$D:$H,2,FALSE),"") | L632: =IFERROR(VLOOKUP(Table1[[#This Row],[Future-1 Description]],'Other '!E620:$F629,2,FALSE),"") | Q632: 0 | Z632: =Table1[[#This Row],[Quantity of measruing units]]*Table1[[#This Row],[Rate (expected)]] -> 0 | AC632: =Table1[[#This Row],[Quantity (expected)]]*Table1[[#This Row],[Rate (expected)2]]*0.9 -> 0 | AD632: =Table1[[#This Row],[Quantity (expected)]]*Table1[[#This Row],[Rate (expected)2]]*0.8 -> 0 | AE632: =Table1[[#This Row],[Quantity (expected)]]*Table1[[#This Row],[Rate (expected)2]]*0.7 -> 0 | AU632: =SUM(Table1[[#This Row],[Jan-23]:[Dec-23]]) -> 0
A633: =VLOOKUP(H633,'Accoount Code Combination'!$D:$L,8,FALSE) -> #N/A | B633: =VLOOKUP(Table1[[#This Row],[Account Code]],'Accoount Code Combination'!$D:$L,9,FALSE) -> #N/A | C633: =VLOOKUP(Table1[[#This Row],[Cost Center Code]],'Cost Center Group'!A:B,2,FALSE) -> #N/A | D633: 847 | G633: 1 | I633: =IFERROR(VLOOKUP(Table1[[#This Row],[Account Code]],'Accoount Code Combination'!$D:$H,2,FALSE),"") | L633: =IFERROR(VLOOKUP(Table1[[#This Row],[Future-1 Description]],'Other '!E621:$F630,2,FALSE),"") | Z633: =Table1[[#This Row],[Quantity of measruing units]]*Table1[[#This Row],[Rate (expected)]] -> 0 | AC633: =Table1[[#This Row],[Quantity (expected)]]*Table1[[#This Row],[Rate (expected)2]]*0.9 -> 0 | AD633: =Table1[[#This Row],[Quantity (expected)]]*Table1[[#This Row],[Rate (expected)2]]*0.8 -> 0 | AE633: =Table1[[#This Row],[Quantity (expected)]]*Table1[[#This Row],[Rate (expected)2]]*0.7 -> 0 | AU633: =SUM(Table1[[#This Row],[Jan-23]:[Dec-23]]) -> 0
A634: =VLOOKUP(H634,'Accoount Code Combination'!$D:$L,8,FALSE) -> #N/A | B634: =VLOOKUP(Table1[[#This Row],[Account Code]],'Accoount Code Combination'!$D:$L,9,FALSE) -> #N/A | C634: =VLOOKUP(Table1[[#This Row],[Cost Center Code]],'Cost Center Group'!A:B,2,FALSE) -> #N/A | D634: 847 | G634: 1 | I634: =IFERROR(VLOOKUP(Table1[[#This Row],[Account Code]],'Accoount Code Combination'!$D:$H,2,FALSE),"") | L634: =IFERROR(VLOOKUP(Table1[[#This Row],[Future-1 Description]],'Other '!E622:$F631,2,FALSE),"") | Z634: =Table1[[#This Row],[Quantity of measruing units]]*Table1[[#This Row],[Rate (expected)]] -> 0 | AC634: =Table1[[#This Row],[Quantity (expected)]]*Table1[[#This Row],[Rate (expected)2]]*0.9 -> 0 | AD634: =Table1[[#This Row],[Quantity (expected)]]*Table1[[#This Row],[Rate (expected)2]]*0.8 -> 0 | AE634: =Table1[[#This Row],[Quantity (expected)]]*Table1[[#This Row],[Rate (expected)2]]*0.7 -> 0 | AU634: =SUM(Table1[[#This Row],[Jan-23]:[Dec-23]]) -> 0
P635: =SUM(Table1[2021Actual]) -> 5.2075457e+08 | Q635: =SUM(Table1[2022 Budget]) -> 508729156 | R635: =SUM(Table1[2022 Estimates full year Actual]) -> 0 | Z635: =SUM(Table1[[2023 Budget ]]) -> 500000 | AC635: =SUM(Table1[2023 Budget Scenario 90%]) -> 0 | AD635: =SUM(Table1[2023 Budget Scenario 80%]) -> 0 | AE635: =SUM(Table1[2023 Budget Scenario 70%]) -> 0 | AI635: =SUM(Table1[Jan-23]) -> 0 | AJ635: =SUM(Table1[Feb-23]) -> 0 | AK635: =SUM(Table1[Mar-23]) -> 0 | AL635: =SUM(Table1[Apr-23]) -> 0 | AM635: =SUM(Table1[May-23]) -> 0 | AN635: =SUM(Table1[Jun-23]) -> 0 | AO635: =SUM(Table1[Jul-23]) -> 0 | AP635: =SUM(Table1[Aug-23]) -> 0 | AQ635: =SUM(Table1[Sep-23]) -> 0 | AR635: =SUM(Table1[Oct-23]) -> 0 | AS635: =SUM(Table1[Nov-23]) -> 0 | AT635: =SUM(Table1[Dec-23]) -> 0 | AU635: =SUM(Table1[Total]) -> 0

Sheet xBudget 2024
F1: Cost Center Description : | G1: =IFERROR(VLOOKUP(G2,'Cost Center'!$A:$B,2,FALSE),"")
F2: Cost Center Code : | M2: Return to Main Page
F3: Year | G3: 2024
F4: Drop Box List | M4: Drop Box List | N4: Required | O4: Optional - Drop Box List | P4: Optional | Q4: Required | R4: Required | S4: Required | T4: Required | U4: Required - Drop Box List | V4: Required - Drop Box Lsit | W4: Drop Box List | X4: Drop Box List | Y4: Required
A5: Account Group | B5: Content Expert | C5: Cost Center Code - Group | D5: Cost Center Code | E5: Cost Center Description | F5: Account Code | G5: Account Description | H5: GL Account Combination | I5: Future-1 Description | J5: Future 1 | K5: Future-2 Description | L5: Future-2 | M5: Budget Driver Name - Primary | N5: Budget Driver Qty - Primary | O5: Budget Driver Name - Secondary | P5: Budget Driver Qty - Secondary | Q5: Itemised Details/Calculation method | R5: Quantity (expected) | S5: Rate (expected) | T5: 2023 Budget | U5: Budget Activity Type | V5: Expenditure Frequency | W5: KU Strategy | X5: Department operation Objective | Y5: Contract or Agreement or PO or budgetary Quotation - KU Driver
A6: =IFERROR(VLOOKUP(F6,'Accoount Code Combination'!$D:$L,8,FALSE),"") | B6: =IFERROR(VLOOKUP(Table15[[#This Row],[Account Code]],'Accoount Code Combination'!$D:$L,9,FALSE),"") | C6: =IFERROR(VLOOKUP(Table15[[#This Row],[Cost Center Code]],'Cost Center Group'!A:B,2,FALSE),"") | G6: =IFERROR(VLOOKUP(Table15[[#This Row],[Account Code]],'Accoount Code Combination'!$D:$H,2,FALSE),"") | J6: =IFERROR(VLOOKUP(Table15[[#This Row],[Future-1 Description]],'Other '!$E:$F,2,FALSE),"") | T6: =Table15[[#This Row],[Quantity (expected)]]*Table15[[#This Row],[Rate (expected)]] -> 0
A7: =IFERROR(VLOOKUP(F7,'Accoount Code Combination'!$D:$L,8,FALSE),"") | B7: =IFERROR(VLOOKUP(Table15[[#This Row],[Account Code]],'Accoount Code Combination'!$D:$L,9,FALSE),"") | C7: =IFERROR(VLOOKUP(Table15[[#This Row],[Cost Center Code]],'Cost Center Group'!A:B,2,FALSE),"") | G7: =IFERROR(VLOOKUP(Table15[[#This Row],[Account Code]],'Accoount Code Combination'!$D:$H,2,FALSE),"") | J7: =IFERROR(VLOOKUP(Table15[[#This Row],[Future-1 Description]],'Other '!$E:$F,2,FALSE),"") | T7: =Table15[[#This Row],[Quantity (expected)]]*Table15[[#This Row],[Rate (expected)]] -> 0
A8: =IFERROR(VLOOKUP(F8,'Accoount Code Combination'!$D:$L,8,FALSE),"") | B8: =IFERROR(VLOOKUP(Table15[[#This Row],[Account Code]],'Accoount Code Combination'!$D:$L,9,FALSE),"") | C8: =IFERROR(VLOOKUP(Table15[[#This Row],[Cost Center Code]],'Cost Center Group'!A:B,2,FALSE),"") | G8: =IFERROR(VLOOKUP(Table15[[#This Row],[Account Code]],'Accoount Code Combination'!$D:$H,2,FALSE),"") | J8: =IFERROR(VLOOKUP(Table15[[#This Row],[Future-1 Description]],'Other '!$E:$F,2,FALSE),"") | T8: =Table15[[#This Row],[Quantity (expected)]]*Table15[[#This Row],[Rate (expected)]] -> 0
A9: =IFERROR(VLOOKUP(F9,'Accoount Code Combination'!$D:$L,8,FALSE),"") | B9: =IFERROR(VLOOKUP(Table15[[#This Row],[Account Code]],'Accoount Code Combination'!$D:$L,9,FALSE),"") | C9: =IFERROR(VLOOKUP(Table15[[#This Row],[Cost Center Code]],'Cost Center Group'!A:B,2,FALSE),"") | G9: =IFERROR(VLOOKUP(Table15[[#This Row],[Account Code]],'Accoount Code Combination'!$D:$H,2,FALSE),"") | J9: =IFERROR(VLOOKUP(Table15[[#This Row],[Future-1 Description]],'Other '!$E:$F,2,FALSE),"") | T9: =Table15[[#This Row],[Quantity (expected)]]*Table15[[#This Row],[Rate (expected)]] -> 0
A10: =IFERROR(VLOOKUP(F10,'Accoount Code Combination'!$D:$L,8,FALSE),"") | B10: =IFERROR(VLOOKUP(Table15[[#This Row],[Account Code]],'Accoount Code Combination'!$D:$L,9,FALSE),"") | C10: =IFERROR(VLOOKUP(Table15[[#This Row],[Cost Center Code]],'Cost Center Group'!A:B,2,FALSE),"") | G10: =IFERROR(VLOOKUP(Table15[[#This Row],[Account Code]],'Accoount Code Combination'!$D:$H,2,FALSE),"") | J10: =IFERROR(VLOOKUP(Table15[[#This Row],[Future-1 Description]],'Other '!$E:$F,2,FALSE),"") | T10: =Table15[[#This Row],[Quantity (expected)]]*Table15[[#This Row],[Rate (expected)]] -> 0
A11: =IFERROR(VLOOKUP(F11,'Accoount Code Combination'!$D:$L,8,FALSE),"") | B11: =IFERROR(VLOOKUP(Table15[[#This Row],[Account Code]],'Accoount Code Combination'!$D:$L,9,FALSE),"") | C11: =IFERROR(VLOOKUP(Table15[[#This Row],[Cost Center Code]],'Cost Center Group'!A:B,2,FALSE),"") | G11: =IFERROR(VLOOKUP(Table15[[#This Row],[Account Code]],'Accoount Code Combination'!$D:$H,2,FALSE),"") | J11: =IFERROR(VLOOKUP(Table15[[#This Row],[Future-1 Description]],'Other '!$E:$F,2,FALSE),"") | T11: =Table15[[#This Row],[Quantity (expected)]]*Table15[[#This Row],[Rate (expected)]] -> 0
A12: =IFERROR(VLOOKUP(F12,'Accoount Code Combination'!$D:$L,8,FALSE),"") | B12: =IFERROR(VLOOKUP(Table15[[#This Row],[Account Code]],'Accoount Code Combination'!$D:$L,9,FALSE),"") | C12: =IFERROR(VLOOKUP(Table15[[#This Row],[Cost Center Code]],'Cost Center Group'!A:B,2,FALSE),"") | G12: =IFERROR(VLOOKUP(Table15[[#This Row],[Account Code]],'Accoount Code Combination'!$D:$H,2,FALSE),"") | J12: =IFERROR(VLOOKUP(Table15[[#This Row],[Future-1 Description]],'Other '!$E:$F,2,FALSE),"") | T12: =Table15[[#This Row],[Quantity (expected)]]*Table15[[#This Row],[Rate (expected)]] -> 0
A13: =IFERROR(VLOOKUP(F13,'Accoount Code Combination'!$D:$L,8,FALSE),"") | B13: =IFERROR(VLOOKUP(Table15[[#This Row],[Account Code]],'Accoount Code Combination'!$D:$L,9,FALSE),"") | C13: =IFERROR(VLOOKUP(Table15[[#This Row],[Cost Center Code]],'Cost Center Group'!A:B,2,FALSE),"") | G13: =IFERROR(VLOOKUP(Table15[[#This Row],[Account Code]],'Accoount Code Combination'!$D:$H,2,FALSE),"") | J13: =IFERROR(VLOOKUP(Table15[[#This Row],[Future-1 Description]],'Other '!$E:$F,2,FALSE),"") | T13: =Table15[[#This Row],[Quantity (expected)]]*Table15[[#This Row],[Rate (expected)]] -> 0
A14: =IFERROR(VLOOKUP(F14,'Accoount Code Combination'!$D:$L,8,FALSE),"") | B14: =IFERROR(VLOOKUP(Table15[[#This Row],[Account Code]],'Accoount Code Combination'!$D:$L,9,FALSE),"") | C14: =IFERROR(VLOOKUP(Table15[[#This Row],[Cost Center Code]],'Cost Center Group'!A:B,2,FALSE),"") | G14: =IFERROR(VLOOKUP(Table15[[#This Row],[Account Code]],'Accoount Code Combination'!$D:$H,2,FALSE),"") | J14: =IFERROR(VLOOKUP(Table15[[#This Row],[Future-1 Description]],'Other '!$E:$F,2,FALSE),"") | T14: =Table15[[#This Row],[Quantity (expected)]]*Table15[[#This Row],[Rate (expected)]] -> 0
A15: =IFERROR(VLOOKUP(F15,'Accoount Code Combination'!$D:$L,8,FALSE),"") | B15: =IFERROR(VLOOKUP(Table15[[#This Row],[Account Code]],'Accoount Code Combination'!$D:$L,9,FALSE),"") | C15: =IFERROR(VLOOKUP(Table15[[#This Row],[Cost Center Code]],'Cost Center Group'!A:B,2,FALSE),"") | G15: =IFERROR(VLOOKUP(Table15[[#This Row],[Account Code]],'Accoount Code Combination'!$D:$H,2,FALSE),"") | J15: =IFERROR(VLOOKUP(Table15[[#This Row],[Future-1 Description]],'Other '!$E:$F,2,FALSE),"") | T15: =Table15[[#This Row],[Quantity (expected)]]*Table15[[#This Row],[Rate (expected)]] -> 0
A16: =IFERROR(VLOOKUP(F16,'Accoount Code Combination'!$D:$L,8,FALSE),"") | B16: =IFERROR(VLOOKUP(Table15[[#This Row],[Account Code]],'Accoount Code Combination'!$D:$L,9,FALSE),"") | C16: =IFERROR(VLOOKUP(Table15[[#This Row],[Cost Center Code]],'Cost Center Group'!A:B,2,FALSE),"") | G16: =IFERROR(VLOOKUP(Table15[[#This Row],[Account Code]],'Accoount Code Combination'!$D:$H,2,FALSE),"") | J16: =IFERROR(VLOOKUP(Table15[[#This Row],[Future-1 Description]],'Other '!$E:$F,2,FALSE),"") | T16: =Table15[[#This Row],[Quantity (expected)]]*Table15[[#This Row],[Rate (expected)]] -> 0
A17: =IFERROR(VLOOKUP(F17,'Accoount Code Combination'!$D:$L,8,FALSE),"") | B17: =IFERROR(VLOOKUP(Table15[[#This Row],[Account Code]],'Accoount Code Combination'!$D:$L,9,FALSE),"") | C17: =IFERROR(VLOOKUP(Table15[[#This Row],[Cost Center Code]],'Cost Center Group'!A:B,2,FALSE),"") | G17: =IFERROR(VLOOKUP(Table15[[#This Row],[Account Code]],'Accoount Code Combination'!$D:$H,2,FALSE),"") | J17: =IFERROR(VLOOKUP(Table15[[#This Row],[Future-1 Description]],'Other '!$E:$F,2,FALSE),"") | T17: =Table15[[#This Row],[Quantity (expected)]]*Table15[[#This Row],[Rate (expected)]] -> 0
... A30: =IFERROR(VLOOKUP(F30,'Accoount Code Combination'!$D:$L,8,FALSE),"") | B30: =IFERROR(VLOOKUP(Table15[[#This Row],[Account Code]],'Accoount Code Combination'!$D:$L,9,FALSE),"") | C30: =IFERROR(VLOOKUP(Table15[[#This Row],[Cost Center Code]],'Cost Center Group'!A:B,2,FALSE),"") | G30: =IFERROR(VLOOKUP(Table15[[#This Row],[Account Code]],'Accoount Code Combination'!$D:$H,2,FALSE),"") | J30: =IFERROR(VLOOKUP(Table15[[#This Row],[Future-1 Description]],'Other '!$E:$F,2,FALSE),"") | T30: =Table15[[#This Row],[Quantity (expected)]]*Table15[[#This Row],[Rate (expected)]] -> 0
T31: =SUM(Table15[[2023 Budget ]]) -> 0

Sheet xBudget 2025
F1: Cost Center Description : | G1: =IFERROR(VLOOKUP(G2,'Cost Center'!$A:$B,2,FALSE),"")
F2: Cost Center Code : | M2: Return to Main Page
F3: Year | G3: 2025
F4: Drop Box List | M4: Drop Box List | N4: Required | O4: Optional - Drop Box | P4: Optional | Q4: Required | R4: Required | S4: Required | T4: Required | U4: Required - Drop Box | V4: Required - Drop Box | W4: Drop Box List | X4: Drop Box List | Y4: Required
A5: Account Group | B5: Content Expert | C5: Cost Center Code - Group | D5: Cost Center Code | E5: Cost Center Description | F5: Account Code | G5: Account Description | H5: GL Account Combination | I5: Future-1 Description | J5: Future 1 | K5: Future-2 Description | L5: Future-2 | M5: Budget Driver Name - Primary | N5: Budget Driver Qty - Primary | O5: Budget Driver Name - Secondary | P5: Budget Driver Qty - Secondary | Q5: Itemised Details/Calculation method | R5: Quantity (expected) | S5: Rate (expected) | T5: 2024 Budget | U5: Budget Activity Type | V5: Expenditure Frequency | W5: KU Strategy | X5: Department operation Objective | Y5: Contract or Agreement or PO or budgetary Quotation - KU Driver
A6: =IFERROR(VLOOKUP(F6,'Accoount Code Combination'!$D:$L,8,FALSE),"") | B6: =IFERROR(VLOOKUP(Table156[[#This Row],[Account Code]],'Accoount Code Combination'!$D:$L,9,FALSE),"") | C6: =IFERROR(VLOOKUP(Table156[[#This Row],[Cost Center Code]],'Cost Center Group'!A:B,2,FALSE),"") | G6: =IFERROR(VLOOKUP(Table156[[#This Row],[Account Code]],'Accoount Code Combination'!$D:$H,2,FALSE),"") | J6: =IFERROR(VLOOKUP(Table156[[#This Row],[Future-1 Description]],'Other '!$E:$F,2,FALSE),"") | T6: =Table156[[#This Row],[Quantity (expected)]]*Table156[[#This Row],[Rate (expected)]] -> 0
A7: =IFERROR(VLOOKUP(F7,'Accoount Code Combination'!$D:$L,8,FALSE),"") | B7: =IFERROR(VLOOKUP(Table156[[#This Row],[Account Code]],'Accoount Code Combination'!$D:$L,9,FALSE),"") | C7: =IFERROR(VLOOKUP(Table156[[#This Row],[Cost Center Code]],'Cost Center Group'!A:B,2,FALSE),"") | G7: =IFERROR(VLOOKUP(Table156[[#This Row],[Account Code]],'Accoount Code Combination'!$D:$H,2,FALSE),"") | J7: =IFERROR(VLOOKUP(Table156[[#This Row],[Future-1 Description]],'Other '!$E:$F,2,FALSE),"") | T7: =Table156[[#This Row],[Quantity (expected)]]*Table156[[#This Row],[Rate (expected)]] -> 0
A8: =IFERROR(VLOOKUP(F8,'Accoount Code Combination'!$D:$L,8,FALSE),"") | B8: =IFERROR(VLOOKUP(Table156[[#This Row],[Account Code]],'Accoount Code Combination'!$D:$L,9,FALSE),"") | C8: =IFERROR(VLOOKUP(Table156[[#This Row],[Cost Center Code]],'Cost Center Group'!A:B,2,FALSE),"") | G8: =IFERROR(VLOOKUP(Table156[[#This Row],[Account Code]],'Accoount Code Combination'!$D:$H,2,FALSE),"") | J8: =IFERROR(VLOOKUP(Table156[[#This Row],[Future-1 Description]],'Other '!$E:$F,2,FALSE),"") | T8: =Table156[[#This Row],[Quantity (expected)]]*Table156[[#This Row],[Rate (expected)]] -> 0
A9: =IFERROR(VLOOKUP(F9,'Accoount Code Combination'!$D:$L,8,FALSE),"") | B9: =IFERROR(VLOOKUP(Table156[[#This Row],[Account Code]],'Accoount Code Combination'!$D:$L,9,FALSE),"") | C9: =IFERROR(VLOOKUP(Table156[[#This Row],[Cost Center Code]],'Cost Center Group'!A:B,2,FALSE),"") | G9: =IFERROR(VLOOKUP(Table156[[#This Row],[Account Code]],'Accoount Code Combination'!$D:$H,2,FALSE),"") | J9: =IFERROR(VLOOKUP(Table156[[#This Row],[Future-1 Description]],'Other '!$E:$F,2,FALSE),"") | T9: =Table156[[#This Row],[Quantity (expected)]]*Table156[[#This Row],[Rate (expected)]] -> 0
A10: =IFERROR(VLOOKUP(F10,'Accoount Code Combination'!$D:$L,8,FALSE),"") | B10: =IFERROR(VLOOKUP(Table156[[#This Row],[Account Code]],'Accoount Code Combination'!$D:$L,9,FALSE),"") | C10: =IFERROR(VLOOKUP(Table156[[#This Row],[Cost Center Code]],'Cost Center Group'!A:B,2,FALSE),"") | G10: =IFERROR(VLOOKUP(Table156[[#This Row],[Account Code]],'Accoount Code Combination'!$D:$H,2,FALSE),"") | J10: =IFERROR(VLOOKUP(Table156[[#This Row],[Future-1 Description]],'Other '!$E:$F,2,FALSE),"") | T10: =Table156[[#This Row],[Quantity (expected)]]*Table156[[#This Row],[Rate (expected)]] -> 0
A11: =IFERROR(VLOOKUP(F11,'Accoount Code Combination'!$D:$L,8,FALSE),"") | B11: =IFERROR(VLOOKUP(Table156[[#This Row],[Account Code]],'Accoount Code Combination'!$D:$L,9,FALSE),"") | C11: =IFERROR(VLOOKUP(Table156[[#This Row],[Cost Center Code]],'Cost Center Group'!A:B,2,FALSE),"") | G11: =IFERROR(VLOOKUP(Table156[[#This Row],[Account Code]],'Accoount Code Combination'!$D:$H,2,FALSE),"") | J11: =IFERROR(VLOOKUP(Table156[[#This Row],[Future-1 Description]],'Other '!$E:$F,2,FALSE),"") | T11: =Table156[[#This Row],[Quantity (expected)]]*Table156[[#This Row],[Rate (expected)]] -> 0
A12: =IFERROR(VLOOKUP(F12,'Accoount Code Combination'!$D:$L,8,FALSE),"") | B12: =IFERROR(VLOOKUP(Table156[[#This Row],[Account Code]],'Accoount Code Combination'!$D:$L,9,FALSE),"") | C12: =IFERROR(VLOOKUP(Table156[[#This Row],[Cost Center Code]],'Cost Center Group'!A:B,2,FALSE),"") | G12: =IFERROR(VLOOKUP(Table156[[#This Row],[Account Code]],'Accoount Code Combination'!$D:$H,2,FALSE),"") | J12: =IFERROR(VLOOKUP(Table156[[#This Row],[Future-1 Description]],'Other '!$E:$F,2,FALSE),"") | T12: =Table156[[#This Row],[Quantity (expected)]]*Table156[[#This Row],[Rate (expected)]] -> 0
A13: =IFERROR(VLOOKUP(F13,'Accoount Code Combination'!$D:$L,8,FALSE),"") | B13: =IFERROR(VLOOKUP(Table156[[#This Row],[Account Code]],'Accoount Code Combination'!$D:$L,9,FALSE),"") | C13: =IFERROR(VLOOKUP(Table156[[#This Row],[Cost Center Code]],'Cost Center Group'!A:B,2,FALSE),"") | G13: =IFERROR(VLOOKUP(Table156[[#This Row],[Account Code]],'Accoount Code Combination'!$D:$H,2,FALSE),"") | J13: =IFERROR(VLOOKUP(Table156[[#This Row],[Future-1 Description]],'Other '!$E:$F,2,FALSE),"") | T13: =Table156[[#This Row],[Quantity (expected)]]*Table156[[#This Row],[Rate (expected)]] -> 0
A14: =IFERROR(VLOOKUP(F14,'Accoount Code Combination'!$D:$L,8,FALSE),"") | B14: =IFERROR(VLOOKUP(Table156[[#This Row],[Account Code]],'Accoount Code Combination'!$D:$L,9,FALSE),"") | C14: =IFERROR(VLOOKUP(Table156[[#This Row],[Cost Center Code]],'Cost Center Group'!A:B,2,FALSE),"") | G14: =IFERROR(VLOOKUP(Table156[[#This Row],[Account Code]],'Accoount Code Combination'!$D:$H,2,FALSE),"") | J14: =IFERROR(VLOOKUP(Table156[[#This Row],[Future-1 Description]],'Other '!$E:$F,2,FALSE),"") | T14: =Table156[[#This Row],[Quantity (expected)]]*Table156[[#This Row],[Rate (expected)]] -> 0
A15: =IFERROR(VLOOKUP(F15,'Accoount Code Combination'!$D:$L,8,FALSE),"") | B15: =IFERROR(VLOOKUP(Table156[[#This Row],[Account Code]],'Accoount Code Combination'!$D:$L,9,FALSE),"") | C15: =IFERROR(VLOOKUP(Table156[[#This Row],[Cost Center Code]],'Cost Center Group'!A:B,2,FALSE),"") | G15: =IFERROR(VLOOKUP(Table156[[#This Row],[Account Code]],'Accoount Code Combination'!$D:$H,2,FALSE),"") | J15: =IFERROR(VLOOKUP(Table156[[#This Row],[Future-1 Description]],'Other '!$E:$F,2,FALSE),"") | T15: =Table156[[#This Row],[Quantity (expected)]]*Table156[[#This Row],[Rate (expected)]] -> 0
A16: =IFERROR(VLOOKUP(F16,'Accoount Code Combination'!$D:$L,8,FALSE),"") | B16: =IFERROR(VLOOKUP(Table156[[#This Row],[Account Code]],'Accoount Code Combination'!$D:$L,9,FALSE),"") | C16: =IFERROR(VLOOKUP(Table156[[#This Row],[Cost Center Code]],'Cost Center Group'!A:B,2,FALSE),"") | G16: =IFERROR(VLOOKUP(Table156[[#This Row],[Account Code]],'Accoount Code Combination'!$D:$H,2,FALSE),"") | J16: =IFERROR(VLOOKUP(Table156[[#This Row],[Future-1 Description]],'Other '!$E:$F,2,FALSE),"") | T16: =Table156[[#This Row],[Quantity (expected)]]*Table156[[#This Row],[Rate (expected)]] -> 0
A17: =IFERROR(VLOOKUP(F17,'Accoount Code Combination'!$D:$L,8,FALSE),"") | B17: =IFERROR(VLOOKUP(Table156[[#This Row],[Account Code]],'Accoount Code Combination'!$D:$L,9,FALSE),"") | C17: =IFERROR(VLOOKUP(Table156[[#This Row],[Cost Center Code]],'Cost Center Group'!A:B,2,FALSE),"") | G17: =IFERROR(VLOOKUP(Table156[[#This Row],[Account Code]],'Accoount Code Combination'!$D:$H,2,FALSE),"") | J17: =IFERROR(VLOOKUP(Table156[[#This Row],[Future-1 Description]],'Other '!$E:$F,2,FALSE),"") | T17: =Table156[[#This Row],[Quantity (expected)]]*Table156[[#This Row],[Rate (expected)]] -> 0
... A38: =IFERROR(VLOOKUP(F38,'Accoount Code Combination'!$D:$L,8,FALSE),"") | B38: =IFERROR(VLOOKUP(Table156[[#This Row],[Account Code]],'Accoount Code Combination'!$D:$L,9,FALSE),"") | C38: =IFERROR(VLOOKUP(Table156[[#This Row],[Cost Center Code]],'Cost Center Group'!A:B,2,FALSE),"") | G38: =IFERROR(VLOOKUP(Table156[[#This Row],[Account Code]],'Accoount Code Combination'!$D:$H,2,FALSE),"") | J38: =IFERROR(VLOOKUP(Table156[[#This Row],[Future-1 Description]],'Other '!$E:$F,2,FALSE),"") | T38: =Table156[[#This Row],[Quantity (expected)]]*Table156[[#This Row],[Rate (expected)]] -> 0
T39: =SUM(Table156[[2024 Budget ]]) -> 0

Sheet Check List
B1: Return to Main Page
A3: Number | B3: Budget Compliance Description | C3: Feedback | D3: Date
A4: 1 | B4: Budget template received
A5: 2 | B5: Budget first submission
A6: 3 | B6: Budget Latest submission
A7: 4 | B7: Supporting Documents for each budget line upload in KU shared drive | E7: Insert the linked
A8: 5 | B8: Budget Itemized all lines entered
A9: 6 | B9: Entered full year Actual Expenditures for 2022
A10: 7 | B10: Entered budget scenarios impact for the 90% , 80% & 70%
A11: 8 | B11: Entered Itemized budget monthly Cash Flow for year 2023
A12: 9 | B12: Content expert’s confirmation | E12: Removed
A13: 10 | B13: IT – ADDA Template fill up and send to IT
A14: 11 | B14: FMS
A15: 12 | B15: Strategic Project | E15: Yes/No
A16: 13 | B16: Selected relevant budget driver/s
A17: 14 | B17: Entered KU Strategy linked with the budget objective
A18: 15 | B18: Enetred budget for the years 2024 - 2025

Sheet Drivers
A1: Return to Main Page
A3: Account | B3: Account Description | C3: Cost drivers (Measrable) | D3: Measruing unit | E3: Quantity of measruing units
A4: 425100 | B4: Advertising Services (General) | C4: Radio advertising cost | D4: Second
A5: 425100 | B5: Advertising Services (General) | C5: TV advertising cost | D5: Second
A6: 425100 | B6: Advertising Services (General) | C6: Advertising through newspapers and other print media | D6: cm2 - Word
A7: 425100 | B7: Advertising Services (General) | C7: Digital Marketing Campaigns | D7: count
A8: 425100 | B8: Advertising Services (General) | C8: Website Maintenance | D8: count
A9: 425100 | B9: Advertising Services (General) | C9: Animation Videos | D9: count
A10: 425100 | B10: Advertising Services (General) | C10: Search Engine Optimization (SEO) | D10: count
A11: 425100 | B11: Advertising Services (General) | C11: Video production | D11: second
A12: 425100 | B12: Advertising Services (General) | C12: Corporate Photoshoot | D12: count
A13: 425100 | B13: Advertising Services (General) | C13: International Publicity | D13: count
A14: 425100 | B14: Advertising Services (General) | C14: Branding | D14: count
A15: 425100 | B15: Advertising Services (General) | C15: Digital advertizing (Radio, TV, Social Media) | D15: count
A16: 425100 | B16: Advertising Services (General) | C16: The cost of advertising on billboards and malls | D16: cm2

Sheet Accoount Code Combination
A1: Cost Center Grouping | B1: Cost Center Code | C1: Cost Center Description | D1: Account Code | E1: Account Description | F1: Future1 | G1: Future1 Description | H1: Future2 Description | I1: Future2 | J1: GL Account Combination | K1: Account Group | L1: Content Expert
A2: President's Office | B2: 8470120 | C2: KUST - Audit & Compliance | D2: 420120 | E2: Internal Audit service | F2: 847001 | G2: KUST - General | H2: FA179-Opex Expense | I2: 200179 | J2: 847.8470120.1.420120.000000.847001.200179 | K2: Other support | L2: No Applicable
A3: President's Office | B3: 8470120 | C3: KUST - Audit & Compliance | D3: 420120 | E3: Internal Audit service | F3: 847001 | G3: KUST - General | H3: Un Specified | I3: 000000 | J3: 847.8470120.1.420120.000000.847001.000000 | K3: Other support | L3: No Applicable
A4: Finance & Business Development Office | B4: 8470620 | C4: KUST - Finance Operations | D4: 420130 | E4: External Audit service | F4: 847001 | G4: KUST - General | H4: FA179-Opex Expense | I4: 200179 | J4: 847.8470620.1.420130.000000.847001.200179 | K4: Other support | L4: No Applicable
A5: Finance & Business Development Office | B5: 8470620 | C5: KUST - Finance Operations | D5: 420130 | E5: External Audit service | F5: 847001 | G5: KUST - General | H5: Un Specified | I5: 000000 | J5: 847.8470620.1.420130.000000.847001.000000 | K5: Other support | L5: No Applicable
A6: Administration, Facilities and EHS Office | B6: 8470530 | C6: KUST - Facilities Management | D6: 420310 | E6: Cleaning: Business premises | F6: 847010 | G6: KUST - Main Campus | H6: FA179-Opex Expense | I6: 200179 | J6: 847.8470530.1.420310.000000.847010.200179 | K6: Facilities | L6: No Applicable
A7: Administration, Facilities and EHS Office | B7: 8470530 | C7: KUST - Facilities Management | D7: 420310 | E7: Cleaning: Business premises | F7: 847010 | G7: KUST - Main Campus | H7: Un Specified | I7: 000000 | J7: 847.8470530.1.420310.000000.847010.000000 | K7: Facilities | L7: No Applicable
A8: Administration, Facilities and EHS Office | B8: 8470530 | C8: KUST - Facilities Management | D8: 420310 | E8: Cleaning: Business premises | F8: 847020 | G8: KUST- Sas Al Nakhl Campus | H8: FA179-Opex Expense | I8: 200179 | J8: 847.8470530.1.420310.000000.847020.200179 | K8: Facilities | L8: No Applicable
A9: Administration, Facilities and EHS Office | B9: 8470530 | C9: KUST - Facilities Management | D9: 420310 | E9: Cleaning: Business premises | F9: 847020 | G9: KUST- Sas Al Nakhl Campus | H9: Un Specified | I9: 000000 | J9: 847.8470530.1.420310.000000.847020.000000 | K9: Facilities | L9: No Applicable
A10: Administration, Facilities and EHS Office | B10: 8470530 | C10: KUST - Facilities Management | D10: 420310 | E10: Cleaning: Business premises | F10: 847030 | G10: KUST- Masdar city campus | H10: FA179-Opex Expense | I10: 200179 | J10: 847.8470530.1.420310.000000.847030.200179 | K10: Facilities | L10: No Applicable
A11: Administration, Facilities and EHS Office | B11: 8470530 | C11: KUST - Facilities Management | D11: 420310 | E11: Cleaning: Business premises | F11: 847030 | G11: KUST- Masdar city campus | H11: Un Specified | I11: 000000 | J11: 847.8470530.1.420310.000000.847030.000000 | K11: Facilities | L11: No Applicable
A12: Academic and Student Services Office | B12: 8471210 | C12: KUST - SVP/ Academic & Student Services Office | D12: 420310 | E12: Cleaning: Business premises | F12: 847001 | G12: KUST - General | H12: Un Specified | I12: 000000 | J12: 847.8471210.1.420310.000000.847001.000000 | K12: Facilities | L12: No Applicable
A13: Academic and Student Services Office | B13: 8471260 | C13: KUST - Student Life | D13: 420310 | E13: Cleaning: Business premises | F13: 847001 | G13: KUST - General | H13: FA179-Opex Expense | I13: 200179 | J13: 847.8471260.1.420310.000000.847001.200179 | K13: Facilities | L13: No Applicable
... A97: Senior Vice President, Research Office | B97: 8471160 | C97: KUST - Research Laboratories | D97: 422100 | E97: Waste management service | F97: 847001 | G97: KUST - General | H97: Un Specified | I97: 000000 | J97: 847.8471160.1.422100.000000.847001.000000 | K97: Facilities | L97: No Applicable
A98: College of Medicine & Health Sciences | B98: 8471305 | C98: KUST - Dean Of Medicine | D98: 422900 | E98: Other specialised professional services, not mentioned elsewhere | F98: 847001 | G98: KUST - General | H98: FA179-Opex Expense | I98: 200179 | J98: 847.8471305.1.422900.000000.847001.200179 | K98: 0 | L98: No Applicable
A99: President's Office | B99: 8470130 | C99: KUST - Institutional Research & Planning | D99: 425100 | E99: Advertising | F99: 847001 | G99: KUST - General | H99: FA179-Opex Expense | I99: 200179 | J99: 847.8470130.1.425100.000000.847001.200179 | K99: Communiction & Marketing | L99: Advertising
A100: President's Office | B100: 8470140 | C100: KUST - Communication | D100: 425100 | E100: Advertising | F100: 847001 | G100: KUST - General | H100: FA179-Opex Expense | I100: 200179 | J100: 847.8470140.1.425100.000000.847001.200179 | K100: Communiction & Marketing | L100: Advertising
A101: President's Office | B101: 8470140 | C101: KUST - Communication | D101: 425100 | E101: Advertising | F101: 847001 | G101: KUST - General | H101: Un Specified | I101: 000000 | J101: 847.8470140.1.425100.000000.847001.000000 | K101: Communiction & Marketing | L101: Advertising
A102: Graduate Studies | B102: 8470230 | C102: KUST - Graduate Studies | D102: 425100 | E102: Advertising | F102: 847001 | G102: KUST - General | H102: FA179-Opex Expense | I102: 200179 | J102: 847.8470230.1.425100.000000.847001.200179 | K102: Communiction & Marketing | L102: Advertising
A103: College of Arts & Science | B103: 8470405 | C103: KUST - Dean Of Arts & Science | D103: 425100 | E103: Advertising | F103: 847001 | G103: KUST - General | H103: FA179-Opex Expense | I103: 200179 | J103: 847.8470405.1.425100.000000.847001.200179 | K103: Communiction & Marketing | L103: Advertising
A104: College of Arts & Science | B104: 8470405 | C104: KUST - Dean Of Arts & Science | D104: 425100 | E104: Advertising | F104: 847001 | G104: KUST - General | H104: Un Specified | I104: 000000 | J104: 847.8470405.1.425100.000000.847001.000000 | K104: Communiction & Marketing | L104: Advertising
A105: HR & Procurement Office | B105: 8470730 | C105: KUST - Human Resources | D105: 425100 | E105: Advertising | F105: 847001 | G105: KUST - General | H105: Un Specified | I105: 000000 | J105: 847.8470730.1.425100.000000.847001.000000 | K105: Communiction & Marketing | L105: Advertising
A106: College of Medicine & Health Sciences | B106: 8471305 | C106: KUST - Dean Of Medicine | D106: 425100 | E106: Advertising | F106: 847001 | G106: KUST - General | H106: FA179-Opex Expense | I106: 200179 | J106: 847.8471305.1.425100.000000.847001.200179 | K106: Communiction & Marketing | L106: Advertising
A107: Finance & Business Development Office | B107: 8470620 | C107: KUST - Finance Operations | D107: 425300 | E107: Banking service charges / Fees | F107: 847001 | G107: KUST - General | H107: FA179-Opex Expense | I107: 200179 | J107: 847.8470620.1.425300.000000.847001.200179 | K107: Finance | L107: No Applicable
A108: Finance & Business Development Office | B108: 8470620 | C108: KUST - Finance Operations | D108: 425300 | E108: Banking service charges / Fees | F108: 847001 | G108: KUST - General | H108: Un Specified | I108: 000000 | J108: 847.8470620.1.425300.000000.847001.000000 | K108: Finance | L108: No Applicable
A109: Finance & Business Development Office | B109: 8470620 | C109: KUST - Finance Operations | D109: 425350 | E109: Fees for processing e-payments | F109: 847001 | G109: KUST - General | H109: FA179-Opex Expense | I109: 200179 | J109: 847.8470620.1.425350.000000.847001.200179 | K109: Finance | L109: No Applicable
A110: Finance & Business Development Office | B110: 8470620 | C110: KUST - Finance Operations | D110: 425350 | E110: Fees for processing e-payments | F110: 847001 | G110: KUST - General | H110: Un Specified | I110: 000000 | J110: 847.8470620.1.425350.000000.847001.000000 | K110: Finance | L110: No Applicable
... A132: College of Arts & Science | B132: 8470405 | C132: KUST - Dean Of Arts & Science | D132: 425510 | E132: Conferences, seminars and exhibitions and other events: - Local Events | F132: 847001 | G132: KUST - General | H132: Un Specified | I132: 000000 | J132: 847.8470405.1.425510.000000.847001.000000 | K132: Communiction & Marketing | L132: Events
A133: #N/A | B133: 8470420 | C133: KUST - Computer Science | D133: 425510 | E133: Conferences, seminars and exhibitions and other events: - Local Events | F133: 847001 | G133: KUST - General | H133: FA179-Opex Expense | I133: 200179 | J133: 847.8470420.1.425510.000000.847001.200179 | K133: Communiction & Marketing | L133: Events
A134: #N/A | B134: 8470420 | C134: KUST - Computer Science | D134: 425510 | E134: Conferences, seminars and exhibitions and other events: - Local Events | F134: 847001 | G134: KUST - General | H134: Un Specified | I134: 000000 | J134: 847.8470420.1.425510.000000.847001.000000 | K134: Communiction & Marketing | L134: Events
A135: Administration, Facilities and EHS Office | B135: 8470520 | C135: KUST - Environment, Health & Safety | D135: 425510 | E135: Conferences, seminars and exhibitions and other events: - Local Events | F135: 847001 | G135: KUST - General | H135: FA179-Opex Expense | I135: 200179 | J135: 847.8470520.1.425510.000000.847001.200179 | K135: Communiction & Marketing | L135: Events
A136: Administration, Facilities and EHS Office | B136: 8470520 | C136: KUST - Environment, Health & Safety | D136: 425510 | E136: Conferences, seminars and exhibitions and other events: - Local Events | F136: 847001 | G136: KUST - General | H136: Un Specified | I136: 000000 | J136: 847.8470520.1.425510.000000.847001.000000 | K136: Communiction & Marketing | L136: Events
A137: Administration, Facilities and EHS Office | B137: 8470520 | C137: KUST - Environment, Health & Safety | D137: 425510 | E137: Conferences, seminars and exhibitions and other events: - Local Events | F137: 847951 | G137: COVID-19 Pandemic | H137: FA179-Opex Expense | I137: 200179 | J137: 847.8470520.1.425510.000000.847951.200179 | K137: Communiction & Marketing | L137: Events
