Workbook

Sheet Sheet5
A1: Future2 Description | B1: FA180-Capex Expense
A3: Row Labels | B3: 2021 Revised Budget | C3: 2021 Actual Amount | D3: 2021 PR | E3: 2021 PO | F3: 2020 Revis.ed Budget | G3: 2020 Actual Amount
A4: KUST - Aerospace Engineering | B4: 759151 | C4: 4619 | D4: 637243.48 | E4: 98213 | F4: 434000 | G4: 433999
A5: KUST - Ankabut office | B5: 4272296 | C5: -379409 | D5: 3948857 | E5: 94598 | F5: 5949149 | G5: 5927842.4
A6: KUST - Biomedical Engineering | B6: 109201 | D6: 0 | E6: 108878.38 | F6: 187000 | G6: 187000
A7: KUST - Center for Teaching & Learning | F7: 0 | G7: 0
A8: KUST - Chemical Engineering | F8: 0 | G8: 0
A9: KUST - Chemistry | B9: 781895 | C9: 13000 | D9: 760900 | E9: 0 | F9: 0 | G9: 0
A10: KUST - Civil Engineering | B10: 224144 | C10: 125060 | D10: 46550 | E10: 39743 | F10: 1585072 | G10: 1525688
A11: KUST - Communication | B11: 200000 | C11: 192455 | D11: 0 | E11: 0 | F11: 0 | G11: 0
A12: KUST - Dean Of Arts & Science
A13: KUST - Dean Of Engineering | F13: 2550 | G13: 2550.19
A14: KUST - Dean Of Medicine | B14: 27422265 | C14: 4474163.7 | D14: 3427896 | E14: 9410471.6 | F14: 19467391 | G14: 17595457
A15: KUST - Department of English | F15: 0 | G15: 0
A16: KUST - Earth Science | F16: 0 | G16: 0
A17: KUST - Electrical & Computer Engineering | B17: 233948 | D17: 232000 | F17: 585250 | G17: 585058.63
A18: KUST - Environment, Health & Safety | F18: 502000 | G18: 501601.43
A19: KUST - Executive Vice President Office | F19: 0 | G19: 0
A20: KUST - Facilities Management | B20: 25061676 | C20: 2067526.2 | D20: 22185794 | E20: 652506 | F20: 34240670 | G20: 34247975
A21: KUST - Finance Operations
A22: KUST - Graduate Studies
A23: KUST - Human Resources | B23: 110494 | C23: 18149.5 | D23: 0 | E23: 0 | F23: 29334 | G23: 29334.5
A24: KUST - Humanities & Social Sciences
A25: KUST - Industrial & Systems Engineering | B25: 80120 | D25: 49000 | F25: 283271 | G25: 283271
A26: KUST - Libraries
A27: KUST - Mathematics
A28: KUST - Mechanical Engineering | B28: 269248 | D28: 193435 | E28: 69443 | F28: 829817 | G28: 822867.91
A29: KUST - Nuclear Engineering | B29: 139983 | D29: 62441 | E29: 77504.46 | F29: 86000 | G29: 0
A30: KUST - Office of the President | F30: 2981521 | G30: 39940.11
A31: KUST - Office of the Provost | B31: 160720 | C31: 10720 | E31: 150000 | F31: 1641944 | G31: 1481224
A32: KUST - Petroleum Engineering | B32: 772173 | D32: 763616.7 | F32: 585128 | G32: 584893
A33: KUST - Physics | B33: 2912920 | C33: 26928 | D33: 1990500 | E33: 868629.7 | F33: 0 | G33: 0
A34: KUST - Preparatory Program | F34: 0 | G34: 0
A35: KUST - Research Computing | B35: 6795858 | C35: 9510 | D35: 6628812.2 | E35: 0 | F35: 5546000 | G35: 5545455
A36: KUST - Research Laboratories | B36: 15882373 | C36: 402222.34 | D36: 14314209 | E36: 764750.27 | F36: 10813606 | G36: 9475691.4
A37: KUST - Research Service | B37: 0 | F37: 3338153 | G37: 3312663.8
A38: KUST - Student Enrollment
A39: KUST - Student Life | F39: 1964000 | G39: 1963930
A40: KUST - SVP/ Academic & Student Services Office
A41: KUST - SVP/ Research & Development Office | F41: 2998678 | G41: 0
...

Sheet Pivot CH1 & Ch2 & Ch3
N2: TO DOF
A3: Future2 Description | B3: Cost Center Code - Group | C3: 2018 Actual | D3: 2019 Actual | E3: 2020 Actual | F3: 2021 R. Budget | G3: 2021 Actual | H3: 2021 PR | I3: 2021 PO | J3: 2022 Budget | K3: 2022 Budget Scenario 90% | L3: 2022 Budget Scenario 80% | M3: 2022 Budget Scenario 70% | N3: 2022 Budget Finance Recommendation | O3: 2023 Budget | P3: 2023 Budget Finance Recommendation | Q3: 2024 Budget | R3: 2024 Budget Finance Recommendation
A4: FA178-Manpower Expense | B4: Manpower | C4: 666857437 | D4: 734104574 | E4: 541385100 | F4: 583465683 | G4: 3.1287481e+08 | H4: 577263.62 | I4: 120262.4 | J4: 624050000 | K4: 561645000 | L4: 499240000 | M4: 436835000 | N4: 614050000 | O4: 624050000 | P4: 624050000 | Q4: 624050000 | R4: 624050000 | S4: =GETPIVOTDATA(" 2022 Budget Finance Recommendation",$A$3,"Cost Center Code - Group","Manpower","Future2 Description","FA178-Manpower Expense")/GETPIVOTDATA(" 2021 R. Budget",$A$3,"Cost Center Code - Group","Manpower","Future2 Description","FA178-Manpower Expense") -> 1.0524184 | T4: =GETPIVOTDATA(" 2022 Budget Finance Recommendation",$A$3,"Cost Center Code - Group","Manpower","Future2 Description","FA178-Manpower Expense")-GETPIVOTDATA(" 2021 R. Budget",$A$3,"Cost Center Code - Group","Manpower","Future2 Description","FA178-Manpower Expense") -> 30584317
A5: FA179-Opex Expense | C5: 4.1157745e+08 | D5: 4.5345466e+08 | E5: 4.3620813e+08 | F5: 398910380 | G5: 1.2931363e+08 | H5: 53383699 | I5: 31493207 | J5: 7.9647721e+08 | K5: 7.0897699e+08 | L5: 6.3020177e+08 | M5: 5.5142654e+08 | N5: 6.708027e+08 | O5: 8.7845816e+08 | P5: 7.3663227e+08 | Q5: 9.1822665e+08 | R5: 8.0277819e+08 | S5: =GETPIVOTDATA(" 2022 Budget Finance Recommendation",$A$3,"Future2 Description","FA179-Opex Expense")/GETPIVOTDATA(" 2021 R. Budget",$A$3,"Future2 Description","FA179-Opex Expense") -> 1.6815875 | T5: =GETPIVOTDATA(" 2022 Budget Finance Recommendation",$A$3,"Future2 Description","FA179-Opex Expense")-GETPIVOTDATA(" 2021 R. Budget",$A$3,"Future2 Description","FA179-Opex Expense") -> 2.7189232e+08
A6: FA180-Capex Expense | C6: 50440080 | D6: 1.5695179e+08 | E6: 84546442 | F6: 87794769 | G6: 7558181.5 | H6: 55697762 | I6: 12334737 | J6: 4.395527e+08 | K6: 3.9330243e+08 | L6: 3.4960216e+08 | M6: 3.0590189e+08 | N6: 1.2478174e+08 | O6: 1.7446565e+08 | P6: 92930733 | Q6: 82288069 | R6: 96961077 | S6: =GETPIVOTDATA(" 2022 Budget Finance Recommendation",$A$3,"Future2 Description","FA180-Capex Expense")/GETPIVOTDATA(" 2021 R. Budget",$A$3,"Future2 Description","FA180-Capex Expense") -> 1.421289 | T6: =GETPIVOTDATA(" 2022 Budget Finance Recommendation",$A$3,"Future2 Description","FA180-Capex Expense")-GETPIVOTDATA(" 2021 R. Budget",$A$3,"Future2 Description","FA180-Capex Expense") -> 36986974
A7: Grand Total | C7: 1.128875e+09 | D7: 1.344511e+09 | E7: 1.0621397e+09 | F7: 1070170832 | G7: 4.4974662e+08 | H7: 1.0965872e+08 | I7: 43948207 | J7: 1.8600799e+09 | K7: 1.6639244e+09 | L7: 1.4790439e+09 | M7: 1.2941634e+09 | N7: 1.4096344e+09 | O7: 1.6769738e+09 | P7: 1.453613e+09 | Q7: 1.6245647e+09 | R7: 1.5237893e+09
F10: 45000000 | J10: CMHS | N10: -45000000
F11: 80000000 | J11: UG | N11: -80000000
F12: =GETPIVOTDATA(" 2021 R. Budget",$A$3)+F10+F11 -> 1195170832 | J12: PG | N12: -40000000
J13: Balance | N13: =GETPIVOTDATA(" 2022 Budget Finance Recommendation",$A$3)+N11+N10+N12 -> 1.2446344e+09
N16: =GETPIVOTDATA(" 2022 Budget Finance Recommendation",$A$3)/F12 -> 1.1794418
A19: Budget Chapters | B19: 2018 Actual | C19: 2019 Actual | D19: 2020 Actual | E19: 2021 R. Budget | F19: 2022 Budget | G19: 2023 Budget | H19: 2024 Budget
A20: CH1-Manpower | B20: 666857437 | C20: 734104574 | D20: 541385100 | E20: 583465683 | F20: 624050000 | G20: 624050000 | H20: 624050000
A21: CH2-Opex | B21: 4.1157745e+08 | C21: 4.5345466e+08 | D21: 4.3620813e+08 | E21: 398910380 | F21: 7.9647721e+08 | G21: 8.7845816e+08 | H21: 9.1822665e+08
A22: CH3-Capex | B22: 50440080 | C22: 1.5695179e+08 | D22: 84546442 | E22: 87794769 | F22: 4.395527e+08 | G22: 1.7446565e+08 | H22: 82288069
A23: Grand Total | B23: =SUM(B20:B22) -> 1.128875e+09 | C23: =SUM(C20:C22) -> 1.344511e+09 | D23: =SUM(D20:D22) -> 1.0621397e+09 | E23: =SUM(E20:E22) -> 1070170832 | F23: =SUM(F20:F22) -> 1.8600799e+09 | G23: =SUM(G20:G22) -> 1.6769738e+09 | H23: =SUM(H20:H22) -> 1.6245647e+09
A29: Budget Chapters | B29: 2021 R. Budget | C29: 2021 Actual | D29: 2021 PR | E29: 2021 PO | F29: 2021 Fund Available
A30: CH1-Manpower | B30: 583465683 | C30: 3.1287481e+08 | D30: 577263.62 | E30: 120262.4 | F30: =B30-C30-D30-E30 -> 2.6989335e+08
A31: CH2-Opex | B31: 398910380 | C31: 1.2931363e+08 | D31: 53383699 | E31: 31493207 | F31: =B31-C31-D31-E31 -> 1.8471984e+08
A32: CH3-Capex | B32: 87794769 | C32: 7558181.5 | D32: 55697762 | E32: 12334737 | F32: =B32-C32-D32-E32 -> 12204088
A33: Grand Total | B33: =SUM(B30:B32) -> 1070170832 | C33: =SUM(C30:C32) -> 4.4974662e+08 | D33: =SUM(D30:D32) -> 1.0965872e+08 | E33: =SUM(E30:E32) -> 43948207 | F33: =SUM(F30:F32) -> 4.6681728e+08
A40: Budget Chapters | B40: 2021 R. Budget | C40: 2022 Budget | D40: 2022 Budget Finance Recommendation | E40: 2023 Budget | F40: 2023 Budget Finance Recommendation | G40: 2024 Budget | H40: 2024 Budget Finance Recommendation
A41: CH1-Manpower | B41: 583465683 | C41: 624050000 | D41: 614050000 | E41: 624050000 | F41: 624050000 | G41: 624050000 | H41: 624050000
A42: CH2-Opex | B42: 398910380 | C42: 7.9647721e+08 | D42: 6.708027e+08 | E42: 8.7845816e+08 | F42: 7.3663227e+08 | G42: 9.1822665e+08 | H42: 8.0277819e+08
A43: CH3-Capex | B43: 87794769 | C43: 4.395527e+08 | D43: 1.2478174e+08 | E43: 1.7446565e+08 | F43: 92930733 | G43: 82288069 | H43: 96961077
A44: Grand Total | B44: =SUM(B41:B43) -> 1070170832 | C44: =SUM(C41:C43) -> 1.8600799e+09 | D44: =SUM(D41:D43) -> 1.4096344e+09 | E44: =SUM(E41:E43) -> 1.6769738e+09 | F44: =SUM(F41:F43) -> 1.453613e+09 | G44: =SUM(G41:G43) -> 1.6245647e+09 | H44: =SUM(H41:H43) -> 1.5237893e+09

Sheet CH1
A1: Chapter Summary
A3: Ledger Name | B3: Chapter Name | C3: 2021 Annual Budget | D3: 2021 Revised Budget | E3: 2021 Actual Amount | F3: 2021 PR | G3: 2021 PO | H3: 2021 Fund Available
A4: KUST Ledger | B4: 1 Personnel Costs | C4: 563874000 | D4: 583465683 | E4: 3.1287481e+08 | F4: 577263.62 | G4: 120262.4 | H4: 2.6989335e+08
B5: 2 Other Operating Costs | C5: 418640000 | D5: 398910380 | E5: 1.3203661e+08 | F5: 52994194 | G5: 29519382 | H5: 1.8436019e+08
B6: 3 Capital Payments | C6: 87207000 | D6: 87794769 | E6: 7708181.5 | F6: 55329862 | G6: 12538999 | H6: 12217726
A7: Grand Total | C7: 1069721000 | D7: 1070170832 | E7: 4.526196e+08 | F7: 1.0890132e+08 | G7: 42178644 | H7: 4.6647127e+08

Sheet Pivot Ch2
A1: Future2 Description | B1: FA179-Opex Expense
A3: Cost Center Code - Group | B3: 2018 Actual | C3: 2019 Actual | D3: 2020 Actual | E3: 2021 R. Budget | F3: 2021 Actual | G3: 2021 PR | H3: 2021 PO | I3: 2022 Budget | J3: 2022 Budget Scenario 90% | K3: 2022 Budget Scenario 80% | L3: 2022 Budget Scenario 70% | M3: 2022 Budget Finance Recommendation | N3: 2023 Budget | O3: 2023 Budget Finance Recommendation | P3: 2024 Budget | Q3: 2024 Budget Finance Recommendation
A4: Senior Vice President, Research Office | B4: 50355414 | C4: 86138314 | D4: 1.1373651e+08 | E4: 118471878 | F4: 43791752 | G4: 13759031 | H4: 9087279.5 | I4: 2.135858e+08 | J4: 1.9222722e+08 | K4: 1.7086864e+08 | L4: 1.4951006e+08 | M4: 1.5050129e+08 | N4: 1.8720002e+08 | O4: 1.3676079e+08 | P4: 1.5396619e+08 | Q4: 1.406961e+08
A5: Graduate Studies | B5: 59904650 | C5: 69759619 | D5: 65711376 | E5: 104483969 | F5: 40905424 | H5: 0 | I5: 178231406 | J5: 1.6040827e+08 | K5: 1.4258512e+08 | L5: 1.2476198e+08 | M5: 150618667 | N5: 219371651 | O5: 167591982 | P5: 2.4392202e+08 | Q5: 186410819
A6: Academic and Student Services Office | B6: 1.8012185e+08 | C6: 1.0242806e+08 | D6: 80592865 | E6: 38514134 | F6: 14455242 | G6: 2557216 | H6: 6173087.8 | I6: 1.4416226e+08 | J6: 1.2974603e+08 | K6: 1.1532981e+08 | L6: 1.0091358e+08 | M6: 1.1760326e+08 | N6: 1.7668398e+08 | O6: 1.4600298e+08 | P6: 1.9877588e+08 | Q6: 1.6365788e+08
A7: College of Medicine & Health Sciences | B7: 3391925.2 | C7: 6964244.4 | D7: 13219211 | E7: 17266074 | F7: 7938865.9 | G7: 1512517.1 | H7: 251075.5 | I7: 87599982 | J7: 77759983 | K7: 69119985 | L7: 60479987 | M7: 85436717 | N7: 1.0541561e+08 | O7: 1.0274461e+08 | P7: 1.2350534e+08 | Q7: 1.2021116e+08
A8: Administration, Facilities and EHS Office | B8: 67137093 | C8: 79045704 | D8: 67113228 | E8: 70236116 | F8: 13384126 | G8: 23785047 | H8: 9787477 | I8: 68823639 | J8: 61941275 | K8: 55058911 | L8: 48176548 | M8: 68823639 | N8: 78028823 | O8: 78028823 | P8: 78307016 | Q8: 78307016
A9: President's Office | B9: 13723360 | C9: 42423014 | D9: 28084938 | E9: 7179350 | F9: 2150653 | G9: 3029213.9 | H9: 601972.5 | I9: 33353835 | J9: 30018451 | K9: 26683068 | L9: 23347684 | M9: 31353835 | N9: 33744388 | O9: 33044388 | P9: 35616380 | Q9: 34116380
A10: Information Technology/ANKABUT | B10: 25090427 | C10: 36724659 | D10: 57480385 | E10: 33281345 | F10: 4265401.8 | G10: 7625202.4 | H10: 4804417.4 | I10: 32355401 | J10: 29119861 | K10: 25884321 | L10: 22648781 | M10: 32355401 | N10: 37434321 | O10: 37434321 | P10: 40279229 | Q10: 40279229
A11: College of Arts & Science | B11: 2320570.8 | C11: 3165328.2 | D11: 1656685.5 | E11: 2461725 | F11: 255636.46 | G11: 46754.46 | H11: 247334.44 | I11: 14070890 | J11: 11520801 | K11: 10240712 | L11: 8960623 | M11: 12880240 | N11: 16817192 | O11: 14291642 | P11: 15601592 | Q11: 13941592
A12: College of Engineering | B12: 6242088.2 | C12: 7538445.4 | D12: 5920790.6 | E12: 4632949 | F12: 1331639.2 | G12: 747237.29 | H12: 500008.16 | I12: 13353788 | J12: 12018409 | K12: 10683030 | L12: 9347651.6 | M12: 13353788 | N12: 13592078 | O12: 13592078 | P12: 17352406 | Q12: 17352406
A13: Provost | I13: 6255000 | M13: 3190650 | N13: 6255000 | O13: 3225550 | P13: 6255000 | Q13: 3160000
A14: HR & Procurement Office | B14: 2324810.4 | C14: 18766991 | D14: 1529905.5 | E14: 1206264 | F14: 402070.04 | G14: 196800.53 | H14: 40555 | I14: 3018400 | J14: 2716560 | K14: 2414720 | L14: 2112880 | M14: 3018400 | N14: 2904000 | O14: 2904000 | P14: 2904000 | Q14: 2904000
A15: Finance & Business Development Office | B15: 965265.4 | C15: 500280.96 | D15: 1162237.7 | E15: 984076 | F15: 397042 | G15: 31680 | I15: 1164440 | J15: 1047996 | K15: 931552 | L15: 815108 | M15: 1164440 | N15: 432480 | O15: 432480 | P15: 442180 | Q15: 442180
A16: Continuing Education | B16: 0 | C16: 0 | D16: 0 | E16: 192500 | F16: 35781.5 | G16: 93000 | I16: 502370 | J16: 452133 | K16: 401896 | L16: 351659 | M16: 502370 | N16: 578620 | O16: 578620 | P16: 1299424 | Q16: 1299424
A17: Grand Total | B17: 4.1157745e+08 | C17: 4.5345466e+08 | D17: 4.3620813e+08 | E17: 398910380 | F17: 1.2931363e+08 | G17: 53383699 | H17: 31493207 | I17: 7.9647721e+08 | J17: 7.0897699e+08 | K17: 6.3020177e+08 | L17: 5.5142654e+08 | M17: 6.708027e+08 | N17: 8.7845816e+08 | O17: 7.3663227e+08 | P17: 9.1822665e+08 | Q17: 8.0277819e+08

Sheet Pivot Ch2 Account
A1: Future2 Description | B1: FA179-Opex Expense
A3: Row Labels | B3: 2018 Actual | C3: 2019 Actual | D3: 2020 Actual | E3: 2021 R. Budget | F3: 2021 Actual | G3: 2021 PR | H3: 2021 PO | I3: 2022 Budget | J3: 2022 Budget Scenario 90% | K3: 2022 Budget Scenario 80% | L3: 2022 Budget Scenario 70% | M3: 2022 Budget Finance Recommendation | N3: 2023 Budget | O3: 2023 Budget Finance Recommendation | P3: 2024 Budget | Q3: 2024 Budget Finance Recommendation
A4: Postgraduate Student Salaries | B4: 0 | C4: 0 | D4: 26246724 | E4: 112772759 | F4: 45891287 | I4: 203710434 | J4: 1.8333939e+08 | K4: 1.6296835e+08 | L4: 1.425973e+08 | M4: 176097695 | N4: 259296044 | O4: 207516375 | P4: 2.9734536e+08 | Q4: 239834163
A5: Scientific | B5: 39989703 | C5: 64438059 | D5: 93594271 | E5: 95910011 | F5: 39988888 | G5: 4008035.6 | H5: 3655194.6 | I5: 1.7960203e+08 | J5: 1.6164183e+08 | K5: 1.4368162e+08 | L5: 1.2572142e+08 | M5: 1.1651752e+08 | N5: 1.5741575e+08 | O5: 1.0697652e+08 | P5: 1.2024661e+08 | Q5: 1.0697652e+08
A6: Student stipend | B6: 94937565 | C6: 1.0947368e+08 | D6: 72208398 | I6: 106236000 | J6: 95612400 | K6: 84988800 | L6: 74365200 | M6: 79677000 | N6: 123039000 | O6: 92358000 | P6: 140802750 | Q6: 105684750
A7: Academic Collaborative Partnership Services | B7: 167121.5 | C7: 120474.4 | D7: 105415.14 | E7: 409202 | F7: 4040.3 | I7: 40162080 | J7: 34345872 | K7: 30529664 | L7: 26713456 | M7: 37225230 | N7: 39162080 | O7: 37560130 | P7: 39162080 | Q7: 36694580
A8: Bldg maintenance-Business premises | B8: 26063815 | C8: 31663888 | D8: 30543870 | E8: 26125691 | F8: 1420463.6 | G8: 19352824 | H8: 2594008.2 | I8: 24034389 | J8: 21630950 | K8: 19227511 | L8: 16824072 | M8: 24034389 | N8: 32832695 | O8: 32832695 | P8: 33088495 | Q8: 33088495
A9: Computer software licenses | B9: 8039197.1 | C9: 10369252 | D9: 10814022 | E9: 15353817 | F9: 1775371.7 | G9: 8556263.3 | H9: 2802726.4 | I9: 19077946 | J9: 17035151 | K9: 15142357 | L9: 13249562 | M9: 19027946 | N9: 20762835 | O9: 20712835 | P9: 22165121 | Q9: 22115121
A10: Laboratory equipment | B10: 5482693.5 | C10: 14016405 | D10: 13658821 | E10: 15553556 | F10: 2475706.4 | G10: 7209968.4 | H10: 5192617.8 | I10: 18551535 | J10: 16426381 | K10: 14601228 | L10: 12776074 | M10: 18551535 | N10: 19754055 | O10: 19754055 | P10: 21000545 | Q10: 21000545
A11: Library books | B11: 536647.68 | C11: 14570173 | D11: 11597337 | E11: 12976004 | F11: 7530590 | G11: 1585181.6 | H11: 3170562.5 | I11: 17362029 | J11: 15625826 | K11: 13889623 | L11: 12153420 | M11: 17362029 | N11: 19074757 | O11: 19074757 | P11: 20959938 | Q11: 20959938
A12: Electricity consumption charges | B12: 32233264 | C12: 28477238 | D12: 24742245 | E12: 16047749 | F12: 5972680.9 | I12: 15465717 | J12: 13919145 | K12: 12372574 | L12: 10826002 | M12: 15465717 | N12: 15465717 | O12: 15465717 | P12: 15465717 | Q12: 15465717
A13: Manpower supply | B13: 8402324.3 | C13: 5295365.6 | D13: 27841721 | E13: 9124106 | F13: 1184032.6 | G13: 460004 | H13: 3431819.2 | I13: 14743480 | J13: 12189132 | K13: 10834784 | L13: 9480435.9 | M13: 13543480 | N13: 15733740 | O13: 14293740 | P13: 16842912 | Q13: 15114912
A14: IT Systems & Support expenses | B14: 5695281.6 | C14: 851424.58 | D14: 1444211.6 | E14: 2100000 | F14: 300000 | G14: 798441 | I14: 13996443 | J14: 12596799 | K14: 11197154 | L14: 9797510.1 | M14: 13967178 | N14: 16414809 | O14: 16414809 | P14: 19710778 | Q14: 19710778
A15: Laboratory - Scientific | B15: 5667447.1 | C15: 7342951.6 | D15: 2473540 | E15: 2420637 | F15: 1409865.5 | G15: 555102.68 | H15: 266424.85 | I15: 11929794 | J15: 10129315 | K15: 9003835.4 | L15: 7878356 | M15: 10739144 | N15: 9032195 | O15: 6506645 | P15: 7238224 | Q15: 5578224
A16: Student Transport | B16: 7066550.8 | C16: 9622796 | D16: 3208631.9 | E16: 6886815 | F16: -22192.57 | G16: 1 | H16: 329381.77 | I16: 10315850 | J16: 9284265 | K16: 8252680 | L16: 7221095 | M16: 10315850 | N16: 10243400 | O16: 10243400 | P16: 10255900 | Q16: 10255900
A17: Conferences, seminars and exhibitions and other events: - Local Events | B17: 9149933.7 | C17: 22006418 | D17: 4201523.9 | E17: 3408789 | F17: 1358731.1 | G17: 1439000 | H17: 257157.5 | I17: 9824821 | J17: 8824338.9 | K17: 7843856.8 | L17: 6863374.7 | M17: 9814821 | N17: 10282383 | O17: 10272383 | P17: 12239237 | Q17: 12229237
A18: Security service | B18: 7859664.9 | C18: 9750717.3 | D18: 9751370 | E18: 7496200 | F18: 1254059.8 | G18: 3366683.3 | H18: 2462249.8 | I18: 9388680 | J18: 8449812 | K18: 7510944 | L18: 6572076 | M18: 9388680 | N18: 9388680 | O18: 9388680 | P18: 9388680 | Q18: 9388680
A19: Cleaning Services: Business premises | B19: 11085217 | C19: 10507188 | D19: 11146117 | E19: 8284070 | F19: 2995204.4 | G19: 5.8207661e-11 | H19: 3285674.5 | I19: 8921787.4 | J19: 8029608.6 | K19: 7137429.9 | L19: 6245251.1 | M19: 8921787.4 | N19: 8921787.3 | O19: 8921787.3 | P19: 8921787.4 | Q19: 8921787.4
A20: Advertising Services (General) | B20: 581045.24 | C20: 5913007.8 | D20: 2482845.9 | E20: 3537655 | F20: 620757.53 | G20: 1894366 | H20: 0 | I20: 7070992.4 | J20: 6363893.2 | K20: 5656793.9 | L20: 4949694.7 | M20: 7070992.4 | N20: 7927000 | O20: 7927000 | P20: 8403333 | Q20: 8403333
A21: Student Internship | B21: 363847.16 | C21: 766232.81 | D21: 263497.54 | E21: 59066 | I21: 6572388.9 | J21: 5915150 | K21: 5257911.1 | L21: 4600672.2 | M21: 6572388.9 | N21: 6900008.3 | O21: 6900008.3 | P21: 7242383.8 | Q21: 7242383.8
A22: Academic Missions - Combined expenses | B22: 2296576.1 | C22: 2740427.7 | D22: 815412.15 | E22: 1459712 | F22: 53465.38 | I22: 6430000 | J22: 5715000 | K22: 5080000 | L22: 4445000 | M22: 6430000 | N22: 6511000 | O22: 6511000 | P22: 6783040 | Q22: 6783040
A23: Student medical insurance | B23: 4336.82 | C23: 0 | D23: 0 | E23: 1 | I23: 4816800 | J23: 4335120 | K23: 3853440 | L23: 3371760 | M23: 4816800 | N23: 5724000 | O23: 5724000 | P23: 6107400 | Q23: 6107400
A24: Water consumption charges | B24: 0 | C24: 1657218.5 | D24: 5368341.6 | E24: 4858034 | F24: 1435559.7 | I24: 4691229 | J24: 4222106.1 | K24: 3752983.2 | L24: 3283860.3 | M24: 4691229 | N24: 4691229 | O24: 4691229 | P24: 4691229 | Q24: 4691229
A25: Education-Outsourced training service | B25: 55955.5 | C25: 963988.45 | D25: 1520699.7 | E25: 2508953 | F25: 577646.56 | G25: 1460393.3 | H25: 3500 | I25: 4592470 | J25: 4133223 | K25: 3673976 | L25: 3214729 | M25: 4592470 | N25: 4340820 | O25: 4340820 | P25: 4415224 | Q25: 4415224
A26: Legal services | B26: 1429997.3 | C26: 2439034.1 | D26: 2695109.5 | E26: 3219289 | F26: 339046.71 | G26: 729456.63 | H26: 36638.18 | I26: 3872238 | J26: 3485014.2 | K26: 3097790.4 | L26: 2710566.6 | M26: 3872238 | N26: 4646385 | O26: 4646385 | P26: 5575362 | Q26: 5575362
A27: Business Travel - Combined expenses | B27: 2147895.3 | C27: 2766837.1 | D27: 216176.96 | E27: 104982 | F27: 17390 | I27: 3631093 | J27: 3105083.7 | K27: 2760074.4 | L27: 2415065.1 | M27: 3565593 | N27: 3619093 | O27: 3553593 | P27: 3828093 | Q27: 3762593
A28: Scholarships & other financial aid | B28: 180843.83 | C28: 0 | D28: 0 | I28: 3000000 | J28: 0 | K28: 0 | L28: 0 | M28: 1500000 | N28: 3000000 | O28: 1500000 | P28: 3000000 | Q28: 1500000
A29: Conferences, seminars and exhibitions and other events: - Overseas event | B29: 6178.69 | C29: 485784.96 | D29: 79093.7 | E29: 90276 | F29: 4515.02 | I29: 2768957 | J29: 2447061.3 | K29: 2175165.6 | L29: 1903269.9 | M29: 2743957 | N29: 2948942 | O29: 2923942 | P29: 3128962 | Q29: 3103962
A30: Academic Publications | B30: 68297.76 | C30: 158851.65 | D30: 436584.61 | E30: 421029 | F30: 130190.17 | G30: 20564 | I30: 2655819.9 | J30: 2318237.9 | K30: 2060655.9 | L30: 1803073.9 | M30: 2655819.9 | N30: 2954459.9 | O30: 2954459.9 | P30: 3238699.9 | Q30: 3238699.9
A31: Student relocation & travel exps | B31: 753383.32 | C31: 2811698.8 | D31: 1730271.6 | E31: 1403064 | F31: 632845 | I31: 2629904 | J31: 2366913.6 | K31: 2103923.2 | L31: 1840932.8 | M31: 2629904 | N31: 3371287 | O31: 3371287 | P31: 3555424 | Q31: 3555424
A32: Data Transmission charges | B32: 2321014.7 | C32: 5668930.6 | D32: 6668930.9 | E32: 3829088 | F32: 2105954.1 | I32: 2618028 | J32: 2356225.2 | K32: 2094422.4 | L32: 1832619.6 | M32: 2618028 | N32: 2018028 | O32: 2018028 | P32: 2018028 | Q32: 2018028
A33: Printing and publishing | B33: 2535 | C33: 334407.04 | D33: 220432.79 | E33: 170455 | F33: 119433.03 | H33: 0 | I33: 2511000 | J33: 2259900 | K33: 2008800 | L33: 1757700 | M33: 2511000 | N33: 1270000 | O33: 1270000 | P33: 1370000 | Q33: 1370000
A34: Public relations | B34: 947316.9 | C34: 1380274.2 | D34: 129310 | E34: 137342 | F34: -820 | I34: 2500000 | J34: 2250000 | K34: 2000000 | L34: 1750000 | M34: 2500000 | N34: 2500000 | O34: 2500000 | P34: 2500000 | Q34: 2500000
A35: Computers and peripherals | B35: 4511639.1 | C35: 17212941 | D35: 16808255 | E35: 14018221 | F35: 781991.19 | G35: 523039.62 | H35: 3370975.3 | I35: 2455000 | J35: 2191500 | K35: 1948000 | L35: 1704500 | M35: 1511000 | N35: 2929000 | O35: 1688000 | P35: 3226180 | Q35: 1650000
A36: Standards Certification Services (e.g. ISO) | B36: 658540.72 | C36: 725941.01 | D36: 1198953 | E36: 972421 | F36: 148176.88 | I36: 2443004 | J36: 1523703.6 | K36: 1354403.2 | L36: 1185102.8 | M36: 2068004 | N36: 1625000 | O36: 1250000 | P36: 5082997 | Q36: 4707997
A37: Student Field trips | B37: 826094.05 | C37: 783042.21 | D37: 537386.89 | E37: 460997 | F37: 18869.47 | H37: 0 | I37: 2370500 | J37: 2133450 | K37: 1896400 | L37: 1659350 | M37: 2370500 | N37: 2695500 | O37: 2695500 | P37: 3020500 | Q37: 3020500
A38: Enrollment expenses | B38: 740812.13 | C38: 5729189.4 | D38: 1588063.2 | E38: 2152196 | F38: 273993.74 | G38: 163301 | H38: 125500 | I38: 2180000 | J38: 1962000 | K38: 1744000 | L38: 1526000 | M38: 2180000 | N38: 2590000 | O38: 2590000 | P38: 3090000 | Q38: 3090000
A39: Student Project Expenses | B39: 693103.86 | C39: 748513.72 | D39: 1440754.9 | E39: 888872 | F39: 527092.53 | G39: 0 | H39: 0 | I39: 2102590 | J39: 1892331 | K39: 1682072 | L39: 1471813 | M39: 2102590 | N39: 2663340 | O39: 2663340 | P39: 2485190 | Q39: 2485190
A40: Events - Awards, prizes & gifts | B40: 19662 | C40: 18555.73 | D40: 2489.15 | E40: 81313 | F40: 7777.99 | I40: 2068000 | J40: 1820700 | K40: 1618400 | L40: 1416100 | M40: 2048000 | N40: 2068000 | O40: 2048000 | P40: 2073400 | Q40: 2053400
A41: Academic Advisory Service | B41: 184630.62 | C41: 491712.84 | D41: 149237.89 | E41: 109861 | F41: 27566.75 | I41: 1821620 | J41: 1531458 | K41: 1361296 | L41: 1191134 | M41: 1761620 | N41: 2887677.5 | O41: 2827677.5 | P41: 3940580 | Q41: 3880580
...

Sheet Pivot Ch3
A1: Future2 Description | B1: FA180-Capex Expense
A3: Cost Center Code - Group | B3: 2018 Actual | C3: 2019 Actual | D3: 2020 Actual | E3: 2021 R. Budget | F3: 2021 Actual | G3: 2021 PR | H3: 2021 PO | I3: 2022 Budget | J3: 2022 Budget Scenario 90% | K3: 2022 Budget Scenario 80% | L3: 2022 Budget Scenario 70% | M3: 2022 Budget Finance Recommendation | N3: 2023 Budget | O3: 2023 Budget Finance Recommendation | P3: 2024 Budget | Q3: 2024 Budget Finance Recommendation
A4: Senior Vice President, Research Office | B4: 16088011 | C4: 24817595 | D4: 18333810 | E4: 24284535 | F4: 1004969.1 | G4: 21399529 | H4: 764750.27 | I4: 2.782088e+08 | J4: 2.5038792e+08 | K4: 2.2256704e+08 | L4: 1.9474616e+08 | M4: 25102366 | N4: 83859445 | O4: 24489459 | P4: 18786312 | Q4: 22489459
A5: Administration, Facilities and EHS Office | B5: 14268377 | C5: 43165437 | D5: 34749576 | E5: 25061676 | F5: 2067526.2 | G5: 22185794 | H5: 652506 | I5: 1.0023933e+08 | J5: 90215397 | K5: 80191464 | L5: 70167531 | M5: 48116815 | N5: 53402634 | O5: 32762500 | P5: 22264265 | Q5: 34354925
A6: College of Medicine & Health Sciences | B6: 2152795 | C6: 61124462 | D6: 17595457 | E6: 27422265 | F6: 4474163.7 | G6: 3427896 | H6: 9410471.6 | I6: 34786123 | J6: 31307511 | K6: 27828898 | L6: 24350286 | M6: 25444123 | N6: 18823354 | O6: 17498554 | P6: 22502422 | Q6: 21581622
A7: College of Engineering | B7: 12466383 | C7: 9982516.4 | D7: 4425327.8 | E7: 2587968 | F7: 129679 | G7: 1984286.2 | H7: 393781.84 | I7: 9343216 | J7: 8408894.4 | K7: 7474572.8 | L7: 6540251.2 | M7: 9343216 | N7: 6053819 | O7: 6053819 | P7: 6590561 | Q7: 6590561
A8: College of Arts & Science | B8: 1500024.6 | C8: 2059737.4 | D8: 0 | E8: 3694815 | F8: 39928 | G8: 2751400 | H8: 868629.7 | I8: 7896973.8 | J8: 4812276.4 | K8: 4277579 | L8: 3742881.7 | M8: 7896973.8 | N8: 5123150.2 | O8: 5123150.2 | P8: 5523260 | Q8: 5523260
A9: Information Technology/ANKABUT | B9: 1848159.8 | C9: 521238.5 | D9: 5927842.4 | E9: 4272296 | F9: -379409 | G9: 3948857 | H9: 94598 | I9: 5011250 | J9: 4510125 | K9: 4009000 | L9: 3507875 | M9: 5011250 | N9: 4432250 | O9: 4432250 | P9: 3850250 | Q9: 3850250
A10: Graduate Studies | B10: 0 | C10: 0 | I10: 2007000 | J10: 1806300 | K10: 1605600 | L10: 1404900 | M10: 2007000 | N10: 711000 | O10: 711000 | P10: 711000 | Q10: 711000
A11: HR & Procurement Office | B11: 0 | C11: 0 | D11: 29334.5 | E11: 110494 | F11: 18149.5 | G11: 0 | H11: 0 | I11: 1650000 | J11: 1485000 | K11: 1320000 | L11: 1155000 | M11: 1650000 | N11: 1650000 | O11: 1650000 | P11: 1650000 | Q11: 1650000
A12: KUST - Office of the Provost | B12: 0 | C12: 2004424.2 | D12: 1481224 | E12: 160720 | F12: 10720 | H12: 150000 | I12: 200000 | J12: 180000 | K12: 160000 | L12: 140000 | M12: 0 | N12: 200000 | O12: 0 | P12: 200000 | Q12: 0
A13: President's Office | B13: 1408395.4 | C13: 4151760.4 | D13: 39940.11 | E13: 200000 | F13: 192455 | G13: 0 | H13: 0 | I13: 200000 | J13: 180000 | K13: 160000 | L13: 140000 | M13: 200000 | N13: 200000 | O13: 200000 | P13: 200000 | Q13: 200000
A14: Academic and Student Services Office | B14: 583733.8 | C14: 9124622.2 | D14: 1963930 | I14: 10000 | J14: 9000 | K14: 8000 | L14: 7000 | M14: 10000 | N14: 10000 | O14: 10000 | P14: 10000 | Q14: 10000
A15: Finance & Business Development Office | B15: 124200 | C15: 0
A16: Grand Total | B16: 50440080 | C16: 1.5695179e+08 | D16: 84546442 | E16: 87794769 | F16: 7558181.5 | G16: 55697762 | H16: 12334737 | I16: 4.395527e+08 | J16: 3.9330243e+08 | K16: 3.4960216e+08 | L16: 3.0590189e+08 | M16: 1.2478174e+08 | N16: 1.7446565e+08 | O16: 92930733 | P16: 82288069 | Q16: 96961077

Sheet Pivot Ch3 Account
A1: Future2 Description | B1: FA180-Capex Expense
A3: Account Description | B3: Cost Center Code - Group | C3: 2018 Actual | D3: 2019 Actual | E3: 2020 Actual | F3: 2021 R. Budget | G3: 2021 Actual | H3: 2021 PR | I3: 2021 PO | J3: 2022 Budget | K3: 2022 Budget Scenario 90% | L3: 2022 Budget Scenario 80% | M3: 2022 Budget Scenario 70% | N3: 2022 Budget Finance Recommendation | O3: 2023 Budget | P3: 2023 Budget Finance Recommendation | Q3: 2024 Budget | R3: 2024 Budget Finance Recommendation
A4: Laboratory equipment | B4: Senior Vice President, Research Office | C4: 16088011 | D4: 24396868 | E4: 18053325 | F4: 18484535 | G4: 995459.05 | H4: 15764203 | I4: 764750.27 | J4: 2.7710644e+08 | K4: 2.4939579e+08 | L4: 2.2168515e+08 | M4: 1.9397451e+08 | N4: 24000000 | O4: 83369986 | P4: 24000000 | Q4: 18296852 | R4: 22000000
B5: College of Medicine & Health Sciences | C5: 2152795 | D5: 57068649 | E5: 15725666 | F5: 21361628 | G5: 4313893.7 | H5: 704656.02 | I5: 7405657.1 | J5: 25108588 | K5: 22597729 | L5: 20086870 | M5: 17576012 | N5: 25108588 | O5: 17127086 | P5: 17127086 | Q5: 21380746 | R5: 21380746
B6: College of Engineering | C6: 12344498 | D6: 9583252.2 | E6: 3600118.5 | F6: 2587968 | G6: 129679 | H6: 1984286.2 | I6: 393781.84 | J6: 9319817 | K6: 8387835.3 | L6: 7455853.6 | M6: 6523871.9 | N6: 9319817 | O6: 6053819 | P6: 6053819 | Q6: 6590561 | R6: 6590561
B7: College of Arts & Science | C7: 1500024.6 | D7: 2035058.2 | E7: 0 | F7: 3694815 | G7: 39928 | H7: 2751400 | I7: 868629.7 | J7: 7493317 | K7: 4448985.3 | L7: 3954653.6 | M7: 3460321.9 | N7: 7493317 | O7: 4371150.2 | P7: 4371150.2 | Q7: 4243260 | R7: 4243260
B8: Administration, Facilities and EHS Office | C8: 579460 | D8: 235407 | E8: 501601.43 | F8: 245879 | H8: 140700 | J8: 250000 | K8: 225000 | L8: 200000 | M8: 175000 | N8: 250000 | O8: 262500 | P8: 262500 | Q8: 275625 | R8: 275625
B9: KUST - Office of the Provost | C9: 0 | D9: 2004424.2 | E9: 1481224 | F9: 160720 | G9: 10720 | I9: 150000 | J9: 200000 | K9: 180000 | L9: 160000 | M9: 140000 | N9: 0 | O9: 200000 | P9: 0 | Q9: 200000 | R9: 0
B10: Academic and Student Services Office | C10: 583733.8 | D10: 0 | E10: 0 | J10: 10000 | K10: 9000 | L10: 8000 | M10: 7000 | N10: 10000 | O10: 10000 | P10: 10000 | Q10: 10000 | R10: 10000
B11: President's Office | C11: 1408395.4 | D11: 4151760.4 | E11: 39940.11 | J11: 0 | K11: 0 | L11: 0 | M11: 0 | N11: 0 | O11: 0 | P11: 0 | Q11: 0 | R11: 0
B12: Information Technology/ANKABUT | C12: 733356 | D12: 0 | E12: -380451 | G12: -388859 | J12: 0 | K12: 0 | L12: 0 | M12: 0 | N12: 0 | O12: 0 | P12: 0 | Q12: 0 | R12: 0
B13: Finance & Business Development Office | C13: 78000 | D13: 0
A14: Laboratory equipment Total | C14: 35468274 | D14: 99475419 | E14: 39021424 | F14: 46535545 | G14: 5100820.8 | H14: 21345245 | I14: 9582818.9 | J14: 3.1948816e+08 | K14: 2.8524434e+08 | L14: 2.5355053e+08 | M14: 2.2185671e+08 | N14: 66181722 | O14: 1.1139454e+08 | P14: 51824555 | Q14: 50997044 | R14: 54500192
A15: Capital expense - Buildings | B15: Administration, Facilities and EHS Office | C15: 13472136 | D15: 39380218 | E15: 27682854 | F15: 22388565 | G15: 1910376.8 | H15: 19776918 | I15: 652506 | J15: 97989330 | K15: 88190397 | L15: 78391464 | M15: 68592531 | N15: 45866815 | O15: 50640134 | P15: 30000000 | Q15: 20988640 | R15: 33079300
B16: Senior Vice President, Research Office | C16: 0 | D16: 0 | E16: 0 | F16: 5600000 | H16: 5600000 | J16: 0 | K16: 0 | L16: 0 | M16: 0 | N16: 0 | O16: 0 | P16: 0 | Q16: 0 | R16: 0
B17: College of Medicine & Health Sciences | C17: 0 | D17: 0 | E17: 1143379 | J17: 0 | K17: 0 | L17: 0 | M17: 0 | N17: 0 | O17: 0 | P17: 0 | Q17: 0 | R17: 0
B18: Academic and Student Services Office | C18: 0 | D18: 0 | E18: 995000 | J18: 0 | K18: 0 | L18: 0 | M18: 0 | N18: 0 | O18: 0 | P18: 0 | Q18: 0 | R18: 0
B19: College of Engineering | C19: 0 | D19: 391826 | E19: 817887 | J19: 0 | K19: 0 | L19: 0 | M19: 0 | N19: 0 | O19: 0 | P19: 0 | Q19: 0 | R19: 0
A20: Capital expense - Buildings Total | C20: 13472136 | D20: 39772044 | E20: 30639120 | F20: 27988565 | G20: 1910376.8 | H20: 25376918 | I20: 652506 | J20: 97989330 | K20: 88190397 | L20: 78391464 | M20: 68592531 | N20: 45866815 | O20: 50640134 | P20: 30000000 | Q20: 20988640 | R20: 33079300
A21: Hardware & peripherals | C21: 630336.13 | D21: 1299505.9 | E21: 6642773.4 | F21: 8592933 | G21: 360785 | H21: 5866329 | I21: 1776727.5 | J21: 16080942 | K21: 14472848 | L21: 12864753 | M21: 11256659 | N21: 6738941.8 | O21: 6624268.5 | P21: 5299468.5 | Q21: 6182288.5 | R21: 5261488.5
A22: Furniture & Fixtures - Offices | C22: 216781 | D22: 15951980 | E22: 7658852.1 | F22: 3026175 | G22: 149900 | H22: 2243075 | I22: 322685 | J22: 3678500 | K22: 3310650 | L22: 2942800 | M22: 2574950 | N22: 3678500 | O22: 4170000 | P22: 4170000 | Q22: 2670000 | R22: 2670000
A23: Computer software | C23: 0 | D23: 0 | E23: 0 | F23: 990000 | H23: 835194.2 | J23: 2042365.7 | K23: 1838129.1 | L23: 1633892.6 | M23: 1429656 | N23: 2042365.7 | O23: 1339459.3 | P23: 1339459.3 | Q23: 1289459.3 | R23: 1289459.3
A24: Copyrights, patents and licenses | C24: 652553.14 | D24: 452844.8 | E24: 584272.75 | F24: 661551 | G24: 36299 | H24: 31000 | I24: 0 | J24: 273399 | K24: 246059.1 | L24: 218719.2 | M24: 191379.3 | N24: 273399 | O24: 297250 | P24: 297250 | Q24: 160637.5 | R24: 160637.5
A25: Grand Total | C25: 50440080 | D25: 1.5695179e+08 | E25: 84546442 | F25: 87794769 | G25: 7558181.5 | H25: 55697762 | I25: 12334737 | J25: 4.395527e+08 | K25: 3.9330243e+08 | L25: 3.4960216e+08 | M25: 3.0590189e+08 | N25: 1.2478174e+08 | O25: 1.7446565e+08 | P25: 92930733 | Q25: 82288069 | R25: 96961077

Sheet UG and PG
B1: 2021-2022 | C1: 2022-2023 | D1: 2023-2024 | E1: 2024-2025 | F1: 2025-2026 | G1: 2026-2027
A2: Continuing Students - UG | B2: 2620 | C2: 3080 | D2: 3696 | E2: 4261 | F2: 4780 | G2: 5248
A3: Continuing Students - PG | B3: 582 | C3: 858 | D3: 1100 | E3: 1250 | F3: 1500 | G3: 1750
A4: Intake - UG | B4: 800 | C4: 858 | D4: 859 | E4: 860 | F4: 861 | G4: 861
A5: Intake - PG | B5: 400 | C5: 400 | D5: 400 | E5: 400 | F5: 400 | G5: 400
A6: Total UG | B6: =SUM(B2,B4) -> 3420 | C6: =SUM(C2,C4) -> 3938 | D6: =SUM(D2,D4) -> 4555 | E6: =SUM(E2,E4) -> 5121 | F6: =SUM(F2,F4) -> 5641 | G6: =SUM(G2,G4) -> 6109
A7: Total PG | B7: 982 | C7: 1258 | D7: =SUM(D3,D5) -> 1500 | E7: =SUM(E3,E5) -> 1650 | F7: =SUM(F3,F5) -> 1900 | G7: =SUM(G3,G5) -> 2150
A8: Grand Total | B8: =SUM(B6:B7) -> 4402 | C8: =SUM(C6:C7) -> 5196 | D8: =SUM(D6:D7) -> 6055 | E8: =SUM(E6:E7) -> 6771 | F8: =SUM(F6:F7) -> 7541 | G8: =SUM(G6:G7) -> 8259

Sheet Cons. Ch2 & Ch3
A1: Cost Center Code - Group | B1: Cost Center Code | C1: Cost Center Description | D1: Account Code | E1: Account Description | F1: GL Account Combination | G1: 2021 Annual Budget | H1: 2021 Revised Budget | I1: 2021 Actual Amount | J1: 2021 PR | K1: 2021 PO | L1: 2021 Fund Available | M1: Future1 | N1: Future1 Description | O1: Future2 | P1: Future2 Description | Q1: 2020 Revis.ed Budget | R1: 2020 Actual Amount | S1: 2022 Budget | T1: 2022 Budget Scenario 90% | U1: 2022 Budget Scenario 80% | V1: 2022 Budget Scenario 70% | W1: 2023 Budget | X1: 2024 Budget | Y1: 2022 Budget Finance Recommendation | Z1: 2023 Budget Finance Recommendation | AA1: 2024 Budget Finance Recommendation | AB1: 2018 Actual Amount | AC1: 2019 Actual Amount | AD1: Diff 2022 | AF1: Diff 2023 | AH1: Diff 2024
A2: President's Office | B2: 8470110 | C2: KUST - Office of the President | D2: 420550 | E2: Academic Advisory Service | F2: 847.8470110.1.420550.000000.847001.200179 | G2: 29119 | H2: 29119 | L2: 29119 | M2: 847001 | N2: KUST - General | O2: 200179 | P2: FA179-Opex Expense | Q2: 29118.09 | R2: 29118.02 | S2: 30000 | T2: =S2*0.9 -> 27000 | U2: =S2*0.8 -> 24000 | V2: =S2*0.7 -> 21000 | W2: 30000 | X2: 30000 | Y2: 30000 | Z2: 30000 | AA2: 30000 | AB2: 2811.43 | AC2: 0 | AD2: =S2-Y2 -> 0 | AF2: =W2-Z2 -> 0 | AH2: =X2-AA2 -> 0
A3: Manpower | B3: Ch1 | C3: Manpower | D3: Ch1 | E3: #N/A | G3: 563874000 | H3: 583465683 | I3: 3.1287481e+08 | J3: 577263.62 | K3: 120262.4 | L3: 2.6989335e+08 | M3: 847001 | N3: KUST - General | O3: 100178 | P3: FA178-Manpower Expense | Q3: 551795870 | R3: 541385100 | S3: 624050000 | T3: =S3*0.9 -> 561645000 | U3: =S3*0.8 -> 499240000 | V3: =S3*0.7 -> 436835000 | W3: 624050000 | X3: 624050000 | Y3: 614050000 | Z3: 624050000 | AA3: 624050000 | AB3: 666857437 | AC3: 734104574 | AD3: =S3-Y3 -> 10000000 | AF3: =W3-Z3 -> 0 | AH3: =X3-AA3 -> 0
A4: President's Office | B4: 8470110 | C4: KUST - Office of the President | D4: 420570 | E4: Academic Collaborative Partnership Services | F4: 847.8470110.1.420570.000000.847001.200179 | G4: 1 | H4: 1 | L4: 1 | M4: 847001 | N4: KUST - General | O4: 200179 | P4: FA179-Opex Expense | Q4: 0.94 | R4: 0 | S4: 10000000 | T4: =S4*0.9 -> 9000000 | U4: =S4*0.8 -> 8000000 | V4: =S4*0.7 -> 7000000 | W4: 10000000 | X4: 10000000 | Y4: 8000000 | Z4: =10000000-700000 -> 9300000 | AA4: =10000000-1500000 -> 8500000 | AB4: 0 | AC4: 0 | AD4: =S4-Y4 -> 2000000 | AE4: ok | AF4: =W4-Z4 -> 700000 | AG4: ok | AH4: =X4-AA4 -> 1500000 | AI4: ok
A5: President's Office | B5: 8470110 | C5: KUST - Office of the President | D5: 420900 | E5: Legal services | F5: 847.8470110.1.420900.000000.847001.200179 | G5: 1501 | H5: 1501 | L5: 1501 | M5: 847001 | N5: KUST - General | O5: 200179 | P5: FA179-Opex Expense | Q5: 1900.4 | R5: 1845 | S5: 1500 | T5: =S5*0.9 -> 1350 | U5: =S5*0.8 -> 1200 | V5: =S5*0.7 -> 1050 | W5: 1500 | X5: 1500 | Y5: 1500 | Z5: 1500 | AA5: 1500 | AB5: 12303.86 | AC5: 2400 | AD5: =S5-Y5 -> 0 | AF5: =W5-Z5 -> 0 | AH5: =X5-AA5 -> 0
A6: President's Office | B6: 8470110 | C6: KUST - Office of the President | D6: 421000 | E6: Management consultancy | F6: 847.8470110.1.421000.000000.847001.200179 | G6: 1 | H6: 1 | L6: 1 | M6: 847001 | N6: KUST - General | O6: 200179 | P6: FA179-Opex Expense | Q6: 0.65 | R6: 0 | S6: 200000 | T6: =S6*0.9 -> 180000 | U6: =S6*0.8 -> 160000 | V6: =S6*0.7 -> 140000 | W6: 200000 | X6: 200000 | Y6: 200000 | Z6: 200000 | AA6: 200000 | AB6: 229317.15 | AC6: 204012.83 | AD6: =S6-Y6 -> 0 | AF6: =W6-Z6 -> 0 | AH6: =X6-AA6 -> 0
A7: President's Office | B7: 8470110 | C7: KUST - Office of the President | D7: 421700 | E7: Standards Certification Services (e.g. ISO) | F7: 847.8470110.1.421700.000000.847001.200179 | G7: 25000 | H7: 25000 | L7: 25000 | M7: 847001 | N7: KUST - General | O7: 200179 | P7: FA179-Opex Expense | Q7: 1.21 | R7: 0 | S7: 25000 | T7: =S7*0.9 -> 22500 | U7: =S7*0.8 -> 20000 | V7: =S7*0.7 -> 17500 | W7: 25000 | X7: 25000 | Y7: 25000 | Z7: 25000 | AA7: 25000 | AB7: 0 | AC7: 0 | AD7: =S7-Y7 -> 0 | AF7: =W7-Z7 -> 0 | AH7: =X7-AA7 -> 0
A8: President's Office | B8: 8470110 | C8: KUST - Office of the President | D8: 425510 | E8: Conferences, seminars and exhibitions and other events: - Local Events | F8: 847.8470110.1.425510.000000.847001.200179 | I8: -190000 | L8: 190000 | M8: 847001 | N8: KUST - General | O8: 200179 | P8: FA179-Opex Expense | Q8: 277367.71 | R8: 277368 | S8: 300000 | T8: =S8*0.9 -> 270000 | U8: =S8*0.8 -> 240000 | V8: =S8*0.7 -> 210000 | W8: 300000 | X8: 300000 | Y8: 300000 | Z8: 300000 | AA8: 300000 | AB8: 96210.44 | AC8: 10546039 | AD8: =S8-Y8 -> 0 | AF8: =W8-Z8 -> 0 | AH8: =X8-AA8 -> 0
A9: President's Office | B9: 8470110 | C9: KUST - Office of the President | D9: 425900 | E9: Entertainment and hospitality | F9: 847.8470110.1.425900.000000.847001.200179 | G9: 10000 | H9: 10000 | I9: -90 | L9: 10090 | M9: 847001 | N9: KUST - General | O9: 200179 | P9: FA179-Opex Expense | Q9: 13356.81 | R9: 13355.7 | S9: 10000 | T9: =S9*0.9 -> 9000 | U9: =S9*0.8 -> 8000 | V9: =S9*0.7 -> 7000 | W9: 10000 | X9: 10000 | Y9: 10000 | Z9: 10000 | AA9: 10000 | AB9: 57571.93 | AC9: 146141.49 | AD9: =S9-Y9 -> 0 | AF9: =W9-Z9 -> 0 | AH9: =X9-AA9 -> 0
A10: President's Office | B10: 8470110 | C10: KUST - Office of the President | D10: 426610 | E10: Computer software licenses | F10: 847.8470110.1.426610.000000.847001.200179 | G10: 80204 | H10: 80204 | I10: 42239.5 | L10: 37964.5 | M10: 847001 | N10: KUST - General | O10: 200179 | P10: FA179-Opex Expense | Q10: 42240.57 | R10: 42239.5 | S10: 518387.5 | T10: =S10*0.9 -> 466548.75 | U10: =S10*0.8 -> 414710 | V10: =S10*0.7 -> 362871.25 | W10: 518387.5 | X10: 518387.5 | Y10: 518387.5 | Z10: 518387.5 | AA10: 518387.5 | AB10: 29255.45 | AC10: 42239.5 | AD10: =S10-Y10 -> 0 | AF10: =W10-Z10 -> 0 | AH10: =X10-AA10 -> 0
A11: President's Office | B11: 8470110 | C11: KUST - Office of the President | D11: 427710 | E11: Subscriptions and membership fees: Trade organisations | F11: 847.8470110.1.427710.000000.847001.200179 | G11: 1880 | H11: 1880 | L11: 1880 | M11: 847001 | N11: KUST - General | O11: 200179 | P11: FA179-Opex Expense | Q11: 3883 | R11: 3882.17 | S11: 0 | T11: =S11*0.9 -> 0 | U11: =S11*0.8 -> 0 | V11: =S11*0.7 -> 0 | W11: 0 | X11: 0 | Y11: 0 | Z11: 0 | AA11: 0 | AB11: 0 | AC11: 0 | AD11: =S11-Y11 -> 0 | AF11: =W11-Z11 -> 0 | AH11: =X11-AA11 -> 0
A12: President's Office | B12: 8470110 | C12: KUST - Office of the President | D12: 427900 | E12: Translation and interpretation service | F12: 847.8470110.1.427900.000000.847001.200179 | G12: 12585 | H12: 12585 | L12: 12585 | M12: 847001 | N12: KUST - General | O12: 200179 | P12: FA179-Opex Expense | Q12: 0.82 | R12: 0 | S12: 0 | T12: =S12*0.9 -> 0 | U12: =S12*0.8 -> 0 | V12: =S12*0.7 -> 0 | W12: 0 | X12: 0 | Y12: 0 | Z12: 0 | AA12: 0 | AB12: 310 | AC12: 0 | AD12: =S12-Y12 -> 0 | AF12: =W12-Z12 -> 0 | AH12: =X12-AA12 -> 0
A13: President's Office | B13: 8470110 | C13: KUST - Office of the President | D13: 428090 | E13: Business Travel - Combined expenses | F13: 847.8470110.1.428090.000000.847001.200179 | G13: 64381 | H13: 64381 | I13: 17390 | L13: 46991 | M13: 847001 | N13: KUST - General | O13: 200179 | P13: FA179-Opex Expense | Q13: 104380.21 | R13: 64375.44 | S13: 1000000 | T13: =S13*0.9 -> 900000 | U13: =S13*0.8 -> 800000 | V13: =S13*0.7 -> 700000 | W13: 1000000 | X13: 1000000 | Y13: 1000000 | Z13: 1000000 | AA13: 1000000 | AB13: 918073.73 | AC13: 1236161 | AD13: =S13-Y13 -> 0 | AF13: =W13-Z13 -> 0 | AH13: =X13-AA13 -> 0
A14: President's Office | B14: 8470110 | C14: KUST - Office of the President | D14: 428640 | E14: Events - Awards, prizes & gifts | F14: 847.8470110.1.428640.000000.847001.200179 | G14: 1 | H14: 1 | L14: 1 | M14: 847001 | N14: KUST - General | O14: 200179 | P14: FA179-Opex Expense | Q14: 0.62 | R14: 0 | S14: 100000 | T14: =S14*0.9 -> 90000 | U14: =S14*0.8 -> 80000 | V14: =S14*0.7 -> 70000 | W14: 100000 | X14: 100000 | Y14: 100000 | Z14: 100000 | AA14: 100000 | AB14: 0 | AC14: 0 | AD14: =S14-Y14 -> 0 | AF14: =W14-Z14 -> 0 | AH14: =X14-AA14 -> 0
A15: President's Office | B15: 8470110 | C15: KUST - Office of the President | D15: 435410 | E15: Catering supplies: Offices | F15: 847.8470110.1.435410.000000.847001.200179 | G15: 1 | H15: 1 | L15: 1 | M15: 847001 | N15: KUST - General | O15: 200179 | P15: FA179-Opex Expense | Q15: 0.96 | R15: 0 | S15: 0 | T15: =S15*0.9 -> 0 | U15: =S15*0.8 -> 0 | V15: =S15*0.7 -> 0 | W15: 0 | X15: 0 | Y15: 0 | Z15: 0 | AA15: 0 | AB15: 1242.04 | AC15: 0 | AD15: =S15-Y15 -> 0 | AF15: =W15-Z15 -> 0 | AH15: =X15-AA15 -> 0
A16: President's Office | B16: 8470110 | C16: KUST - Office of the President | D16: 435519 | E16: Photography - Consumable materials /Tools | F16: 847.8470110.1.435519.000000.847001.200179 | G16: 2000 | H16: 2000 | L16: 2000 | M16: 847001 | N16: KUST - General | O16: 200179 | P16: FA179-Opex Expense | Q16: 0.94 | R16: 0 | S16: 0 | T16: =S16*0.9 -> 0 | U16: =S16*0.8 -> 0 | V16: =S16*0.7 -> 0 | W16: 0 | X16: 0 | Y16: 0 | Z16: 0 | AA16: 0 | AB16: 0 | AC16: 0 | AD16: =S16-Y16 -> 0 | AF16: =W16-Z16 -> 0 | AH16: =X16-AA16 -> 0
A17: President's Office | B17: 8470110 | C17: KUST - Office of the President | D17: 436110 | E17: Printing supplies | F17: 847.8470110.1.436110.000000.847001.200179 | G17: 4195 | H17: 4195 | L17: 4195 | M17: 847001 | N17: KUST - General | O17: 200179 | P17: FA179-Opex Expense | Q17: 0.94 | R17: 0 | S17: 0 | T17: =S17*0.9 -> 0 | U17: =S17*0.8 -> 0 | V17: =S17*0.7 -> 0 | W17: 0 | X17: 0 | Y17: 0 | Z17: 0 | AA17: 0 | AB17: 0 | AC17: 0 | AD17: =S17-Y17 -> 0 | AF17: =W17-Z17 -> 0 | AH17: =X17-AA17 -> 0
A18: President's Office | B18: 8470120 | C18: KUST - Audit & Compliance | D18: 420120 | E18: Internal Audit service | F18: 847.8470120.1.420120.000000.847001.200179 | G18: 400000 | H18: 400000 | J18: 15847.9 | K18: 383815 | L18: 337.1 | M18: 847001 | N18: KUST - General | O18: 200179 | P18: FA179-Opex Expense | Q18: -477000 | R18: -493500 | S18: 500000 | T18: =S18*0.9 -> 450000 | U18: =S18*0.8 -> 400000 | V18: =S18*0.7 -> 350000 | W18: 520000 | X18: 490000 | Y18: 500000 | Z18: 520000 | AA18: 490000 | AB18: 787666.24 | AC18: 304115.92 | AD18: =S18-Y18 -> 0 | AF18: =W18-Z18 -> 0 | AH18: =X18-AA18 -> 0
A19: President's Office | B19: 8470130 | C19: KUST - Institutional Research & Planning | D19: 421000 | E19: Management consultancy | F19: 847.8470130.1.421000.000000.847001.200179 | G19: 276300 | H19: 134500 | I19: 134500 | K19: 0 | L19: 0 | M19: 847001 | N19: KUST - General | O19: 200179 | P19: FA179-Opex Expense | Q19: 162970 | R19: 28465.75 | S19: 720000 | T19: =S19*0.9 -> 648000 | U19: =S19*0.8 -> 576000 | V19: =S19*0.7 -> 504000 | W19: 720000 | X19: 720000 | Y19: 720000 | Z19: 720000 | AA19: 720000 | AB19: 0 | AC19: 0 | AD19: =S19-Y19 -> 0 | AF19: =W19-Z19 -> 0 | AH19: =X19-AA19 -> 0
A20: President's Office | B20: 8470130 | C20: KUST - Institutional Research & Planning | D20: 425510 | E20: Conferences, seminars and exhibitions and other events: - Local Events | F20: 847.8470130.1.425510.000000.847001.200179 | G20: 2200 | H20: 2200 | L20: 2200 | M20: 847001 | N20: KUST - General | O20: 200179 | P20: FA179-Opex Expense | Q20: 2200 | R20: 2200 | S20: 0 | T20: =S20*0.9 -> 0 | U20: =S20*0.8 -> 0 | V20: =S20*0.7 -> 0 | W20: 0 | X20: 0 | Y20: 0 | Z20: 0 | AA20: 0 | AB20: 0 | AC20: 920160 | AD20: =S20-Y20 -> 0 | AF20: =W20-Z20 -> 0 | AH20: =X20-AA20 -> 0
A21: President's Office | B21: 8470130 | C21: KUST - Institutional Research & Planning | D21: 427710 | E21: Subscriptions and membership fees: Trade organisations | F21: 847.8470130.1.427710.000000.847001.200179 | G21: 125000 | H21: 129650 | I21: 129634.5 | L21: 15.5 | M21: 847001 | N21: KUST - General | O21: 200179 | P21: FA179-Opex Expense | Q21: 0 | R21: 0 | S21: 0 | T21: =S21*0.9 -> 0 | U21: =S21*0.8 -> 0 | V21: =S21*0.7 -> 0 | W21: 0 | X21: 0 | Y21: 0 | Z21: 0 | AA21: 0 | AB21: 0 | AC21: 0 | AD21: =S21-Y21 -> 0 | AF21: =W21-Z21 -> 0 | AH21: =X21-AA21 -> 0
A22: President's Office | B22: 8470140 | C22: KUST - Communication | D22: 425100 | E22: Advertising Services (General) | F22: 847.8470140.1.425100.000000.847001.200179 | G22: 2320934 | H22: 3070934 | I22: 620757.53 | J22: 1801366 | K22: 0 | L22: 648810.47 | M22: 847001 | N22: KUST - General | O22: 200179 | P22: FA179-Opex Expense | Q22: 2558303.5 | R22: 2353626.8 | S22: 6450992.4 | T22: =S22*0.9 -> 5805893.2 | U22: =S22*0.8 -> 5160793.9 | V22: =S22*0.7 -> 4515694.7 | W22: 7284500 | X22: 7745833 | Y22: 6450992.4 | Z22: 7284500 | AA22: 7745833 | AB22: 559823.4 | AC22: 5116143.8 | AD22: =S22-Y22 -> 0 | AF22: =W22-Z22 -> 0 | AH22: =X22-AA22 -> 0
A23: President's Office | B23: 8470140 | C23: KUST - Communication | D23: 425510 | E23: Conferences, seminars and exhibitions and other events: - Local Events | F23: 847.8470140.1.425510.000000.847001.200179 | G23: 3500000 | H23: 2850000 | I23: 1418079.7 | J23: 1212000 | K23: 218157.5 | L23: 1762.78 | M23: 847001 | N23: KUST - General | O23: 200179 | P23: FA179-Opex Expense | Q23: 2911261.6 | R23: 2727959.1 | S23: 7048000 | T23: =S23*0.9 -> 6343200 | U23: =S23*0.8 -> 5638400 | V23: =S23*0.7 -> 4933600 | W23: 6585060 | X23: 8025300 | Y23: 7048000 | Z23: 6585060 | AA23: 8025300 | AB23: 8248780 | AC23: 9740819.5 | AD23: =S23-Y23 -> 0 | AF23: =W23-Z23 -> 0 | AH23: =X23-AA23 -> 0
A24: President's Office | B24: 8470140 | C24: KUST - Communication | D24: 425550 | E24: Conferences, seminars and exhibitions and other events: - Overseas event | F24: 847.8470140.1.425550.000000.847001.200179 | G24: 1 | H24: 1 | L24: 1 | M24: 847001 | N24: KUST - General | O24: 200179 | P24: FA179-Opex Expense | Q24: 0.88 | R24: 0 | S24: 791955 | T24: =S24*0.9 -> 712759.5 | U24: =S24*0.8 -> 633564 | V24: =S24*0.7 -> 554368.5 | W24: 791940 | X24: 791960 | Y24: 791955 | Z24: 791940 | AA24: 791960 | AB24: 0 | AC24: 73716.59 | AD24: =S24-Y24 -> 0 | AF24: =W24-Z24 -> 0 | AH24: =X24-AA24 -> 0
A25: President's Office | B25: 8470140 | C25: KUST - Communication | D25: 427100 | E25: Public relations | F25: 847.8470140.1.427100.000000.847001.200179 | G25: 137341 | H25: 137341 | I25: -820 | L25: 138161 | M25: 847001 | N25: KUST - General | O25: 200179 | P25: FA179-Opex Expense | Q25: 135840.03 | R25: 129310 | S25: 2500000 | T25: =S25*0.9 -> 2250000 | U25: =S25*0.8 -> 2000000 | V25: =S25*0.7 -> 1750000 | W25: 2500000 | X25: 2500000 | Y25: 2500000 | Z25: 2500000 | AA25: 2500000 | AB25: 934828.56 | AC25: 1380274.2 | AD25: =S25-Y25 -> 0 | AF25: =W25-Z25 -> 0 | AH25: =X25-AA25 -> 0
A26: President's Office | B26: 8470140 | C26: KUST - Communication | D26: 427200 | E26: Printing and publishing | F26: 847.8470140.1.427200.000000.847001.200179 | G26: 1962 | H26: 1962 | I26: -21038.22 | K26: 0 | L26: 23000.22 | M26: 847001 | N26: KUST - General | O26: 200179 | P26: FA179-Opex Expense | Q26: 132195.98 | R26: 125002.84 | S26: 750000 | T26: =S26*0.9 -> 675000 | U26: =S26*0.8 -> 600000 | V26: =S26*0.7 -> 525000 | W26: 750000 | X26: 750000 | Y26: 750000 | Z26: 750000 | AA26: 750000 | AB26: 0 | AC26: 332618.73 | AD26: =S26-Y26 -> 0 | AF26: =W26-Z26 -> 0 | AH26: =X26-AA26 -> 0
A27: President's Office | B27: 8470140 | C27: KUST - Communication | D27: 435310 | E27: Newspapers, magazines, journals, etc | F27: 847.8470140.1.435310.000000.847001.200179 | G27: 10000 | H27: 10000 | L27: 10000 | M27: 847001 | N27: KUST - General | O27: 200179 | P27: FA179-Opex Expense | Q27: 13569 | R27: 13568.1 | S27: 10000 | T27: =S27*0.9 -> 9000 | U27: =S27*0.8 -> 8000 | V27: =S27*0.7 -> 7000 | W27: 10000 | X27: 10000 | Y27: 10000 | Z27: 10000 | AA27: 10000 | AB27: 2158 | AC27: 17260.1 | AD27: =S27-Y27 -> 0 | AF27: =W27-Z27 -> 0 | AH27: =X27-AA27 -> 0
A28: President's Office | B28: 8470140 | C28: KUST - Communication | D28: 435519 | E28: Photography - Consumable materials /Tools | F28: 847.8470140.1.435519.000000.847001.200179 | G28: 193297 | H28: 193297 | J28: 0 | L28: 193297 | M28: 847001 | N28: KUST - General | O28: 200179 | P28: FA179-Opex Expense | Q28: 77323.96 | R28: 53870 | S28: 135000 | T28: =S28*0.9 -> 121500 | U28: =S28*0.8 -> 108000 | V28: =S28*0.7 -> 94500 | W28: 135000 | X28: 135000 | Y28: 135000 | Z28: 135000 | AA28: 135000 | AB28: 0 | AC28: 0 | AD28: =S28-Y28 -> 0 | AF28: =W28-Z28 -> 0 | AH28: =X28-AA28 -> 0
A29: President's Office | B29: 8470150 | C29: KUST - General Counsel | D29: 420900 | E29: Legal services | F29: 847.8470150.1.420900.000000.847001.200179 | G29: 18595 | H29: 18595 | L29: 18595 | M29: 847001 | N29: KUST - General | O29: 200179 | P29: FA179-Opex Expense | Q29: 18595 | R29: 16996.14 | S29: 0 | T29: =S29*0.9 -> 0 | U29: =S29*0.8 -> 0 | V29: =S29*0.7 -> 0 | W29: 0 | X29: 0 | Y29: 0 | Z29: 0 | AA29: 0 | AB29: 0 | AC29: 0 | AD29: =S29-Y29 -> 0 | AF29: =W29-Z29 -> 0 | AH29: =X29-AA29 -> 0
A30: President's Office | B30: 8470150 | C30: KUST - General Counsel | D30: 425900 | E30: Entertainment and hospitality | F30: 847.8470150.1.425900.000000.847001.200179 | G30: 1 | H30: 1 | L30: 1 | M30: 847001 | N30: KUST - General | O30: 200179 | P30: FA179-Opex Expense | Q30: 0.17 | R30: 0 | S30: 0 | T30: =S30*0.9 -> 0 | U30: =S30*0.8 -> 0 | V30: =S30*0.7 -> 0 | W30: 0 | X30: 0 | Y30: 0 | Z30: 0 | AA30: 0 | AB30: 0 | AC30: 0 | AD30: =S30-Y30 -> 0 | AF30: =W30-Z30 -> 0 | AH30: =X30-AA30 -> 0
A31: Graduate Studies | B31: 8470230 | C31: KUST - Graduate Studies | D31: 420550 | E31: Academic Advisory Service | F31: 847.8470230.1.420550.000000.847001.200179 | G31: 80740 | H31: 80740 | I31: 27566.75 | L31: 53173.25 | M31: 847001 | N31: KUST - General | O31: 200179 | P31: FA179-Opex Expense | Q31: 79821 | R31: 79119.87 | S31: 1020620 | T31: =S31*0.9 -> 918558 | U31: =S31*0.8 -> 816496 | V31: =S31*0.7 -> 714434 | W31: 2057477.5 | X31: 3110580 | Y31: 1020620 | Z31: 2057477.5 | AA31: 3110580 | AB31: 154511.25 | AC31: 346385.92 | AD31: =S31-Y31 -> 0 | AF31: =W31-Z31 -> 0 | AH31: =X31-AA31 -> 0
A32: Graduate Studies | B32: 8470230 | C32: KUST - Graduate Studies | D32: 425100 | E32: Advertising Services (General) | F32: 847.8470230.1.425100.000000.847001.200179 | G32: 240000 | H32: 240000 | L32: 240000 | M32: 847001 | N32: KUST - General | O32: 200179 | P32: FA179-Opex Expense | Q32: 0 | R32: 0 | S32: 300000 | T32: =S32*0.9 -> 270000 | U32: =S32*0.8 -> 240000 | V32: =S32*0.7 -> 210000 | W32: 300000 | X32: 300000 | Y32: 300000 | Z32: 300000 | AA32: 300000 | AB32: 0 | AC32: 251555 | AD32: =S32-Y32 -> 0 | AF32: =W32-Z32 -> 0 | AH32: =X32-AA32 -> 0
A33: Graduate Studies | B33: 8470230 | C33: KUST - Graduate Studies | D33: 425510 | E33: Conferences, seminars and exhibitions and other events: - Local Events | F33: 847.8470230.1.425510.000000.847001.200179 | G33: 10000 | H33: 10000 | I33: -6134.47 | K33: 0 | L33: 16134.47 | M33: 847001 | N33: KUST - General | O33: 200179 | P33: FA179-Opex Expense | Q33: 17919 | R33: 17919 | S33: 34000 | T33: =S33*0.9 -> 30600 | U33: =S33*0.8 -> 27200 | V33: =S33*0.7 -> 23800 | W33: 34000 | X33: 34000 | Y33: 34000 | Z33: 34000 | AA33: 34000 | AB33: 0 | AC33: 46160.94 | AD33: =S33-Y33 -> 0 | AF33: =W33-Z33 -> 0 | AH33: =X33-AA33 -> 0
A34: Graduate Studies | B34: 8470230 | C34: KUST - Graduate Studies | D34: 425550 | E34: Conferences, seminars and exhibitions and other events: - Overseas event | F34: 847.8470230.1.425550.000000.847001.200179 | G34: 16500 | H34: 16500 | I34: 3326.03 | L34: 13173.97 | M34: 847001 | N34: KUST - General | O34: 200179 | P34: FA179-Opex Expense | Q34: 25218 | R34: 25200.26 | S34: 222000 | T34: =S34*0.9 -> 199800 | U34: =S34*0.8 -> 177600 | V34: =S34*0.7 -> 155400 | W34: 222000 | X34: 222000 | Y34: 222000 | Z34: 222000 | AA34: 222000 | AB34: 6178.69 | AC34: 347020.06 | AD34: =S34-Y34 -> 0 | AF34: =W34-Z34 -> 0 | AH34: =X34-AA34 -> 0
A35: Graduate Studies | B35: 8470230 | C35: KUST - Graduate Studies | D35: 425743 | E35: Graduation rewards | F35: 847.8470230.1.425743.000000.847001.200179 | G35: 720000 | H35: 720000 | I35: 720000 | L35: 0 | M35: 847001 | N35: KUST - General | O35: 200179 | P35: FA179-Opex Expense | Q35: 2010000 | R35: 2010000 | S35: 240000 | T35: =S35*0.9 -> 216000 | U35: =S35*0.8 -> 192000 | V35: =S35*0.7 -> 168000 | W35: 0 | X35: 0 | Y35: 240000 | Z35: 0 | AA35: 0 | AB35: 3500875 | AC35: 7340000 | AD35: =S35-Y35 -> 0 | AF35: =W35-Z35 -> 0 | AH35: =X35-AA35 -> 0
A36: Graduate Studies | B36: 8470230 | C36: KUST - Graduate Studies | D36: 425744 | E36: Student medical insurance | F36: 847.8470230.1.425744.000000.847001.200179 | G36: 1 | H36: 1 | L36: 1 | M36: 847001 | N36: KUST - General | O36: 200179 | P36: FA179-Opex Expense | Q36: 1 | R36: 0 | S36: 4816800 | T36: =S36*0.9 -> 4335120 | U36: =S36*0.8 -> 3853440 | V36: =S36*0.7 -> 3371760 | W36: 5724000 | X36: 6107400 | Y36: 4816800 | Z36: 5724000 | AA36: 6107400 | AB36: 4336.82 | AC36: 0 | AD36: =S36-Y36 -> 0 | AF36: =W36-Z36 -> 0 | AH36: =X36-AA36 -> 0
A37: Graduate Studies | B37: 8470230 | C37: KUST - Graduate Studies | D37: 425745 | E37: Student relocation & travel exps | F37: 847.8470230.1.425745.000000.847001.200179 | G37: 1403064 | H37: 1403064 | I37: 632845 | L37: 770219 | M37: 847001 | N37: KUST - General | O37: 200179 | P37: FA179-Opex Expense | Q37: 1899907 | R37: 1706509.4 | S37: 2629904 | T37: =S37*0.9 -> 2366913.6 | U37: =S37*0.8 -> 2103923.2 | V37: =S37*0.7 -> 1840932.8 | W37: 3371287 | X37: 3555424 | Y37: 2629904 | Z37: 3371287 | AA37: 3555424 | AB37: 561661.9 | AC37: 2585908.8 | AD37: =S37-Y37 -> 0 | AF37: =W37-Z37 -> 0 | AH37: =X37-AA37 -> 0
A38: Graduate Studies | B38: 8470230 | C38: KUST - Graduate Studies | D38: 425749 | E38: Postgraduate Student Salaries | F38: 847.8470230.1.425749.000000.847001.200179 | G38: 101999705 | H38: 101999705 | I38: 39527820 | L38: 62471885 | M38: 847001 | N38: KUST - General | O38: 200179 | P38: FA179-Opex Expense | Q38: 22420122 | R38: 22420057 | S38: 168430434 | T38: =S38*0.9 -> 1.5158739e+08 | U38: =S38*0.8 -> 1.3474435e+08 | V38: =S38*0.7 -> 1.179013e+08 | W38: 207120284 | X38: 2.3004481e+08 | Y38: 140817695 | Z38: 155340615 | AA38: 172533615 | AB38: 0 | AC38: 0 | AD38: =S38-Y38 -> 27612739 | AE38: ok | AF38: =W38-Z38 -> 51779669 | AG38: ok | AH38: =X38-AA38 -> 57511197 | AI38: ok
A39: Graduate Studies | B39: 8470230 | C39: KUST - Graduate Studies | D39: 426610 | E39: Computer software licenses | F39: 847.8470230.1.426610.000000.847001.200179 | G39: 8959 | H39: 8959 | L39: 8959 | M39: 847001 | N39: KUST - General | O39: 200179 | P39: FA179-Opex Expense | Q39: 1 | R39: 0 | S39: 10000 | T39: =S39*0.9 -> 9000 | U39: =S39*0.8 -> 8000 | V39: =S39*0.7 -> 7000 | W39: 10000 | X39: 10000 | Y39: 10000 | Z39: 10000 | AA39: 10000 | AB39: 31437.25 | AC39: 0 | AD39: =S39-Y39 -> 0 | AF39: =W39-Z39 -> 0 | AH39: =X39-AA39 -> 0
A40: Graduate Studies | B40: 8470230 | C40: KUST - Graduate Studies | D40: 436110 | E40: Printing supplies | F40: 847.8470230.1.436110.000000.847001.200179 | G40: 5000 | H40: 5000 | L40: 5000 | M40: 847001 | N40: KUST - General | O40: 200179 | P40: FA179-Opex Expense | Q40: 42101 | R40: 42100 | S40: 5000 | T40: =S40*0.9 -> 4500 | U40: =S40*0.8 -> 4000 | V40: =S40*0.7 -> 3500 | W40: 5000 | X40: 5000 | Y40: 5000 | Z40: 5000 | AA40: 5000 | AB40: 1650 | AC40: 1400 | AD40: =S40-Y40 -> 0 | AF40: =W40-Z40 -> 0 | AH40: =X40-AA40 -> 0
...

Sheet Dof 2022 Items Support
A1: Cost Center Code | B1: Cost Center Description | C1: Account Code | D1: Account Description | E1: GL Account Code Combination | F1: Future-1 Description | G1: Future-1 | H1: Future-2 Description | I1: Future-2 | J1: Itemised Details/Calculation method | K1: Quantity (expected) | L1: Rate (expected) | M1: 2022 Budget
A2: 8470110 | B2: KUST - Office of the President | C2: 420570 | D2: Academic Collaborative Partnership Services | E2: =CONCATENATE(847,".",A2,".",1,".",C2,".","000000",".",G2,".",I2) -> 847.8470110.1.420570.000000.847001.200179 | F2: KUST - General | G2: 847001 | H2: FA179-Opex Expense | I2: 200179 | J2: For payments made to collaborating institutions, as part of partnership agreements. This would include a potential affilation partnership for the greaduate school of busineess | K2: 1 | L2: 10000000 | M2: 8000000
A3: 8470230 | B3: KUST - Graduate Studies | C3: 425749 | D3: Postgraduate Student Salaries | E3: =CONCATENATE(847,".",A3,".",1,".",C3,".","000000",".",G3,".",I3) -> 847.8470230.1.425749.000000.847001.200179 | F3: KUST - General | G3: 847001 | H3: FA179-Opex Expense | I3: 200179 | J3: Students Stipend | K3: 1151 | L3: 146334 | M3: 140817695
A4: 8470305 | B4: KUST - Dean Of Engineering | C4: 420550 | D4: Academic Advisory Service | E4: =CONCATENATE(847,".",A4,".",1,".",C4,".","000000",".",G4,".",I4) -> 847.8470305.1.420550.000000.847001.200179 | F4: KUST - General | G4: 847001 | H4: FA179-Opex Expense | I4: 200179 | J4: advisory meeting | K4: 1 | L4: 10000 | M4: 10000
A5: 8470305 | B5: KUST - Dean Of Engineering | C5: 420570 | D5: Academic Collaborative Partnership Services | E5: =CONCATENATE(847,".",A5,".",1,".",C5,".","000000",".",G5,".",I5) -> 847.8470305.1.420570.000000.847001.200179 | F5: KUST - General | G5: 847001 | H5: FA179-Opex Expense | I5: 200179 | J5: local industry partnerships | K5: 1 | L5: 10000 | M5: 10000
