Workbook
Name Catering: Data!$H$2:$H$23
Name CateringCost: Data!$I$2:$I$22
Name InstPayment: Data!$C$2:$C$22
Name Instructor: Data!$A$2:$A$149
Name PMCost: Data!$K$2:$K$22
Name ProductionMaterial: Data!$J$2:$J$22
Name Rank: Data!$B$2:$B$22
Name Stationaries: Data!$D$2:$D$22
Name StationariesCost: Data!$E$2:$E$22
Name Venue: Data!$F$2:$F$22
Name VenueCost: Data!$G$2:$G$23

Sheet Course Calculator
A1: Continuing Education Course Cost Calculation
A2: For Courses Conducted by KU Faculty & Staff
A5: Class Demographics
A6: Select is the course is New or Existing
A7: Course Duration (in days) | B7: 5
G8: Actual Course Cost | I8: =((E15*3.675)+(E23)+E25+E38+E42+E47+E54) -> 43327.574
A9: How many students per class | B9: 20 | G9: Enter as a % of revenue from this course | I9: 30
G10: Course Revenue | I10: =I9/100*((E15*3.675)+(E23)+E25+E38+E42+E47+E54) -> 12998.272
A12: ONE-TIME DEVELOPMENT COSTS | G12: TOTAL COST | I12: =SUM((E15*3.675)+(E23)+I10+E25+E38+E42+E47+E54) -> 56325.846
I13: =I12/3.675 -> 15326.761
A14: Personnel Costs
A15: Total internal labor costs for developing the course | E15: =SUM(C17*D17+C18*D18+C19*D19+C20*D20+C21*D21) -> 3260 | G15: Profit Margin 12% | I15: =I12*12% -> 6759.1015
A16: Instructor | B16: Rank | C16: Days | D16: Rate | E16: =E15*3.675 -> 11980.5 | G16: Total | I16: =I12+I15 -> 63084.948
A17: Please select from list | B17: Basic | C17: =B7 -> 5 | D17: =VLOOKUP(B17,Data!$B$2:$C$6,2,FALSE) -> 652 | G17: Cost per student | I17: =I16/B9 -> 3154.2474
A18: Please select from list | B18: Please select from list | D18: =VLOOKUP(B18,Data!$B$2:$C$6,2,FALSE) -> 0 | I18: =I17/3.675 -> 858.29861
A19: Please select from list | B19: Please select from list | D19: =VLOOKUP(B19,Data!$B$2:$C$6,2,FALSE) -> 0
A20: Please select from list | B20: Please select from list | D20: =VLOOKUP(B20,Data!$B$2:$C$6,2,FALSE) -> 0
A21: Please select from list | B21: Please select from list | D21: =VLOOKUP(B21,Data!$B$2:$C$6,2,FALSE) -> 0
A22: Course Preparation
A23: Revised | C23: =VLOOKUP(A23,Data!$L$2:$M$7,2,FALSE) -> 10087.074 | E23: =SUM(C23) -> 10087.074
A24: Production & Material Costs
A25: Total production & material costs | B25: Quantity | C25: Price | D25: Cost | E25: =SUM(D26:D36) -> 5700
A26: Color Printing | B26: 20 | C26: =VLOOKUP(A26,Data!$J$2:$K$7,2,FALSE)*$B$9*B7 -> 285 | D26: =B26*C26 -> 5700
A27: Please select from list | C27: =VLOOKUP(A27,Data!$J$2:$K$7,2,FALSE)*$B$9 -> 0 | D27: =B27*C27 -> 0
A28: Please select from list | C28: =VLOOKUP(A28,Data!$J$2:$K$7,2,FALSE)*$B$9 -> 0 | D28: =B28*C28 -> 0
A29: Please select from list | C29: =VLOOKUP(A29,Data!$J$2:$K$7,2,FALSE)*$B$9 -> 0 | D29: =B29*C29 -> 0
A30: Please select from list | C30: =VLOOKUP(A30,Data!$J$2:$K$7,2,FALSE)*$B$9 -> 0 | D30: =B30*C30 -> 0
A31: Please select from list | C31: =VLOOKUP(A31,Data!$J$2:$K$7,2,FALSE)*$B$9 -> 0 | D31: =B31*C31 -> 0
A32: Please select from list | C32: =VLOOKUP(A32,Data!$J$2:$K$7,2,FALSE)*$B$9 -> 0 | D32: =B32*C32 -> 0
A33: Please select from list | C33: =VLOOKUP(A33,Data!$J$2:$K$7,2,FALSE)*$B$9 -> 0 | D33: =B33*C33 -> 0
A34: Please select from list | C34: =VLOOKUP(A34,Data!$J$2:$K$7,2,FALSE)*$B$9 -> 0 | D34: =B34*C34 -> 0
A35: Please select from list | C35: =VLOOKUP(A35,Data!$J$2:$K$7,2,FALSE)*$B$9 -> 0 | D35: =B35*C35 -> 0
A36: Please select from list | C36: =VLOOKUP(A36,Data!$J$2:$K$7,2,FALSE)*$B$9 -> 0 | D36: =B36*C36 -> 0
A37: Classroom Cost
A38: Total Classroom Cost | B38: Quantity | E38: =SUM(B39*C39+B40*C40) -> 6000
A39: Large | B39: =$B$7 -> 5 | C39: =VLOOKUP(A39,Data!$F$2:$G$5,2,FALSE) -> 1200 | D39: =B39*C39 -> 6000
A40: Please select from list | C40: =VLOOKUP(A40,Data!$F$2:$G$5,2,FALSE) -> 0 | D40: =B40*C40 -> 0
A41: Catering Costs
A42: Total Catering costs | B42: Quantity | E42: =SUM(B43*C43+B44*C44+B45*C45) -> 8800
A43: In House Breakfast | B43: =B9*B7 -> 100 | C43: =VLOOKUP(A43,Data!$H$2:$I$8,2,FALSE) -> 35 | D43: =B43*C43 -> 3500
...

Sheet Data
A1: Instructor | B1: Rank | C1: Instructor Payment | D1: Stationaries | E1: Stationaries Cost | F1: Venue | G1: Venue Cost | H1: Catering | I1: KU Catering Cost | J1: Production & Material | K1: P&M Cost | L1: Preparation | M1: Prepration Cost
A2: Please select from list | B2: Please select from list | C2: 0 | D2: Please select from list | E2: 0 | F2: Please select from list | G2: 0 | H2: Please select from list | I2: 0 | J2: Please select from list | K2: 0 | L2: Please select from list | M2: 0
A3: Ali Al Sumaiti | B3: Basic | C3: 652 | D3: Flip Chart | E3: 80 | F3: Large | G3: 1200 | H3: In House Breakfast | I3: 35 | J3: Color Printing | K3: 2.85 | L3: New | M3: ='Faculty & Preparation Cost'!H3*'Course Calculator'!B7*6 -> 20174.148
A4: Abukari Idriss | B4: Mid Range | C4: 978 | D4: Notebooks | E4: 10 | F4: Medium | G4: 750 | H4: In House Lunch | I4: 25 | J4: B&W Printing | K4: 1.05 | L4: Revised | M4: ='Faculty & Preparation Cost'!H3*'Course Calculator'!B7*3 -> 10087.074
A5: Aldo Vesnaver | B5: Medical Course | C5: 1304 | D5: Pens | E5: 5 | F5: Small | G5: 500 | H5: In House Coffee Breaks | I5: 25 | J5: Video Taping | K5: 145 | L5: Existing | M5: ='Faculty & Preparation Cost'!H3*'Course Calculator'!B7 -> 3362.358
A6: Arafat Al Dweik | B6: Coordinator | C6: 100 | D6: Pencil | E6: 5 | H6: Outside Breakfast | I6: 20 | J6: Computers | K6: 100
A7: Ameena Al Sumaiti | D7: Marker 12pc | E7: 60 | H7: Outside Lunch vouchers | I7: 28 | J7: Extra Projector | K7: 100
A8: Bisweswar Ghosh | D8: A4 Divider | E8: 5 | H8: Outside Coffee Breaks | I8: 20
A9: Clarence Rorigues | D9: Posters | E9: 190
A10: Guo Tao | D10: Banners | E10: 100
A11: Ernesto Damiani | D11: Binding | E11: 25
A12: Hadi Belhaj | D12: A4 Folders | E12: 15
A13: Igor Boiko
A14: Jorge Gomes
A15: John Williams
A16: Jonathan Hujo
A17: Jaby Mohammed
A18: Jeyalal Jeyaseelan
A19: Mahmoud Meribout
A20: Mohammed Motiur Rahman
A21: Mohammed Ali
A22: Mimoune Kissami
A23: Navaz Kannu
A24: Rodney Simmons
... A30: Youcef Bouzidi

Sheet Faculty & Preparation Cost
A1: Rank | B1: Average gross salary | C1: Cost Per 22 Days | D1: Instructor Payment Per Day ($) | E1: Instructor Payment Per Day (AED) | F1: Total Instructor Cost Per Day | G1: Total Instructor Cost Per Day ($) | H1: Total Instructor Cost Per Hour | I1: Total Instructor Cost Per Hour ($)
A2: Full Professor | B2: 98748 | C2: =B2/22 -> 4488.5455 | D2: 640 | E2: 2350 | F2: =C2+E2 -> 6838.5455 | G2: =F2/3.675 -> 1860.8287 | H2: =F2/8 -> 854.81818 | I2: =G2/8 -> 232.60359
A3: Associate Professor | B3: 81505 | C3: =B3/22 -> 3704.7727 | D3: 455 | E3: 1675 | F3: =C3+E3 -> 5379.7727 | G3: =F3/3.675 -> 1463.8837 | H3: =F3/8 -> 672.47159 | I3: =G3/8 -> 182.98547
A4: Assistant Professor | B4: 67633 | C4: =B4/22 -> 3074.2273 | D4: 320 | E4: 1180 | F4: =C4+E4 -> 4254.2273 | G4: =F4/3.675 -> 1157.6129 | H4: =F4/8 -> 531.77841 | I4: =G4/8 -> 144.70161
