Workbook

Sheet Summary
B2: Chapter | C2: FINAL 2018 BUDGET | D2: 2018 STRATEGIC INITIATIVE/NEW PROJECT BUDGET | E2: 2017 KUSTAR Approved budget | F2: 2016 KUSTAR Actuals | G2: 2015 KUSTAR Actuals | H2: 2017 MASDAR Approved budget | I2: 2016 MASDAR Actuals | J2: 2015 MASDAR Actuals | K2: 2017 PI Approved budget | L2: 2016 PI Actuals | M2: 2015 PI Actuals
B6: Operating | C6: ='Operating consolidated'!F95 -> 14101933 | D6: ='Operating consolidated'!G95 -> 0 | E6: ='Operating consolidated'!I95 -> 3445000 | F6: ='Operating consolidated'!J95 -> 3193129.2 | G6: ='Operating consolidated'!K95 -> 3444048.9 | H6: ='Operating consolidated'!M95 -> 5204000 | I6: ='Operating consolidated'!N95 -> 4048133.4 | J6: ='Operating consolidated'!O95 -> 3844497.2 | K6: ='Operating consolidated'!Q95 -> 7700781 | L6: ='Operating consolidated'!R95 -> 3723110.4 | M6: ='Operating consolidated'!S95 -> 10929388
B8: Capital | C8: ='Capital consolidated'!G54 -> 0 | D8: ='Capital consolidated'!H54 -> 0 | E8: ='Capital consolidated'!J54 -> 0 | F8: ='Capital consolidated'!K54 -> 6638 | G8: ='Capital consolidated'!L54 -> 2500 | H8: ='Capital consolidated'!N54 -> 0 | I8: ='Capital consolidated'!O54 -> 0 | J8: ='Capital consolidated'!P54 -> 0 | K8: ='Capital consolidated'!R54 -> 0 | L8: ='Capital consolidated'!S54 -> 0 | M8: ='Capital consolidated'!T54 -> 0
B10: Total | C10: =SUM(C6:C9) -> 14101933 | D10: =SUM(D6:D9) -> 0 | E10: =SUM(E6:E9) -> 3445000 | F10: =SUM(F6:F9) -> 3199767.2 | G10: =SUM(G6:G9) -> 3446548.9 | H10: =SUM(H6:H9) -> 5204000 | I10: =SUM(I6:I9) -> 4048133.4 | J10: =SUM(J6:J9) -> 3844497.2 | ... M10: =SUM(M6:M9) -> 10929388

Sheet Operating consolidated
B1: DOF system | D1: Remark | E1: Content expert | F1: FINAL 2018 BUDGET | G1: 2018 STRATEGIC INITIATIVE/NEW PROJECT BUDGET | I1: 2017 KUSTAR Approved budget | J1: 2016 KUSTAR Actuals | K1: 2015 KUSTAR Actuals | M1: 2017 MASDAR Approved budget | N1: 2016 MASDAR Actuals | O1: 2015 MASDAR Actuals | Q1: 2017 PI Approved budget | R1: 2016 PI Actuals | S1: 2015 PI Actuals
B2: Account code | C2: Description
A4: Academic | B4: 420550 | C4: Academic Advisory Service | D4: For expenses related to Academic boards, including Presidents Academic Advisory Council. This includes travel cost, accommodation and honorarium. | I4: 0 | J4: 0 | K4: 0 | Q4: 0 | R4: 0 | S4: 0
B5: 420570 | C5: Academic Collaborative Partnership Services | D5: For payments made to collaborating institutions, as part of partnership agreements. Does not include fund contributions (ARIC, EBTIC etc.) | I5: 0 | J5: 0 | K5: 0 | Q5: 0 | R5: 0 | S5: 0
B6: 421700 | C6: Standards certification (e.g. ISO) | D6: For all expenses connected to accreditations ( academic and otherwise) | I6: 0 | J6: 0 | K6: 0 | Q6: 0 | R6: 0 | S6: 0
B7: 425770 | C7: Academic Missions - Combined expenses | D7: For faculty conferences (local and international). This includes travel costs, per diem & registration fees) | I7: 11000 | J7: 0 | K7: 0 | Q7: -111696.28 | R7: -54002 | S7: 183941
B8: 432209 | C8: Lab Equipment | D8: Costs for maintaining lab equipment (academic labs & research labs). This does not include maintenance of IT hardware and peripherals. | I8: 0 | J8: 0 | K8: 0 | Q8: 66187.935 | R8: 32000 | S8: 1840
B9: 435310 | C9: Newspapers, magazines, journals, etc | D9: This includes library subscriptions of journals & magazines. This also includes newspaper subscriptions. This account does not include cost of hard copies of library books. | F9: =(I9+M9+Q9+M53)*0.95 -> 10401624 | I9: 3334000 | J9: 3051332.3 | K9: 3354945 | M9: 11000 | O9: 11571.14 | Q9: 3743077.7 | R9: 1809672.5 | S9: 7558547.8
B10: 435330 | C10: Library books | D10: Only for costs of library books ( hard bound copies) | F10: =(I10+M10+Q10)*0.95 -> 3455308.8 | I10: 0 | J10: 0 | K10: 0 | M10: 44000 | N10: 14998.89 | O10: 35891.3 | Q10: 3593167.2 | R10: 1737195 | S10: 3055123.9
B11: 435350 | C11: Academic Publications | D11: For publication costs of faculty journals only | I11: 0 | J11: 0 | K11: 0 | Q11: 0 | R11: 0 | S11: 0
B12: 435508 | C12: Laboratory - Scientific | D12: Lab supplies/ consumables for academic and research labs | I12: 0 | J12: 0 | K12: 0 | Q12: 75648.777 | R12: 36574.05 | S12: 35038
B13: 436600 | C13: Training/Teaching equipment and other educational aid | D13: This account is for teaching supplies/ consumables to be used specifically in classrooms. This does not include the cost of regular stationery, provided by the University. | I13: 0 | J13: 0 | K13: 0 | Q13: 0 | R13: 0 | S13: 0
B14: 435530 | C14: School consumables, not specifically mentioned elsewhere | D14: This is for costs connected with developing curriculum. This would include payments made to those who develop the curriculum. | I14: 0 | J14: 0 | K14: 0 | Q14: 0 | R14: 0 | S14: 0
A15: External Relations | B15: 425100 | C15: Advertising | D15: This includes all costs connected with advertisement of the University . This excludes media & communication expenses like press meets. | E15: Communication | I15: 0 | J15: 0 | K15: 0 | Q15: 0 | R15: 0 | S15: 0
B16: 425510 | C16: Conferences, seminars and exhibitions and other events: - Local Events | D16: Includes all expenses connected with event expenses hosted/participated in UAE. Does not include faculty conferences. | E16: Communication | F16: 50000 | I16: 4000 | J16: 1100 | K16: 0 | Q16: 0 | R16: 0 | S16: 0
B17: 425550 | C17: Conferences, seminars and exhibitions and other events: - Overseas event | D17: Includes all expenses connected with event expenses hosted/participated outside UAE. Does not include faculty conferences. | E17: Communication | I17: 0 | J17: 0 | K17: 0 | Q17: 0 | R17: 0 | S17: 0
B18: 427100 | C18: Public relations | D18: For media & communication expenses ( example press meets) | E18: Communication | I18: 0 | J18: 0 | K18: 0 | Q18: 0 | R18: 0 | S18: 0
B19: 428640 | C19: Events - Awards, prizes & gifts | D19: For costs of gifts including those for VIP guests (excluding those given as part of an event expense) | E19: Communication | I19: 0 | J19: 0 | K19: 0 | Q19: 0 | R19: 0 | S19: 0
B20: 435519 | C20: Photography - Consumable materials /Tools | D20: Includes costs connected with photography (still and video) | E20: Communication | I20: 0 | J20: 0 | K20: 0 | Q20: 0 | R20: 0 | S20: 0
B21: 427200 | C21: Printing and publishing | D21: For costs connected with University wide publication expenses | E21: Communication | I21: 0 | J21: 0 | K21: 0 | Q21: 0 | R21: 0 | S21: 0
A22: Facilities | B22: 420310 | C22: Cleaning and Security Services :Business premises | D22: This is for cleaning costs of University buildings, premises and hostels. Does not include security services | E22: Facilities | I22: 0 | J22: 0 | K22: 0 | Q22: 0 | R22: 0 | S22: 0
B23: 421600 | C23: Security service | D23: This is for security costs of University buildings, premises and hostels. Does not include cleaning services | I23: 0 | J23: 0 | K23: 0 | Q23: 0 | R23: 0 | S23: 0
B24: 422100 | C24: Waste management service | D24: This is for costs incurred for managing the wastes of the University, including laboratory waste materials | I24: 0 | J24: 0 | K24: 0 | Q24: 0 | R24: 0 | S24: 0
B25: 426210 | C25: Insurance - Cash and fidelity | D25: Cost for providing cash and fidelity insurance | I25: 0 | J25: 0 | K25: 0 | Q25: 0 | R25: 0 | S25: 0
B26: 426220 | C26: Insurance - Fire and allied perils | D26: Cost for providing fire insurance | I26: 0 | J26: 0 | K26: 0 | Q26: 0 | R26: 0 | S26: 0
B27: 426250 | C27: Insurance - Motor vehicles | D27: Cost for providing vehicle insurance | I27: 0 | J27: 0 | K27: 0 | Q27: 0 | R27: 0 | S27: 0
B28: 426290 | C28: Insurance - Other | D28: Cost for providing insurance, not covered in other insurance account lines ( example all risk insurance) | I28: 0 | J28: 0 | K28: 0 | Q28: 0 | R28: 0 | S28: 0
B29: 426800 | C29: Motor vehicle registration and inspection charges | D29: For vehicle running expenses, including Salik charges/Mawaqif and excluding car maintenance & fuel | I29: 0 | J29: 0 | K29: 0 | Q29: 0 | R29: 0 | S29: 0
B30: 428111 | C30: Electricity consumption charges | D30: Electricity charges for University buildings, premises and hostels | I30: 0 | J30: 0 | K30: 0 | Q30: 0 | R30: 0 | S30: 0
B31: 428112 | C31: Water consumption charges | D31: Water charges for University buildings, premises and hostels | I31: 0 | J31: 0 | K31: 0 | Q31: 0 | R31: 0 | S31: 0
B32: 428200 | C32: Health,safety&environment awareness | D32: Costs connected to environment, health & safety | F32: 0 | I32: 0 | J32: 0 | K32: 0 | Q32: 38754.07 | R32: 18736.5 | S32: 59220
B33: 430120 | C33: Rental - Buildings, other than staff residences | D33: Charges to rent buildings or premises, for the University's purposes. This does not include booth space rentals at exhibitions or conferences | I33: 0 | J33: 0 | K33: 0 | Q33: 0 | R33: 0 | S33: 0
B34: 430330 | C34: Rental - Motor vehicles | D34: This includes vehicle hire expenses, taxi charges and other transportation expenses | E34: Facilities | I34: 0 | J34: 0 | K34: 0 | Q34: 0 | R34: 0 | S34: 0
B35: 430930 | C35: Rental - Training facilities (includes premises, equipment, catering, etc) | D35: For lab usage fees | E35: Facilities | I35: 0 | J35: 0 | K35: 0 | Q35: 0 | R35: 0 | S35: 0
B36: 432120 | C36: Bldg maintenance-Business premises | D36: For maintenance charges of University & hostel buildings/lifts/CCTV, including annual maintenance contracts. | E36: Facilities | I36: 0 | J36: 0 | K36: 0 | Q36: 0 | R36: 0 | S36: 0
B37: 432170 | C37: Bldg decoration & minor improvements | D37: For building décor expenses and minor improvements that are not capital in nature. | E37: Facilities | I37: 0 | J37: 0 | K37: 0 | Q37: 0 | R37: 0 | S37: 0
B38: 432310 | C38: Office Furniture and fixtures | D38: Maintaining and refurbishing costs of University furniture, excluding hostels | E38: Facilities | I38: 0 | J38: 0 | K38: 0 | Q38: 0 | R38: 0 | S38: 0
B39: 432320 | C39: Residential Furniture and fixtures | D39: Maintaining and refurbishing costs of hostel furniture. | I39: 0 | J39: 0 | K39: 0 | Q39: 0 | R39: 0 | S39: 0
B40: 432540 | C40: Motor vehicles (non-military) | D40: Car maintenance expenses | I40: 0 | J40: 0 | K40: 0 | Q40: 0 | R40: 0 | S40: 0
B41: 435510 | C41: Landscaping and other horticulture | D41: Landscaping charges for the University buildings and premises | I41: 0 | J41: 0 | K41: 0 | Q41: 0 | R41: 0 | S41: 0
...

Sheet Itemized detail
A2: Account Code | B2: Account Description | C2: Itemised Details/Calculation method | D2: Quantity (expected) | E2: Rate (expected) | F2: Budget expected | G2: Content Expert
A4: 432120 | B4: Bldg maintenance-Business premises | G4: Facilities
F5: =D5*E5 -> 0
F6: =D6*E6 -> 0
F7: =D7*E7 -> 0
F8: =D8*E8 -> 0
F9: =D9*E9 -> 0
F10: =D10*E10 -> 0
F11: =D11*E11 -> 0
F12: =D12*E12 -> 0
F13: =D13*E13 -> 0
F14: =D14*E14 -> 0
F15: =D15*E15 -> 0
A18: Account Code | B18: Account Description | C18: Itemised Details/Calculation method | D18: Quantity (expected) | E18: Rate (expected) | F18: Budget expected | G18: Content Expert
A20: 428111 & 428112 | B20: Water & Electricity - offices | G20: Facilities
F21: =D21*E21 -> 0
F22: =D22*E22 -> 0
F23: =D23*E23 -> 0
F24: =D24*E24 -> 0
F25: =D25*E25 -> 0
F26: =D26*E26 -> 0
F27: =D27*E27 -> 0
F28: =D28*E28 -> 0
F29: =D29*E29 -> 0
F30: =D30*E30 -> 0
F31: =D31*E31 -> 0
A36: Account Code | B36: Account Description | C36: Itemised Details/Calculation method | D36: Quantity (expected) | E36: Rate (expected) | F36: Budget expected | G36: Content Expert
A38: 432170 | B38: Bldg decoration & minor improvements | F38: =D38*E38 -> 0 | G38: Facilities
F39: =D39*E39 -> 0
F40: =D40*E40 -> 0
F41: =D41*E41 -> 0
F42: =D42*E42 -> 0
F43: =D43*E43 -> 0
F44: =D44*E44 -> 0
F45: =D45*E45 -> 0
F46: =D46*E46 -> 0
F47: =D47*E47 -> 0
F48: =D48*E48 -> 0
A53: Account Code | B53: Account Description | C53: Itemised Details/Calculation method | D53: Quantity (expected) | E53: Rate (expected) | F53: Budget expected | G53: Content Expert
A55: 425746 | B55: Student Transport | F55: =D55*E55 -> 0 | G55: Student Services
...

Sheet Capital consolidated
A6: Asset Category | B6: Description | C6: Purpose | D6: Qty. | E6: Unit Cost | F6: Month Of Purchase | G6: 2018 Budget | H6: 2018 STRATEGIC INITIATIVE/NEW PROJECT BUDGET | J6: 2017 KUSTAR Approved Budget | K6: 2016 KUSTAR Actuals | L6: 2015 KUSTAR Actuals | N6: 2017 MASDAR Approved Budget | O6: 2016 MASDAR Actuals | P6: 2015 MASDAR Actuals | R6: 2017 PI Approved Budget | S6: 2016 PI Actuals | T6: 2015 PI Actuals
A7: GENERAL EQUIPMENT
A8: Plant & Machinery
A13: Office Equipment
A17: Teaching Equipment
A21: Lab. Equipment | L21: 2500
A24: Research Equipment
A26: Sub-total | G26: =SUM(G8:G25) -> 0 | H26: =SUM(H8:H25) -> 0 | J26: =SUM(J8:J25) -> 0 | K26: =SUM(K8:K25) -> 0 | L26: =SUM(L8:L25) -> 2500 | N26: =SUM(N8:N25) -> 0 | O26: =SUM(O8:O25) -> 0 | P26: =SUM(P8:P25) -> 0 | R26: =SUM(R8:R25) -> 0 | S26: =SUM(S8:S25) -> 0 | T26: =SUM(T8:T25) -> 0
A27: FURN. & FIXTURES
A36: IT EQUIPMENT
A37: Computer Hardware
A41: Computer Software | K41: 6638
A46: Sub-total | G46: =SUM(G27:G45) -> 0 | H46: =SUM(H27:H45) -> 0 | J46: =SUM(J27:J45) -> 0 | K46: =SUM(K27:K45) -> 6638 | L46: =SUM(L27:L45) -> 0 | N46: =SUM(N27:N45) -> 0 | O46: =SUM(O27:O45) -> 0 | P46: =SUM(P27:P45) -> 0 | R46: =SUM(R27:R45) -> 0 | S46: =SUM(S27:S45) -> 0 | T46: =SUM(T27:T45) -> 0
A47: VEHICLES
A49: BUILDINGS
A50: New Buildings
A51: Building Improvements
A52: Sub-total | G52: =SUM(G47:G51) -> 0 | H52: =SUM(H47:H51) -> 0 | J52: =SUM(J47:J51) -> 0 | K52: =SUM(K47:K51) -> 0 | L52: =SUM(L47:L51) -> 0 | N52: =SUM(N47:N51) -> 0 | O52: =SUM(O47:O51) -> 0 | P52: =SUM(P47:P51) -> 0 | R52: =SUM(R47:R51) -> 0 | S52: =SUM(S47:S51) -> 0 | T52: =SUM(T47:T51) -> 0
A54: Grand Total | G54: =G26+G46+G52 -> 0 | H54: =H26+H46+H52 -> 0 | J54: =J26+J46+J52 -> 0 | K54: =K26+K46+K52 -> 6638 | L54: =L26+L46+L52 -> 2500 | N54: =N26+N46+N52 -> 0 | O54: =O26+O46+O52 -> 0 | P54: =P26+P46+P52 -> 0 | R54: =R26+R46+R52 -> 0 | S54: =S26+S46+S52 -> 0 | T54: =T26+T46+T52 -> 0
A57: * Itemised details are required along with budgetary quotations
