Workbook

Sheet Summary
A3: Row Labels | B3: Count of Request no. | C3: Sum of Transfer Amount
A4: Chapter 1 | B4: 60 | C4: 74290819
A5: Chapter 2 | B5: 75 | C5: 85864732
A6: Chapter 3 | B6: 19 | C6: 22648979
A7: Grand Total | B7: 154 | C7: 182804530

Sheet 1 to 5
A1: Request no. | B1: Transfer Amount | C1: Requested By | D1: Requested Date | E1: Approved or Rejected By | F1: Approved Date | G1: Transfer Status | H1: Chapter
A2: IT-0001 | B2: 614406 | C2: Eiman Al Khoori (ku100041915) | D2: 44950 | E2: Abdulla Ali Al Mansoori (kupi4099) | F2: 44950 | G2: Approved | H2: =_xlfn.XLOOKUP(A2,'6 to 37'!B:B,'6 to 37'!A:A) -> Chapter 1
A3: IT-0002 | B3: 310000 | C3: Eiman Al Khoori (ku100041915) | D3: 44950 | E3: Abdulla Ali Al Mansoori (kupi4099) | F3: 44950 | G3: Approved | H3: =_xlfn.XLOOKUP(A3,'6 to 37'!B:B,'6 to 37'!A:A) -> Chapter 3
A4: IT-0003 | B4: 63776 | C4: Eiman Al Khoori (ku100041915) | D4: 44953 | E4: Abdulla Ali Al Mansoori (kupi4099) | F4: 44956 | G4: Approved | H4: =_xlfn.XLOOKUP(A4,'6 to 37'!B:B,'6 to 37'!A:A) -> Chapter 1
A5: IT-0004 | B5: 64000 | C5: Eiman Al Khoori (ku100041915) | D5: 44957 | E5: Abdulla Ali Al Mansoori (kupi4099) | F5: 44957 | G5: Approved | H5: =_xlfn.XLOOKUP(A5,'6 to 37'!B:B,'6 to 37'!A:A) -> Chapter 1
A6: IT-0005 | B6: 779574 | C6: Eiman Al Khoori (ku100041915) | D6: 44960 | E6: Abdulla Ali Al Mansoori (kupi4099) | F6: 44960 | G6: Approved | H6: =_xlfn.XLOOKUP(A6,'6 to 37'!B:B,'6 to 37'!A:A) -> Chapter 2
A7: IT-0006 | B7: 121000 | C7: Eiman Al Khoori (ku100041915) | D7: 44960 | E7: Abdulla Ali Al Mansoori (kupi4099) | F7: 44960 | G7: Approved | H7: =_xlfn.XLOOKUP(A7,'6 to 37'!B:B,'6 to 37'!A:A) -> Chapter 3
A8: IT-0007 | B8: 400000 | C8: Eiman Al Khoori (ku100041915) | D8: 44960 | E8: Abdulla Ali Al Mansoori (kupi4099) | F8: 44960 | G8: Approved | H8: =_xlfn.XLOOKUP(A8,'6 to 37'!B:B,'6 to 37'!A:A) -> Chapter 1
A9: IT-0008 | B9: 6602331 | C9: Eiman Al Khoori (ku100041915) | D9: 44965 | E9: Abdulla Ali Al Mansoori (kupi4099) | F9: 44965 | G9: Approved | H9: =_xlfn.XLOOKUP(A9,'6 to 37'!B:B,'6 to 37'!A:A) -> Chapter 2
A10: IT-0009 | B10: 897671 | C10: Eiman Al Khoori (ku100041915) | D10: 44971 | E10: Abdulla Ali Al Mansoori (kupi4099) | F10: 44971 | G10: Approved | H10: =_xlfn.XLOOKUP(A10,'6 to 37'!B:B,'6 to 37'!A:A) -> Chapter 2
A11: IT-0010 | B11: 74540 | C11: Eiman Al Khoori (ku100041915) | D11: 44971 | E11: Abdulla Ali Al Mansoori (kupi4099) | F11: 44971 | G11: Approved | H11: =_xlfn.XLOOKUP(A11,'6 to 37'!B:B,'6 to 37'!A:A) -> Chapter 1
A12: IT-0011 | B12: 313980 | C12: Eiman Al Khoori (ku100041915) | D12: 44971 | E12: Abdulla Ali Al Mansoori (kupi4099) | F12: 44971 | G12: Approved | H12: =_xlfn.XLOOKUP(A12,'6 to 37'!B:B,'6 to 37'!A:A) -> Chapter 3
A13: IT-0012 | B13: 3967 | C13: Eiman Al Khoori | D13: 44974 | E13: Abdulla Ali Al Mansoori | F13: 44976 | G13: Approved | H13: =_xlfn.XLOOKUP(A13,'6 to 37'!B:B,'6 to 37'!A:A) -> Chapter 2
... A124: IT-0126 | B124: 300000 | C124: Fatima Almazrooei | D124: 45155 | E124: Abdulla Ali Al Mansoori | F124: 45155 | G124: Approved | H124: =_xlfn.XLOOKUP(A124,'6 to 37'!B:B,'6 to 37'!A:A) -> Chapter 2
A125: IT-0127 | B125: 60245 | C125: Fatima Almazrooei | D125: 45160 | E125: Abdulla Ali Al Mansoori | F125: 45160 | G125: Approved | H125: Chapter 1
A126: IT-0128 | B126: 136750 | C126: Fatima Almazrooei | D126: 45160 | E126: Abdulla Ali Al Mansoori | F126: 45160 | G126: Approved | H126: Chapter 1
A127: IT-0129 | B127: 497902 | C127: Fatima Almazrooei | D127: 45161 | E127: Abdulla Ali Al Mansoori | F127: 45161 | G127: Approved | H127: Chapter 1
A128: IT-0130 | B128: 174228 | C128: Fatima Almazrooei | D128: 45163 | E128: Abdulla Ali Al Mansoori | F128: 45163 | G128: Approved | H128: Chapter 1
A129: IT-0131 | B129: 133220 | C129: Fatima Almazrooei | D129: 45163 | E129: Abdulla Ali Al Mansoori | F129: 45163 | G129: Approved | H129: Chapter 1
A130: IT-0132 | B130: 1562000 | C130: Fatima Almazrooei | D130: 45163 | E130: Abdulla Ali Al Mansoori | F130: 45163 | G130: Approved | H130: =_xlfn.XLOOKUP(A130,'6 to 37'!B:B,'6 to 37'!A:A) -> Chapter 2
A131: IT-0133 | B131: 279417 | C131: Fatima Almazrooei | D131: 45163 | E131: Abdulla Ali Al Mansoori | F131: 45165 | G131: Approved | H131: =_xlfn.XLOOKUP(A131,'6 to 37'!B:B,'6 to 37'!A:A) -> Chapter 2
A132: IT-0134 | B132: 218842 | C132: Fatima Almazrooei | D132: 45166 | E132: Abdulla Ali Al Mansoori | F132: 45166 | G132: Approved | H132: =_xlfn.XLOOKUP(A132,'6 to 37'!B:B,'6 to 37'!A:A) -> Chapter 1
A133: IT-0135 | B133: 1100000 | C133: Fatima Almazrooei | D133: 45166 | E133: Abdulla Ali Al Mansoori | F133: 45167 | G133: Approved | H133: =_xlfn.XLOOKUP(A133,'6 to 37'!B:B,'6 to 37'!A:A) -> Chapter 1
A134: IT-0136 | B134: 50473 | C134: Eiman Al Khoori | D134: 45169 | E134: Abdulla Ali Al Mansoori | F134: 45169 | G134: Approved | H134: =_xlfn.XLOOKUP(A134,'6 to 37'!B:B,'6 to 37'!A:A) -> Chapter 2
A135: IT-0137 | B135: 968921 | C135: Eiman Al Khoori | D135: 45176 | E135: Abdulla Ali Al Mansoori | F135: 45176 | G135: Approved | H135: =_xlfn.XLOOKUP(A135,'6 to 37'!B:B,'6 to 37'!A:A) -> Chapter 2
A136: IT-0138 | B136: 1367375 | C136: Eiman Al Khoori | D136: 45174 | E136: Abdulla Ali Al Mansoori | F136: 45174 | G136: Approved | H136: =_xlfn.XLOOKUP(A136,'6 to 37'!B:B,'6 to 37'!A:A) -> Chapter 2
A137: IT-0139 | B137: 300000 | C137: Eiman Al Khoori | D137: 45187 | E137: Abdulla Ali Al Mansoori | F137: 45187 | G137: Approved | H137: =_xlfn.XLOOKUP(A137,'6 to 37'!B:B,'6 to 37'!A:A) -> Chapter 1
A138: IT-0140 | B138: 329868 | C138: Eiman Al Khoori | D138: 45176 | E138: Abdulla Ali Al Mansoori | F138: 45176 | G138: Approved | H138: =_xlfn.XLOOKUP(A138,'6 to 37'!B:B,'6 to 37'!A:A) -> Chapter 1
A139: IT-0141 | B139: 16657 | C139: Eiman Al Khoori | D139: 45181 | E139: Abdulla Ali Al Mansoori | F139: 45181 | G139: Approved | H139: =_xlfn.XLOOKUP(A139,'6 to 37'!B:B,'6 to 37'!A:A) -> Chapter 3
A140: IT-0142 | B140: 472500 | C140: Eiman Al Khoori | D140: 45181 | E140: Abdulla Ali Al Mansoori | F140: 45181 | G140: Approved | H140: =_xlfn.XLOOKUP(A140,'6 to 37'!B:B,'6 to 37'!A:A) -> Chapter 2
A141: IT-0143 | B141: 408000 | C141: Eiman Al Khoori | D141: 45187 | E141: Abdulla Ali Al Mansoori | F141: 45187 | G141: Approved | H141: =_xlfn.XLOOKUP(A141,'6 to 37'!B:B,'6 to 37'!A:A) -> Chapter 2
... A153: IT-0155 | B153: 1099151 | C153: Fatima Almazrooei | D153: 45205 | E153: Abdulla Ali Al Mansoori | F153: 45205 | G153: Approved | H153: =_xlfn.XLOOKUP(A153,'6 to 37'!B:B,'6 to 37'!A:A) -> Chapter 2
A154: IT-0156 | B154: 153256 | D154: 45205 | E154: Abdulla Ali Al Mansoori | F154: 45205 | G154: Approved | H154: =_xlfn.XLOOKUP(A154,'6 to 37'!B:B,'6 to 37'!A:A) -> Chapter 1
A155: IT-0157 | B155: 727000 | C155: Fatima Almazrooei | D155: 45205 | E155: Abdulla Ali Al Mansoori | F155: 45205 | G155: Approved | H155: =_xlfn.XLOOKUP(A155,'6 to 37'!B:B,'6 to 37'!A:A) -> Chapter 3

Sheet Sheet4
A1: Chapter | B1: (All)
A3: Row Labels | B3: Sum of Source. | C3: Sum of Target.
A4: IT-0114 | B4: 50737204 | C4: 50737204 | E4: =B4=C4 -> TRUE
A5: IT-0018 | B5: 14000000 | C5: 14000000 | E5: =B5=C5 -> TRUE
A6: IT-0050 | B6: 6660168 | C6: 6660168 | E6: =B6=C6 -> TRUE
A7: IT-0008 | B7: 6602331 | C7: 6602331 | E7: =B7=C7 -> TRUE
A8: IT-0116 | B8: 5658128 | C8: 5658128 | E8: =B8=C8 -> TRUE
A9: IT-0106 | B9: 5497623 | C9: 5497623 | E9: =B9=C9 -> TRUE
A10: IT-0022 | B10: 4942000 | C10: 4942000 | E10: =B10=C10 -> TRUE
A11: IT-0032 | B11: 4200000 | C11: 4200000 | E11: =B11=C11 -> TRUE
A12: IT-0064 | B12: 3170270 | C12: 3170270 | E12: =B12=C12 -> TRUE
A13: IT-0030 | B13: 3154833 | C13: 3154833 | E13: =B13=C13 -> TRUE
A14: IT-0025 | B14: 3133861 | C14: 3133861 | E14: =B14=C14 -> TRUE
A15: IT-0061 | B15: 2553851 | C15: 2553851 | E15: =B15=C15 -> TRUE
... A151: IT-0021 | B151: 1 | C151: 1 | E151: =B151=C151 -> TRUE
A152: IT-0134 | C152: 68417 | E152: =B152=C152 -> FALSE
A153: Grand Total | B153: 180767952 | C153: 181036369
C155: =B153-C153 -> -268417

Sheet 6 to 37
A1: Chapter | B1: Transfer Code | C1: Cost Center | D1: Future1 | E1: Future2 | F1: Budget Category | G1: Accounts | H1: Source. | I1: Target.
A2: Chapter 1 | B2: IT-0001 | C2: D8470415 | D2: F847001 | E2: FA178 | F2: BC1 | G2: A412121 | H2: 167708 | J2: =VLOOKUP(B2,'[1]Testing sheet'!$A:$A,1,0) -> #N/A
A3: Chapter 1 | B3: IT-0001 | C3: D8470415 | D3: F847001 | E3: FA178 | F3: BC1 | G3: A414120 | I3: 167708 | J3: =VLOOKUP(B3,'[1]Testing sheet'!$A:$A,1,0) -> #N/A
A4: Chapter 1 | B4: IT-0001 | C4: D8470730 | D4: F847001 | E4: FA178 | F4: BC1 | G4: A412121 | H4: 10000 | J4: =VLOOKUP(B4,'[1]Testing sheet'!$A:$A,1,0) -> #N/A
A5: Chapter 1 | B5: IT-0001 | C5: D8471140 | D5: F847001 | E5: FA178 | F5: BC1 | G5: A412121 | H5: 328170 | J5: =VLOOKUP(B5,'[1]Testing sheet'!$A:$A,1,0) -> #N/A
A6: Chapter 1 | B6: IT-0001 | C6: D8471140 | D6: F847001 | E6: FA178 | F6: BC1 | G6: A413710 | I6: 10000 | J6: =VLOOKUP(B6,'[1]Testing sheet'!$A:$A,1,0) -> #N/A
A7: Chapter 1 | B7: IT-0001 | C7: D8471140 | D7: F847001 | E7: FA178 | F7: BC1 | G7: A414120 | I7: 328170 | J7: =VLOOKUP(B7,'[1]Testing sheet'!$A:$A,1,0) -> #N/A
A8: Chapter 1 | B8: IT-0001 | C8: D8471150 | D8: F847001 | E8: FA178 | F8: BC1 | G8: A412121 | H8: 108528 | J8: =VLOOKUP(B8,'[1]Testing sheet'!$A:$A,1,0) -> #N/A
A9: Chapter 1 | B9: IT-0001 | C9: D8471150 | D9: F847001 | E9: FA178 | F9: BC1 | G9: A414120 | I9: 108528 | J9: =VLOOKUP(B9,'[1]Testing sheet'!$A:$A,1,0) -> #N/A
A10: Chapter 1 | B10: IT-0003 | C10: D8470140 | D10: F847001 | E10: FA178 | F10: BC1 | G10: A412121 | H10: 63776 | J10: =VLOOKUP(B10,'[1]Testing sheet'!$A:$A,1,0) -> #N/A
A11: Chapter 1 | B11: IT-0003 | C11: D8471140 | D11: F847001 | E11: FA178 | F11: BC1 | G11: A414120 | I11: 63776 | J11: =VLOOKUP(B11,'[1]Testing sheet'!$A:$A,1,0) -> #N/A
A12: Chapter 1 | B12: IT-0004 | C12: D8471140 | D12: F847001 | E12: FA178 | F12: BC1 | G12: A412121 | H12: 64000 | J12: =VLOOKUP(B12,'[1]Testing sheet'!$A:$A,1,0) -> #N/A
A13: Chapter 1 | B13: IT-0004 | C13: D8471140 | D13: F847001 | E13: FA178 | F13: BC1 | G13: A414120 | I13: 64000 | J13: =VLOOKUP(B13,'[1]Testing sheet'!$A:$A,1,0) -> #N/A
A14: Chapter 1 | B14: IT-0007 | C14: D8471305 | D14: F847001 | E14: FA178 | F14: BC1 | G14: A412121 | H14: 400000 | J14: =VLOOKUP(B14,'[1]Testing sheet'!$A:$A,1,0) -> #N/A
A15: Chapter 1 | B15: IT-0007 | C15: D8471305 | D15: F847001 | E15: FA178 | F15: BC1 | G15: A414120 | I15: 300000 | J15: =VLOOKUP(B15,'[1]Testing sheet'!$A:$A,1,0) -> #N/A
A16: Chapter 1 | B16: IT-0007 | C16: D8471305 | D16: F847001 | E16: FA178 | F16: BC1 | G16: A416110 | I16: 100000 | J16: =VLOOKUP(B16,'[1]Testing sheet'!$A:$A,1,0) -> #N/A
A17: Chapter 1 | B17: IT-0010 | C17: D8470540 | D17: F847001 | E17: FA178 | F17: BC1 | G17: A413310 | H17: 74540 | J17: =VLOOKUP(B17,'[1]Testing sheet'!$A:$A,1,0) -> #N/A
A18: Chapter 1 | B18: IT-0010 | C18: D8470540 | D18: F847010 | E18: FA178 | F18: BC1 | G18: A413310 | I18: 74540 | J18: =VLOOKUP(B18,'[1]Testing sheet'!$A:$A,1,0) -> #N/A
A19: Chapter 1 | B19: IT-0014 | C19: D8470110 | D19: F847001 | E19: FA178 | F19: BC1 | G19: A413121 | H19: 24000 | J19: =VLOOKUP(B19,'[1]Testing sheet'!$A:$A,1,0) -> #N/A
A20: Chapter 1 | B20: IT-0014 | C20: D8470730 | D20: F847001 | E20: FA178 | F20: BC1 | G20: A414310 | I20: 24000 | J20: =VLOOKUP(B20,'[1]Testing sheet'!$A:$A,1,0) -> #N/A
A21: Chapter 1 | B21: IT-0017 | C21: D8471140 | D21: F847001 | E21: FA178 | F21: BC1 | G21: A412121 | H21: 63558 | J21: =VLOOKUP(B21,'[1]Testing sheet'!$A:$A,1,0) -> #N/A
A22: Chapter 1 | B22: IT-0017 | C22: D8471140 | D22: F847001 | E22: FA178 | F22: BC1 | G22: A414120 | I22: 63558 | J22: =VLOOKUP(B22,'[1]Testing sheet'!$A:$A,1,0) -> #N/A
A23: Chapter 1 | B23: IT-0020 | C23: D8470140 | D23: F847001 | E23: FA178 | F23: BC1 | G23: A412121 | H23: 12000 | J23: =VLOOKUP(B23,'[1]Testing sheet'!$A:$A,1,0) -> #N/A
A24: Chapter 1 | B24: IT-0020 | C24: D8470140 | D24: F847001 | E24: FA178 | F24: BC1 | G24: A413710 | I24: 12000 | J24: =VLOOKUP(B24,'[1]Testing sheet'!$A:$A,1,0) -> #N/A
A25: Chapter 1 | B25: IT-0020 | C25: D8471140 | D25: F847001 | E25: FA178 | F25: BC1 | G25: A412121 | H25: 10000 | J25: =VLOOKUP(B25,'[1]Testing sheet'!$A:$A,1,0) -> #N/A
A26: Chapter 1 | B26: IT-0020 | C26: D8471140 | D26: F847001 | E26: FA178 | F26: BC1 | G26: A413710 | I26: 10000 | J26: =VLOOKUP(B26,'[1]Testing sheet'!$A:$A,1,0) -> #N/A
A27: Chapter 1 | B27: IT-0025 | C27: D8470121 | D27: F847001 | E27: FA178 | F27: BC1 | G27: A415110 | I27: 135051 | J27: =VLOOKUP(B27,'[1]Testing sheet'!$A:$A,1,0) -> #N/A
A28: Chapter 1 | B28: IT-0025 | C28: D8470121 | D28: F847001 | E28: FA178 | F28: BC1 | G28: A412121 | I28: 1583670 | J28: =VLOOKUP(B28,'[1]Testing sheet'!$A:$A,1,0) -> #N/A
A29: Chapter 1 | B29: IT-0025 | C29: D8470121 | D29: F847001 | E29: FA178 | F29: BC1 | G29: A412125 | I29: 1374670 | J29: =VLOOKUP(B29,'[1]Testing sheet'!$A:$A,1,0) -> #N/A
A30: Chapter 1 | B30: IT-0025 | C30: D8470121 | D30: F847001 | E30: FA178 | F30: BC1 | G30: A412523 | I30: 12000 | J30: =VLOOKUP(B30,'[1]Testing sheet'!$A:$A,1,0) -> #N/A
A31: Chapter 1 | B31: IT-0025 | C31: D8470121 | D31: F847001 | E31: FA178 | F31: BC1 | G31: A412546 | I31: 28470 | J31: =VLOOKUP(B31,'[1]Testing sheet'!$A:$A,1,0) -> #N/A
A32: Chapter 1 | B32: IT-0025 | C32: D8470330 | D32: F847001 | E32: FA178 | F32: BC1 | G32: A412121 | H32: 3133861 | J32: =VLOOKUP(B32,'[1]Testing sheet'!$A:$A,1,0) -> #N/A
A33: Chapter 1 | B33: IT-0039 | C33: D8470140 | D33: F847001 | E33: FA178 | F33: BC1 | G33: A412121 | H33: 10000 | J33: =VLOOKUP(B33,'[1]Testing sheet'!$A:$A,1,0) -> #N/A
A34: Chapter 1 | B34: IT-0039 | C34: D8470140 | D34: F847001 | E34: FA178 | F34: BC1 | G34: A413710 | I34: 10000 | J34: =VLOOKUP(B34,'[1]Testing sheet'!$A:$A,1,0) -> #N/A
A35: Chapter 1 | B35: IT-0039 | C35: D8470425 | D35: F847001 | E35: FA178 | F35: BC1 | G35: A412121 | H35: 13700 | J35: =VLOOKUP(B35,'[1]Testing sheet'!$A:$A,1,0) -> #N/A
A36: Chapter 1 | B36: IT-0039 | C36: D8470425 | D36: F847001 | E36: FA178 | F36: BC1 | G36: A413710 | I36: 13700 | J36: =VLOOKUP(B36,'[1]Testing sheet'!$A:$A,1,0) -> #N/A
A37: Chapter 1 | B37: IT-0039 | C37: D8471140 | D37: F847001 | E37: FA178 | F37: BC1 | G37: A412121 | H37: 10000 | J37: =VLOOKUP(B37,'[1]Testing sheet'!$A:$A,1,0) -> #N/A
A38: Chapter 1 | B38: IT-0039 | C38: D8471140 | D38: F847001 | E38: FA178 | F38: BC1 | G38: A413710 | I38: 10000 | J38: =VLOOKUP(B38,'[1]Testing sheet'!$A:$A,1,0) -> #N/A
A39: Chapter 1 | B39: IT-0039 | C39: D8471305 | D39: F847001 | E39: FA178 | F39: BC1 | G39: A412121 | H39: 600 | J39: =VLOOKUP(B39,'[1]Testing sheet'!$A:$A,1,0) -> #N/A
A40: Chapter 1 | B40: IT-0039 | C40: D8471305 | D40: F847001 | E40: FA178 | F40: BC1 | G40: A412523 | I40: 600 | J40: =VLOOKUP(B40,'[1]Testing sheet'!$A:$A,1,0) -> #N/A
...

Sheet Samples
A3: Transfer Code | B3: Transfer Amount | C3: Requested By | D3: Requested Date | E3: Approved or Rejected By | F3: Approved Date | G3: Transfer Status | H3: Chapter #
A4: IT-0045 | B4: 2134174 | C4: Eiman Al Khoori | D4: 45014 | E4: Abdulla Ali Al Mansoori | F4: 45014 | G4: Approved | H4: Chapter 1
A5: IT-0064 | B5: 3170270 | C5: Eiman Al Khoori | D5: 45055 | E5: Abdulla Ali Al Mansoori | F5: 45055 | G5: Approved | H5: =_xlfn.XLOOKUP(A5,'6 to 37'!B:B,'6 to 37'!A:A) -> Chapter 1
A6: IT-0114 | B6: 50737204 | C6: Eiman Al Khoori | D6: 45131 | E6: Abdulla Ali Al Mansoori | F6: 45131 | G6: Approved | H6: =_xlfn.XLOOKUP(A6,'6 to 37'!B:B,'6 to 37'!A:A) -> Chapter 1
A7: IT-0135 | B7: 1100000 | C7: Fatima Almazrooei | D7: 45166 | E7: Abdulla Ali Al Mansoori | F7: 45167 | G7: Approved | H7: Chapter 1
A8: IT-0156 | B8: 153256 | D8: 45205 | E8: Abdulla Ali Al Mansoori | F8: 45205 | G8: Approved | H8: =_xlfn.XLOOKUP(A8,'6 to 37'!B:B,'6 to 37'!A:A) -> Chapter 1
A9: IT-0008 | B9: 6602331 | C9: Eiman Al Khoori (ku100041915) | D9: 44965 | E9: Abdulla Ali Al Mansoori (kupi4099) | F9: 44965 | G9: Approved | H9: =_xlfn.XLOOKUP(A9,'6 to 37'!B:B,'6 to 37'!A:A) -> Chapter 2
A10: IT-0018 | B10: 14000000 | C10: Fatima Almazrooei | D10: 44978 | E10: Abdulla Ali Al Mansoori | F10: 44978 | G10: Approved | H10: =_xlfn.XLOOKUP(A10,'6 to 37'!B:B,'6 to 37'!A:A) -> Chapter 2
A11: IT-0022 | B11: 4942000 | C11: Fatima Almazrooei | D11: 44984 | E11: Abdulla Ali Al Mansoori | F11: 44984 | G11: Approved | H11: =_xlfn.XLOOKUP(A11,'6 to 37'!B:B,'6 to 37'!A:A) -> Chapter 2
A12: IT-0026 | B12: 745902 | C12: Fatima Almazrooei | D12: 44987 | E12: Abdulla Ali Al Mansoori | F12: 44987 | G12: Approved | H12: Chapter 2
A13: IT-0029 | B13: 1885167 | C13: Fatima Almazrooei | D13: 44992 | E13: Abdulla Ali Al Mansoori | F13: 44992 | G13: Approved | H13: Chapter 2
A14: IT-0030 | B14: 3154833 | C14: Fatima Almazrooei | D14: 44992 | E14: Abdulla Ali Al Mansoori | F14: 44993 | G14: Approved | H14: =_xlfn.XLOOKUP(A14,'6 to 37'!B:B,'6 to 37'!A:A) -> Chapter 2
A15: IT-0033 | B15: 1476900 | C15: Fatima Almazrooei | D15: 44994 | E15: Abdulla Ali Al Mansoori | F15: 44994 | G15: Approved | H15: Chapter 2
A16: IT-0035 | B16: 2402264 | C16: Eiman Al Khoori | D16: 45006 | E16: Abdulla Ali Al Mansoori | F16: 45006 | G16: Approved | H16: Chapter 2
A17: IT-0043 | B17: 1025316 | C17: Eiman Al Khoori | D17: 45012 | E17: Abdulla Ali Al Mansoori | F17: 45012 | G17: Approved | H17: Chapter 2
A18: IT-0063 | B18: 1684205 | C18: Eiman Al Khoori | D18: 45055 | E18: Abdulla Ali Al Mansoori | F18: 45055 | G18: Approved | H18: Chapter 2
A19: IT-0069 | B19: 1628742 | C19: Eiman Al Khoori | D19: 45065 | E19: Abdulla Ali Al Mansoori | F19: 45065 | G19: Approved | H19: Chapter 2
A20: IT-0088 | B20: 1613440 | C20: Fatima Almazrooei | D20: 45079 | E20: Abdulla Ali Al Mansoori | F20: 45079 | G20: Approved | H20: Chapter 2
A21: IT-0090 | B21: 1629918 | C21: Eiman Al Khoori | D21: 45083 | E21: Abdulla Ali Al Mansoori | F21: 45083 | G21: Approved | H21: Chapter 2
A22: IT-0099 | B22: 2027352 | C22: Eiman Al Khoori | D22: 45093 | E22: Abdulla Ali Al Mansoori | F22: 45093 | G22: Approved | H22: Chapter 2
A23: IT-0116 | B23: 5658128 | C23: Eiman Al Khoori | D23: 45135 | E23: Abdulla Ali Al Mansoori | F23: 45135 | G23: Approved | H23: =_xlfn.XLOOKUP(A23,'6 to 37'!B:B,'6 to 37'!A:A) -> Chapter 2
A24: IT-0120 | B24: 120000 | C24: Eiman Al Khoori | D24: 45141 | E24: Abdulla Ali Al Mansoori | F24: 45141 | G24: Approved | H24: Chapter 2
A25: IT-0132 | B25: 1562000 | C25: Fatima Almazrooei | D25: 45163 | E25: Abdulla Ali Al Mansoori | F25: 45163 | G25: Approved | H25: Chapter 2
A26: IT-0137 | B26: 968921 | C26: Eiman Al Khoori | D26: 45176 | E26: Abdulla Ali Al Mansoori | F26: 45176 | G26: Approved | H26: Chapter 2
A27: IT-0002 | B27: 310000 | C27: Eiman Al Khoori (ku100041915) | D27: 44950 | E27: Abdulla Ali Al Mansoori (kupi4099) | F27: 44950 | G27: Approved | H27: =_xlfn.XLOOKUP(A27,'6 to 37'!B:B,'6 to 37'!A:A) -> Chapter 3
A28: IT-0032 | B28: 4200000 | C28: Fatima Almazrooei | D28: 44993 | E28: Abdulla Ali Al Mansoori | F28: 44993 | G28: Approved | H28: =_xlfn.XLOOKUP(A28,'6 to 37'!B:B,'6 to 37'!A:A) -> Chapter 3
A29: IT-0061 | B29: 2553851 | C29: Eiman Al Khoori | D29: 45049 | E29: Abdulla Ali Al Mansoori | F29: 45049 | G29: Approved | H29: Chapter 3
A30: IT-0106 | B30: 5497623 | C30: Eiman Al Khoori | D30: 45103 | E30: Abdulla Ali Al Mansoori | F30: 45103 | G30: Approved | H30: =_xlfn.XLOOKUP(A30,'6 to 37'!B:B,'6 to 37'!A:A) -> Chapter 3
A31: IT-0117 | B31: 1584200 | C31: Eiman Al Khoori | D31: 45135 | E31: Abdulla Ali Al Mansoori | F31: 45135 | G31: Approved | H31: Chapter 3
A32: IT-0122 | B32: 1387415 | C32: Eiman Al Khoori | D32: 45147 | E32: Abdulla Ali Al Mansoori | F32: 45147 | G32: Approved | H32: =_xlfn.XLOOKUP(A32,'6 to 37'!B:B,'6 to 37'!A:A) -> Chapter 3
A33: IT-0157 | B33: 727000 | C33: Fatima Almazrooei | D33: 45205 | E33: Abdulla Ali Al Mansoori | F33: 45205 | G33: Approved | H33: =_xlfn.XLOOKUP(A33,'6 to 37'!B:B,'6 to 37'!A:A) -> Chapter 3
